Workbook
Name CANTIDAD_POR_DEPARTAMENTO: #REF!
Name SUELDOS_POR_DEPARTAMENTO: #REF!

Sheet OCTUBRE 2025
B2: COOPERATIVA DE AHORRO Y CRÉDITO "LOS ANDES LATINOS" LTDA. | AN2: COOPERATIVA DE AHORRO Y CRÉDITO "LOS ANDES LATINOS" LTDA.
B3: ROL DE PAGOS | R3: MES DE OCTUBRE 2025 | AN3: BENEFICIOS SOCIALES | AU3: =+R3 -> MES DE OCTUBRE 2025
C4: 1 | D4: 2 | E4: 3 | F4: 4 | G4: 5 | H4: 6 | I4: 7 | J4: 8 | K4: 9 | L4: 10 | M4: 11 | N4: 12 | O4: 13 | P4: 14 | Q4: 15 | R4: 16 | S4: 17 | T4: 18 | U4: 19 | V4: 20 | W4: 21 | X4: 22 | Y4: 23 | Z4: 24 | AA4: 25 | AB4: 26 | AC4: 27 | AD4: 28 | AE4: 29 | AF4: 30 | AG4: 31 | AH4: 32 | AI4: 33
J5: INGRESOS | Z5: EGRESOS
B6: No. | C6: CEDULA | D6: NOMBRE | E6: FECHA DE INGRESO | F6: CARGO | G6: GÉNERO | H6: AGENCIA | I6: DIAS TRABAJADOS | J6: SUELDO BRUTO | K6: BONO VEHICULAR | L6: Bono General Mensual | M6: BONO CUMPLIMIENTO | N6: COMISIÓN SUP. META | O6: COMISION POR PLAZOS FIJOS | P6: COM. SOCIOS NUEVOS Y COLOCACION | Q6: VALOR EN HORAS EXTRAS | S6: TOTAL POR VARIACION | T6: INGRESOS APORTE AL IESS | U6: FONDO RESERVAS | V6: FONDO DE RESERVA (BONO NAVIDEÑO) | W6: DECIMO TERCERO | X6: DECIMO CUARTO | Y6: TOTAL DE Ingresos | Z6: IESS | AA6: RET IMP A LA RENTA | AB6: DSCTOS | AC6: PRESTAMO PQ- HIP | AD6: SUBSIDIOS MONETARIO | AE6: EXT. SALUD | AF6: PENSION ALIMENTICIA | AG6: C*C | AH6: ANTICP. SUELD. | AI6: TOTAL DESCTS. | AJ6: NETO | AK6: RECIBI CONFORME | AN6: No. | AO6: NOMBRE | AP6: FECHA DE INGRESO. | AQ6: DIAS TRABAJADOS | AR6: AGENCIA | AS6: TOTAL GANADO EN EL MES GRAVABLE | AT6: 13ER. SUELDO | AU6: FONDO DE RESERVA | AV6: 14TO. SUELDO | AW6: 14TO. SUELDO | AX6: VACACIONES | AY6: TOTAL SUELDO + B.SOCIAL | AZ6: APORTE AL IESS
Q7: 0.5 | R7: 1 | Z7: 0.0945 | AT7: 12 | AU7: 0.0833 | AV7: AJUSTE | AW7: 470 | AX7: 24 | AZ7: Patronal 11,15% | BA7: CCC 1% | BB7: TOTAL
B8: 1 | C8: 925813685 | D8: ASITIMBAY CRIOLLO JOHN ANDERSON | E8: 44292 | F8: JEFE DE MARKETING | G8: M | H8: Matriz | I8: 30 | J8: 817.76 | K8: =IFERROR(VLOOKUP(C8,Tabla15[[CEDULA]:[BONO VEHICULAR]],8,0),0) -> 0 | L8: 17.78 | M8: =+VLOOKUP(C8,Tabla335[[CEDULA ]:[US$,,]],9,0) -> 0 | P8: =+VLOOKUP(C8,'COMISIONES-SOCIOS'!$C$8:$L$57,10,0) -> 0 | Q8: =+VLOOKUP(C8,Tabla3[[CEDULA ]:[US$,]],8,0) -> 0 | R8: =+VLOOKUP($C8,Tabla3[[CEDULA ]:[US$,]],9,0) -> 0 | S8: =SUM(K8:R8) -> 17.78 | T8: =+J8+S8 -> 835.54 | U8: =VLOOKUP(C8,FR!$C$6:$M$55,11,0) -> 69.600482 | Y8: =SUM(T8:X8) -> 905.14048 | Z8: =T8*9.45% -> 78.95853 | AB8: 0 | AC8: =IFERROR(+VLOOKUP(D8,PQ!$D$35:$E$45,2,0),0) -> 0 | AH8: 720.63 | AI8: =SUM(Z8:AH8) -> 799.58853 | AJ8: =+Y8-AI8 -> 105.55195 | AK8: 600101009364 | AN8: 1 | AO8: =+D8 -> ASITIMBAY CRIOLLO JOHN ANDERSON | AP8: =+E8 -> 44292 | AQ8: =+I8 -> 30 | AR8: =+H8 -> Matriz | AS8: =T8 -> 835.54 | AT8: =+AS8/12 -> 69.628333 | AU8: 0 | AW8: =($AW$7/360)*AQ8 -> 39.166667 | AX8: =+AS8/24 -> 34.814167 | AY8: =SUM(AS8:AX8) -> 979.14917 | AZ8: =+AS8*11.15% -> 93.16271 | BA8: =+AS8*1% -> 8.3554 | BB8: =SUM(AZ8:BA8) -> 101.51811
B9: =+B8+1 -> 2 | C9: 944405737 | D9: BARAHONA ZAMBRANO DAYANA NICOLE | E9: 45029 | F9: CAJERO FINANCIERO | G9: F | H9: Matriz | I9: 1 | J9: 15.86 | K9: =IFERROR(VLOOKUP(C9,Tabla15[[CEDULA]:[BONO VEHICULAR]],8,0),0) -> 0 | L9: 35.02 | M9: =+VLOOKUP(C9,Tabla335[[CEDULA ]:[US$,,]],9,0) -> 0 | P9: =+VLOOKUP(C9,'COMISIONES-SOCIOS'!$C$8:$L$57,10,0) -> 0 | Q9: =+VLOOKUP(C9,Tabla3[[CEDULA ]:[US$,]],8,0) -> 0 | R9: =+VLOOKUP($C9,Tabla3[[CEDULA ]:[US$,]],9,0) -> 0 | S9: =SUM(K9:R9) -> 35.02 | T9: =+J9+S9 -> 50.88 | U9: =VLOOKUP(C9,FR!$C$6:$M$55,11,0) -> ACUMULA | Y9: =SUM(T9:X9) -> 50.88 | Z9: =T9*9.45% -> 4.80816 | AC9: =IFERROR(+VLOOKUP(D9,PQ!$D$35:$E$45,2,0),0) -> 0 | AH9: 0 | AI9: =SUM(Z9:AH9) -> 4.80816 | AJ9: =+Y9-AI9 -> 46.07184 | AK9: 600301314479 | AN9: =+AN8+1 -> 2 | AO9: =+D9 -> BARAHONA ZAMBRANO DAYANA NICOLE | AP9: =+E9 -> 45029 | AQ9: =+I9 -> 1 | AR9: =+H9 -> Matriz | AS9: =T9 -> 50.88 | AT9: =+AS9/12 -> 4.24 | AU9: =+AS9*AU7 -> 4.238304 | AW9: =($AW$7/360)*AQ9 -> 1.3055556 | AX9: =+AS9/24 -> 2.12 | AY9: =SUM(AS9:AX9) -> 62.78386 | AZ9: =+AS9*11.15% -> 5.67312 | BA9: =+AS9*1% -> 0.5088 | BB9: =SUM(AZ9:BA9) -> 6.18192
B10: =+B9+1 -> 3 | C10: 604394502 | D10: BETUN CHAFLA JULIO CESAR | E10: 44735 | F10: ASESOR DE NEGOCIOS | G10: M | H10: Matriz | I10: 30 | J10: 613.32 | K10: =IFERROR(VLOOKUP(C10,Tabla15[[CEDULA]:[BONO VEHICULAR]],8,0),0) -> 0 | L10: 13.33 | M10: =+VLOOKUP(C10,Tabla335[[CEDULA ]:[US$,,]],9,0) -> 0 | P10: =+VLOOKUP(C10,'COMISIONES-SOCIOS'!$C$8:$L$57,10,0) -> 0 | Q10: =+VLOOKUP(C10,Tabla3[[CEDULA ]:[US$,]],8,0) -> 0 | R10: =+VLOOKUP($C10,Tabla3[[CEDULA ]:[US$,]],9,0) -> 0 | S10: =SUM(K10:R10) -> 13.33 | T10: =+J10+S10 -> 626.65 | U10: =VLOOKUP(C10,FR!$C$6:$M$55,11,0) -> 52.199945 | Y10: =SUM(T10:X10) -> 678.84995 | Z10: =T10*9.45% -> 59.218425 | AC10: =IFERROR(+VLOOKUP(D10,PQ!$D$35:$E$45,2,0),0) -> 0 | AH10: 0 | AI10: =SUM(Z10:AH10) -> 59.218425 | AJ10: =+Y10-AI10 -> 619.63152 | AK10: 600101311713 | AN10: =+AN9+1 -> 3 | AO10: =+D10 -> BETUN CHAFLA JULIO CESAR | AP10: =+E10 -> 44735 | AQ10: =+I10 -> 30 | AR10: =+H10 -> Matriz | AS10: =T10 -> 626.65 | AT10: =+AS10/12 -> 52.220833 | AU10: 0 | AW10: =($AW$7/360)*AQ10 -> 39.166667 | AX10: =+AS10/24 -> 26.110417 | AY10: =SUM(AS10:AX10) -> 744.14792 | AZ10: =+AS10*11.15% -> 69.871475 | BA10: =+AS10*1% -> 6.2665 | BB10: =SUM(AZ10:BA10) -> 76.137975
B11: =+B10+1 -> 4 | C11: 955741970 | D11: CHACAGUASAY CHACAGUASAY ROBERTH CRISTHIAN | E11: 44986 | F11: OFICIAL DE RECAUDACIONES | G11: M | H11: Matriz | I11: 30 | J11: 473.88 | K11: =IFERROR(VLOOKUP(C11,Tabla15[[CEDULA]:[BONO VEHICULAR]],8,0),0) -> 100 | L11: 10.03 | M11: =+VLOOKUP(C11,Tabla335[[CEDULA ]:[US$,,]],9,0) -> 0 | P11: =+VLOOKUP(C11,'COMISIONES-SOCIOS'!$C$8:$L$57,10,0) -> 0 | Q11: =+VLOOKUP(C11,Tabla3[[CEDULA ]:[US$,]],8,0) -> 0 | R11: =+VLOOKUP($C11,Tabla3[[CEDULA ]:[US$,]],9,0) -> 0 | S11: =SUM(K11:R11) -> 110.03 | T11: =+J11+S11 -> 583.91 | U11: =VLOOKUP(C11,FR!$C$6:$M$55,11,0) -> 48.639703 | Y11: =SUM(T11:X11) -> 632.5497 | Z11: =T11*9.45% -> 55.179495 | AC11: =IFERROR(+VLOOKUP(D11,PQ!$D$35:$E$45,2,0),0) -> 0 | AH11: 400 | AI11: =SUM(Z11:AH11) -> 455.17949 | AJ11: =+Y11-AI11 -> 177.37021 | AK11: 600101313870 | AN11: =+AN10+1 -> 4 | AO11: =+D11 -> CHACAGUASAY CHACAGUASAY ROBERTH CRISTHIAN | AP11: =+E11 -> 44986 | AQ11: =+I11 -> 30 | AR11: =+H11 -> Matriz | AS11: =T11 -> 583.91 | AT11: =+AS11/12 -> 48.659167 | AU11: 0 | AW11: =($AW$7/360)*AQ11 -> 39.166667 | AX11: =+AS11/24 -> 24.329583 | AY11: =SUM(AS11:AX11) -> 696.06542 | AZ11: =+AS11*11.15% -> 65.105965 | BA11: =+AS11*1% -> 5.8391 | BB11: =SUM(AZ11:BA11) -> 70.945065
B12: =+B11+1 -> 5 | C12: 0943964973 | D12: CHACAGUASAY GUAMAN KEVIN NEHEMIAS | E12: 45945 | F12: ASESOR DE NEGOCIOS | G12: M | H12: Matriz | I12: 16 | J12: 256.53 | M12: =+VLOOKUP(C12,Tabla335[[CEDULA ]:[US$,,]],9,0) -> 368.77 | P12: =+VLOOKUP(C12,'COMISIONES-SOCIOS'!$C$8:$L$57,10,0) -> 0 | Q12: =+VLOOKUP(C12,Tabla3[[CEDULA ]:[US$,]],8,0) -> 0 | R12: =+VLOOKUP($C12,Tabla3[[CEDULA ]:[US$,]],9,0) -> 0 | S12: =SUM(K12:R12) -> 368.77 | T12: =+J12+S12 -> 625.3 | Y12: =SUM(T12:X12) -> 625.3 | Z12: =T12*9.45% -> 59.09085 | AN12: =+AN11+1 -> 5 | AO12: =+D12 -> CHACAGUASAY GUAMAN KEVIN NEHEMIAS | AP12: =+E12 -> 45945 | AQ12: =+I12 -> 16 | AW12: =($AW$7/360)*AQ12 -> 20.888889
B13: =+B12+1 -> 6 | C13: 944143148 | D13: CHIMBOLEMA YUNGAN MARIO EFRAIN | E13: 45884 | F13: OFICIAL DE RECAUDACIONES | G13: M | H13: Durán | I13: 9 | J13: 142.16 | K13: =IFERROR(VLOOKUP(C13,Tabla15[[CEDULA]:[BONO VEHICULAR]],8,0),0) -> 30 | L13: 0 | M13: =+VLOOKUP(C13,Tabla335[[CEDULA ]:[US$,,]],9,0) -> 0 | P13: =+VLOOKUP(C13,'COMISIONES-SOCIOS'!$C$8:$L$57,10,0) -> 0 | Q13: =+VLOOKUP(C13,Tabla3[[CEDULA ]:[US$,]],8,0) -> 0 | R13: =+VLOOKUP($C13,Tabla3[[CEDULA ]:[US$,]],9,0) -> 0 | S13: =SUM(K13:R13) -> 30 | T13: =+J13+S13 -> 172.16 | U13: =VLOOKUP(C13,FR!$C$6:$M$55,11,0) -> 0 | Y13: =SUM(T13:X13) -> 172.16 | Z13: =T13*9.45% -> 16.26912 | AH13: 0 | AI13: =SUM(Z13:AH13) -> 16.26912 | AJ13: =+Y13-AI13 -> 155.89088 | AK13: 600301320262 | AN13: =+AN12+1 -> 6 | AO13: =+D13 -> CHIMBOLEMA YUNGAN MARIO EFRAIN | AP13: =+E13 -> 45884 | AQ13: =+I13 -> 9 | AR13: =+H13 -> Durán | AS13: =T13 -> 172.16 | AT13: =+AS13/12 -> 14.346667 | AU13: 0 | AW13: =($AW$7/360)*AQ13 -> 11.75 | AX13: =+AS13/24 -> 7.1733333 | AY13: =SUM(AS13:AX13) -> 205.43 | AZ13: =+AS13*11.15% -> 19.19584 | BA13: =+AS13*1% -> 1.7216 | BB13: =SUM(AZ13:BA13) -> 20.91744
B14: =+B13+1 -> 7 | C14: 955325238 | D14: CHOCA CEPEDA INES VIVIANA | E14: 45945 | F14: CAJERA FINANCIERA | G14: F | H14: Matriz | I14: 16 | J14: 256.53 | M14: =+VLOOKUP(C14,Tabla335[[CEDULA ]:[US$,,]],9,0) -> 0 | P14: =+VLOOKUP(C14,'COMISIONES-SOCIOS'!$C$8:$L$57,10,0) -> 0 | Q14: =+VLOOKUP(C14,Tabla3[[CEDULA ]:[US$,]],8,0) -> 0 | R14: =+VLOOKUP($C14,Tabla3[[CEDULA ]:[US$,]],9,0) -> 0 | S14: =SUM(K14:R14) -> 0 | T14: =+J14+S14 -> 256.53 | Y14: =SUM(T14:X14) -> 256.53 | Z14: =T14*9.45% -> 24.242085 | AH14: 0 | AN14: =+AN13+1 -> 7 | AO14: =+D14 -> CHOCA CEPEDA INES VIVIANA | AP14: =+E14 -> 45945 | AQ14: =+I14 -> 16 | AW14: =($AW$7/360)*AQ14 -> 20.888889
B15: =+B14+1 -> 8 | C15: 914163654 | D15: COCA BENITEZ JORGE MANUEL | E15: 44470 | F15: ANALISTA DE RIESGO | G15: M | H15: Matriz | I15: 15 | J15: 1200 | K15: =IFERROR(VLOOKUP(C15,Tabla15[[CEDULA]:[BONO VEHICULAR]],8,0),0) -> 0 | L15: 0 | M15: =+VLOOKUP(C15,Tabla335[[CEDULA ]:[US$,,]],9,0) -> 0 | P15: =+VLOOKUP(C15,'COMISIONES-SOCIOS'!$C$8:$L$57,10,0) -> 0 | Q15: =+VLOOKUP(C15,Tabla3[[CEDULA ]:[US$,]],8,0) -> 0 | R15: =+VLOOKUP($C15,Tabla3[[CEDULA ]:[US$,]],9,0) -> 0 | S15: =SUM(K15:R15) -> 0 | T15: =+J15+S15 -> 1200 | U15: =VLOOKUP(C15,FR!$C$6:$M$55,11,0) -> 99.96 | Y15: =SUM(T15:X15) -> 1299.96 | Z15: =T15*9.45% -> 113.4 | AB15: 0 | AC15: =IFERROR(+VLOOKUP(D15,PQ!$D$35:$E$45,2,0),0) -> 0 | AD15: 624.02405 | AH15: 0 | AI15: =SUM(Z15:AH15) -> 737.42405 | AJ15: =+Y15-AI15 -> 562.53595 | AK15: 600101010004 | AN15: =+AN14+1 -> 8 | AO15: =+D15 -> COCA BENITEZ JORGE MANUEL | AP15: =+E15 -> 44470 | AQ15: =+I15 -> 15 | AR15: =+H15 -> Matriz | AS15: =T15 -> 1200 | AT15: =+AS15/12 -> 100 | AU15: 0 | AW15: =($AW$7/360)*AQ15 -> 19.583333 | AX15: =+AS15/24 -> 50 | AY15: =SUM(AS15:AX15) -> 1369.5833 | AZ15: =+AS15*11.15% -> 133.8 | BA15: =+AS15*1% -> 12 | BB15: =SUM(AZ15:BA15) -> 145.8
B16: =+B15+1 -> 9 | C16: 956668305 | D16: CORO YUQUILEMA RUTH NOEMI | E16: 45945 | F16: OFICIAL DE RECAUDACIONES | G16: F | H16: Matriz | I16: 16 | J16: 252.74 | M16: =+VLOOKUP(C16,Tabla335[[CEDULA ]:[US$,,]],9,0) -> 0 | P16: =+VLOOKUP(C16,'COMISIONES-SOCIOS'!$C$8:$L$57,10,0) -> 0 | Q16: =+VLOOKUP(C16,Tabla3[[CEDULA ]:[US$,]],8,0) -> 0 | R16: =+VLOOKUP($C16,Tabla3[[CEDULA ]:[US$,]],9,0) -> 0 | S16: =SUM(K16:R16) -> 0 | T16: =+J16+S16 -> 252.74 | Y16: =SUM(T16:X16) -> 252.74 | Z16: =T16*9.45% -> 23.88393 | AH16: 0 | AN16: =+AN15+1 -> 9 | AO16: =+D16 -> CORO YUQUILEMA RUTH NOEMI | AP16: =+E16 -> 45945 | AQ16: =+I16 -> 16 | AW16: =($AW$7/360)*AQ16 -> 20.888889
B17: =+B16+1 -> 10 | C17: 0918741448 | D17: DEFAS CHICAIZA JOEL ALBERTO | E17: 45823 | F17: ASESOR DE NEGOCIOS | G17: M | H17: Norte | I17: 30 | J17: 626.65 | K17: =IFERROR(VLOOKUP(C17,Tabla15[[CEDULA]:[BONO VEHICULAR]],8,0),0) -> 0 | L17: 0 | M17: =+VLOOKUP(C17,Tabla335[[CEDULA ]:[US$,,]],9,0) -> 0 | P17: =+VLOOKUP(C17,'COMISIONES-SOCIOS'!$C$8:$L$57,10,0) -> 0 | Q17: =+VLOOKUP(C17,Tabla3[[CEDULA ]:[US$,]],8,0) -> 0 | R17: =+VLOOKUP($C17,Tabla3[[CEDULA ]:[US$,]],9,0) -> 0 | S17: =SUM(K17:R17) -> 0 | T17: =+J17+S17 -> 626.65 | U17: =VLOOKUP(C17,FR!$C$6:$M$55,11,0) -> 0 | Y17: =SUM(T17:X17) -> 626.65 | Z17: =T17*9.45% -> 59.218425 | AC17: =IFERROR(+VLOOKUP(D17,PQ!$D$35:$E$45,2,0),0) -> 261.63 | AH17: 150 | AI17: =SUM(Z17:AH17) -> 470.84842 | AJ17: =+Y17-AI17 -> 155.80158 | AK17: 600201320019 | AN17: =+AN16+1 -> 10 | AO17: =+D17 -> DEFAS CHICAIZA JOEL ALBERTO | AP17: =+E17 -> 45823 | AQ17: =+I17 -> 30 | AR17: =+H17 -> Norte | AS17: =T17 -> 626.65 | AT17: =+AS17/12 -> 52.220833 | AU17: 0 | AW17: =($AW$7/360)*AQ17 -> 39.166667 | AX17: =+AS17/24 -> 26.110417 | AY17: =SUM(AS17:AX17) -> 744.14792 | AZ17: =+AS17*11.15% -> 69.871475 | BA17: =+AS17*1% -> 6.2665 | BB17: =SUM(AZ17:BA17) -> 76.137975
B18: =+B17+1 -> 11 | C18: 931097620 | D18: DEL ROSARIO RODRIGUEZ JUDY ANGELICA | E18: 45945 | F18: CAJERA FINANCIERA | G18: F | H18: Norte | I18: 16 | J18: 256.53 | M18: =+VLOOKUP(C18,Tabla335[[CEDULA ]:[US$,,]],9,0) -> 368.77 | P18: =+VLOOKUP(C18,'COMISIONES-SOCIOS'!$C$8:$L$57,10,0) -> 0 | Q18: =+VLOOKUP(C18,Tabla3[[CEDULA ]:[US$,]],8,0) -> 0 | R18: =+VLOOKUP($C18,Tabla3[[CEDULA ]:[US$,]],9,0) -> 0 | S18: =SUM(K18:R18) -> 368.77 | T18: =+J18+S18 -> 625.3 | Y18: =SUM(T18:X18) -> 625.3 | Z18: =T18*9.45% -> 59.09085 | AH18: 144.3 | AN18: =+AN17+1 -> 11 | AO18: =+D18 -> DEL ROSARIO RODRIGUEZ JUDY ANGELICA | AP18: =+E18 -> 45945 | AQ18: =+I18 -> 16 | AW18: =($AW$7/360)*AQ18 -> 20.888889
B19: =+B18+1 -> 12 | C19: 1105483422 | D19: FLORES HERRERA WENDY DEL CISNE | E19: 45065 | F19: CAJERO FINANCIERO | G19: F | H19: Durán | I19: 30 | J19: 650 | K19: =IFERROR(VLOOKUP(C19,Tabla15[[CEDULA]:[BONO VEHICULAR]],8,0),0) -> 0 | L19: 14.13 | M19: =+VLOOKUP(C19,Tabla335[[CEDULA ]:[US$,,]],9,0) -> 0 | P19: =+VLOOKUP(C19,'COMISIONES-SOCIOS'!$C$8:$L$57,10,0) -> 0 | Q19: =+VLOOKUP(C19,Tabla3[[CEDULA ]:[US$,]],8,0) -> 0 | R19: =+VLOOKUP($C19,Tabla3[[CEDULA ]:[US$,]],9,0) -> 0 | S19: =SUM(K19:R19) -> 14.13 | T19: =+J19+S19 -> 664.13 | U19: =VLOOKUP(C19,FR!$C$6:$M$55,11,0) -> 52.199945 | Y19: =SUM(T19:X19) -> 716.32994 | Z19: =T19*9.45% -> 62.760285 | AC19: =IFERROR(+VLOOKUP(D19,PQ!$D$35:$E$45,2,0),0) -> 0 | AH19: 0 | AI19: =SUM(Z19:AH19) -> 62.760285 | AJ19: =+Y19-AI19 -> 653.56966 | AK19: 600301314628 | AN19: =+AN18+1 -> 12 | AO19: =+D19 -> FLORES HERRERA WENDY DEL CISNE | AP19: =+E19 -> 45065 | AQ19: =+I19 -> 30 | AR19: =+H19 -> Durán | AS19: =T19 -> 664.13 | AT19: =+AS19/12 -> 55.344167 | AU19: 0 | AW19: =($AW$7/360)*AQ19 -> 39.166667 | AX19: =+AS19/24 -> 27.672083 | AY19: =SUM(AS19:AX19) -> 786.31292 | AZ19: =+AS19*11.15% -> 74.050495 | BA19: =+AS19*1% -> 6.6413 | BB19: =SUM(AZ19:BA19) -> 80.691795
B20: =+B19+1 -> 13 | C20: 942614645 | D20: FUELA TOABANDA JOSUE CHRISTIAN | E20: 45474 | F20: ASISTENTE CONTABLE | G20: M | H20: Matriz | I20: 30 | J20: 481 | K20: =IFERROR(VLOOKUP(C20,Tabla15[[CEDULA]:[BONO VEHICULAR]],8,0),0) -> 0 | L20: 219 | M20: =+VLOOKUP(C20,Tabla335[[CEDULA ]:[US$,,]],9,0) -> 0 | P20: =+VLOOKUP(C20,'COMISIONES-SOCIOS'!$C$8:$L$57,10,0) -> 0 | Q20: =+VLOOKUP(C20,Tabla3[[CEDULA ]:[US$,]],8,0) -> 0 | R20: =+VLOOKUP($C20,Tabla3[[CEDULA ]:[US$,]],9,0) -> 0 | S20: =SUM(K20:R20) -> 219 | T20: =+J20+S20 -> 700 | U20: =VLOOKUP(C20,FR!$C$6:$M$55,11,0) -> 58.31 | Y20: =SUM(T20:X20) -> 758.31 | Z20: =T20*9.45% -> 66.15 | AC20: =IFERROR(+VLOOKUP(D20,PQ!$D$35:$E$45,2,0),0) -> 0 | AG20: 0 | AH20: 350 | AI20: =SUM(Z20:AH20) -> 416.15 | AJ20: =+Y20-AI20 -> 342.16 | AK20: 600101317776 | AN20: =+AN19+1 -> 13 | AO20: =+D20 -> FUELA TOABANDA JOSUE CHRISTIAN | AP20: =+E20 -> 45474 | AQ20: =+I20 -> 30 | AR20: =+H20 -> Matriz | AS20: =T20 -> 700 | AT20: =+AS20/12 -> 58.333333 | AU20: 0 | AW20: =($AW$7/360)*AQ20 -> 39.166667 | AX20: =+AS20/24 -> 29.166667 | AY20: =SUM(AS20:AX20) -> 826.66667 | AZ20: =+AS20*11.15% -> 78.05 | BA20: =+AS20*1% -> 7 | BB20: =SUM(AZ20:BA20) -> 85.05
B21: =+B20+1 -> 14 | C21: 951200062 | D21: GALAN LEMACHE INGRID GISELA | E21: 45139 | F21: BACK UP ADMINISTRATIVO FINANCIERO | G21: F | H21: Norte | I21: 30 | J21: 473.88 | K21: =IFERROR(VLOOKUP(C21,Tabla15[[CEDULA]:[BONO VEHICULAR]],8,0),0) -> 0 | L21: 190.25 | M21: =+VLOOKUP(C21,Tabla335[[CEDULA ]:[US$,,]],9,0) -> 0 | P21: =+VLOOKUP(C21,'COMISIONES-SOCIOS'!$C$8:$L$57,10,0) -> 0 | Q21: =+VLOOKUP(C21,Tabla3[[CEDULA ]:[US$,]],8,0) -> 0 | R21: =+VLOOKUP($C21,Tabla3[[CEDULA ]:[US$,]],9,0) -> 0 | S21: =SUM(K21:R21) -> 190.25 | T21: =+J21+S21 -> 664.13 | U21: =VLOOKUP(C21,FR!$C$6:$M$55,11,0) -> 55.322029 | Y21: =SUM(T21:X21) -> 719.45203 | Z21: =T21*9.45% -> 62.760285 | AC21: =IFERROR(+VLOOKUP(D21,PQ!$D$35:$E$45,2,0),0) -> 0 | AG21: 0 | AH21: 300 | AI21: =SUM(Z21:AH21) -> 362.76029 | AJ21: =+Y21-AI21 -> 356.69174 | AK21: 600301315318 | AN21: =+AN20+1 -> 14 | AO21: =+D21 -> GALAN LEMACHE INGRID GISELA | AP21: =+E21 -> 45139 | AQ21: =+I21 -> 30 | AR21: =+H21 -> Norte | AS21: =T21 -> 664.13 | AT21: =+AS21/12 -> 55.344167 | AU21: 0 | AW21: =($AW$7/360)*AQ21 -> 39.166667 | AX21: =+AS21/24 -> 27.672083 | AY21: =SUM(AS21:AX21) -> 786.31292 | AZ21: =+AS21*11.15% -> 74.050495 | BA21: =+AS21*1% -> 6.6413 | BB21: =SUM(AZ21:BA21) -> 80.691795
B22: =+B21+1 -> 15 | C22: 950929232 | D22: GARCIA VERA HENRY LUIS | E22: 44726 | F22: OFICIAL DE RECAUDACIONES | G22: M | H22: Norte | I22: 30 | J22: 715.54 | K22: =IFERROR(VLOOKUP(C22,Tabla15[[CEDULA]:[BONO VEHICULAR]],8,0),0) -> 0 | L22: 0 | M22: =+VLOOKUP(C22,Tabla335[[CEDULA ]:[US$,,]],9,0) -> 0 | P22: =+VLOOKUP(C22,'COMISIONES-SOCIOS'!$C$8:$L$57,10,0) -> 0 | Q22: =+VLOOKUP(C22,Tabla3[[CEDULA ]:[US$,]],8,0) -> 0 | R22: =+VLOOKUP($C22,Tabla3[[CEDULA ]:[US$,]],9,0) -> 0 | S22: =SUM(K22:R22) -> 0 | T22: =+J22+S22 -> 715.54 | U22: =VLOOKUP(C22,FR!$C$6:$M$55,11,0) -> ACUMULA | Y22: =SUM(T22:X22) -> 715.54 | Z22: =T22*9.45% -> 67.61853 | AB22: 0 | AC22: =IFERROR(+VLOOKUP(D22,PQ!$D$35:$E$45,2,0),0) -> 87.66 | AE22: =+T22*3.41% -> 24.399914 | AH22: 300 | AI22: =SUM(Z22:AH22) -> 479.67844 | AJ22: =+Y22-AI22 -> 235.86156 | AK22: 600201311725 | AN22: =+AN21+1 -> 15 | AO22: =+D22 -> GARCIA VERA HENRY LUIS | AP22: =+E22 -> 44726 | AQ22: =+I22 -> 30 | AR22: =+H22 -> Norte | AS22: =T22 -> 715.54 | AT22: =+AS22/12 -> 59.628333 | AU22: =+AS22*$AU$7 -> 59.604482 | AW22: =($AW$7/360)*AQ22 -> 39.166667 | AX22: =+AS22/24 -> 29.814167 | AY22: =SUM(AS22:AX22) -> 903.75365 | AZ22: =+AS22*11.15% -> 79.78271 | BA22: =+AS22*1% -> 7.1554 | BB22: =SUM(AZ22:BA22) -> 86.93811
B23: =+B22+1 -> 16 | C23: 953819646 | D23: GUALACEO ÑAMO JONATHAN IVÁN | E23: 44637 | F23: OFICIAL DE RECAUDACIONES | G23: M | H23: Matriz | I23: 30 | J23: 511.1 | K23: =IFERROR(VLOOKUP(C23,Tabla15[[CEDULA]:[BONO VEHICULAR]],8,0),0) -> 100 | L23: 11.11 | M23: =+VLOOKUP(C23,Tabla335[[CEDULA ]:[US$,,]],9,0) -> 0 | P23: =+VLOOKUP(C23,'COMISIONES-SOCIOS'!$C$8:$L$57,10,0) -> 0 | Q23: =+VLOOKUP(C23,Tabla3[[CEDULA ]:[US$,]],8,0) -> 0 | R23: =+VLOOKUP($C23,Tabla3[[CEDULA ]:[US$,]],9,0) -> 0 | S23: =SUM(K23:R23) -> 111.11 | T23: =+J23+S23 -> 622.21 | U23: =VLOOKUP(C23,FR!$C$6:$M$55,11,0) -> 51.830093 | Y23: =SUM(T23:X23) -> 674.04009 | Z23: =T23*9.45% -> 58.798845 | AB23: 0 | AC23: =IFERROR(+VLOOKUP(D23,PQ!$D$35:$E$45,2,0),0) -> 0 | AH23: 0 | AI23: =SUM(Z23:AH23) -> 58.798845 | AJ23: =+Y23-AI23 -> 615.24125 | AK23: 600101311237 | AN23: =+AN22+1 -> 16 | AO23: =+D23 -> GUALACEO ÑAMO JONATHAN IVÁN | AP23: =+E23 -> 44637 | AQ23: =+I23 -> 30 | AR23: =+H23 -> Matriz | AS23: =T23 -> 622.21 | AT23: =+AS23/12 -> 51.850833 | AU23: 0 | AW23: =($AW$7/360)*AQ23 -> 39.166667 | AX23: =+AS23/24 -> 25.925417 | AY23: =SUM(AS23:AX23) -> 739.15292 | AZ23: =+AS23*11.15% -> 69.376415 | BA23: =+AS23*1% -> 6.2221 | BB23: =SUM(AZ23:BA23) -> 75.598515
B24: =+B23+1 -> 17 | C24: 956953392 | D24: GUAPI YUMAGLLA OSCAR EDUARDO | E24: 45357 | F24: OFICIAL DE RECAUDACIONES | G24: M | H24: Matriz | I24: 30 | J24: 473.88 | K24: =IFERROR(VLOOKUP(C24,Tabla15[[CEDULA]:[BONO VEHICULAR]],8,0),0) -> 0 | L24: =550-J24 -> 76.12 | M24: =+VLOOKUP(C24,Tabla335[[CEDULA ]:[US$,,]],9,0) -> 0 | P24: =+VLOOKUP(C24,'COMISIONES-SOCIOS'!$C$8:$L$57,10,0) -> 0 | Q24: =+VLOOKUP(C24,Tabla3[[CEDULA ]:[US$,]],8,0) -> 0 | R24: =+VLOOKUP($C24,Tabla3[[CEDULA ]:[US$,]],9,0) -> 0 | S24: =SUM(K24:R24) -> 76.12 | T24: =+J24+S24 -> 550 | U24: =VLOOKUP(C24,FR!$C$6:$M$55,11,0) -> 45.815 | Y24: =SUM(T24:X24) -> 595.815 | Z24: =T24*9.45% -> 51.975 | AC24: =IFERROR(+VLOOKUP(D24,PQ!$D$35:$E$45,2,0),0) -> 0 | AH24: 150 | AI24: =SUM(Z24:AH24) -> 201.975 | AJ24: =+Y24-AI24 -> 393.84 | AK24: 600101005932 | AN24: =+AN23+1 -> 17 | AO24: =+D24 -> GUAPI YUMAGLLA OSCAR EDUARDO | AP24: =+E24 -> 45357 | AQ24: =+I24 -> 30 | AR24: =+H24 -> Matriz | AS24: =T24 -> 550 | AT24: =+AS24/12 -> 45.833333 | AU24: 0 | AW24: =($AW$7/360)*AQ24 -> 39.166667 | AX24: =+AS24/24 -> 22.916667 | AY24: =SUM(AS24:AX24) -> 657.91667 | AZ24: =+AS24*11.15% -> 61.325 | BA24: =+AS24*1% -> 5.5 | BB24: =SUM(AZ24:BA24) -> 66.825
B25: =+B24+1 -> 18 | C25: 956796767 | D25: GUAYANLEMA RUIZ EDINSON DAVID | E25: 44763 | F25: OFICIAL DE RECAUDACIONES | G25: M | H25: Norte | I25: 30 | J25: 473.88 | K25: =IFERROR(VLOOKUP(C25,Tabla15[[CEDULA]:[BONO VEHICULAR]],8,0),0) -> 100 | L25: 10.3 | M25: =+VLOOKUP(C25,Tabla335[[CEDULA ]:[US$,,]],9,0) -> 0 | P25: =+VLOOKUP(C25,'COMISIONES-SOCIOS'!$C$8:$L$57,10,0) -> 0 | Q25: =+VLOOKUP(C25,Tabla3[[CEDULA ]:[US$,]],8,0) -> 0 | R25: =+VLOOKUP($C25,Tabla3[[CEDULA ]:[US$,]],9,0) -> 0 | S25: =SUM(K25:R25) -> 110.3 | T25: =+J25+S25 -> 584.18 | U25: =VLOOKUP(C25,FR!$C$6:$M$55,11,0) -> 48.662194 | Y25: =SUM(T25:X25) -> 632.84219 | Z25: =T25*9.45% -> 55.20501 | AC25: =IFERROR(+VLOOKUP(D25,PQ!$D$35:$E$45,2,0),0) -> 20.96 | AH25: 390 | AI25: =SUM(Z25:AH25) -> 466.16501 | AJ25: =+Y25-AI25 -> 166.67718 | AK25: 600201312138 | AN25: =+AN24+1 -> 18 | AO25: =+D25 -> GUAYANLEMA RUIZ EDINSON DAVID | AP25: =+E25 -> 44763 | AQ25: =+I25 -> 30 | AR25: =+H25 -> Norte | AS25: =T25 -> 584.18 | AT25: =+AS25/12 -> 48.681667 | AU25: 0 | AW25: =($AW$7/360)*AQ25 -> 39.166667 | AX25: =+AS25/24 -> 24.340833 | AY25: =SUM(AS25:AX25) -> 696.36917 | AZ25: =+AS25*11.15% -> 65.13607 | BA25: =+AS25*1% -> 5.8418 | BB25: =SUM(AZ25:BA25) -> 70.97787
B26: =+B25+1 -> 19 | C26: 0932036049 | D26: HERRERA JIMENEZ CAROLINA ADELIHER | E26: 45839 | F26: ASISTENTE DE OPERACIONES | G26: F | H26: Matriz | I26: 30 | J26: 481 | K26: =IFERROR(VLOOKUP(C26,Tabla15[[CEDULA]:[BONO VEHICULAR]],8,0),0) -> 0 | L26: 0 | M26: =+VLOOKUP(C26,Tabla335[[CEDULA ]:[US$,,]],9,0) -> 0 | P26: =+VLOOKUP(C26,'COMISIONES-SOCIOS'!$C$8:$L$57,10,0) -> 0 | Q26: =+VLOOKUP(C26,Tabla3[[CEDULA ]:[US$,]],8,0) -> 0 | R26: =+VLOOKUP($C26,Tabla3[[CEDULA ]:[US$,]],9,0) -> 0 | S26: =SUM(K26:R26) -> 0 | T26: =+J26+S26 -> 481 | U26: =VLOOKUP(C26,FR!$C$6:$M$55,11,0) -> 0 | Y26: =SUM(T26:X26) -> 481 | Z26: =T26*9.45% -> 45.4545 | AC26: =IFERROR(+VLOOKUP(D26,PQ!$D$35:$E$45,2,0),0) -> 0 | AH26: 0 | AI26: =SUM(Z26:AH26) -> 45.4545 | AJ26: =+Y26-AI26 -> 435.5455 | AK26: 600101320088 | AN26: =+AN25+1 -> 19 | AO26: =+D26 -> HERRERA JIMENEZ CAROLINA ADELIHER | AP26: =+E26 -> 45839 | AQ26: =+I26 -> 30 | AR26: =+H26 -> Matriz | AS26: =T26 -> 481 | AT26: =+AS26/12 -> 40.083333 | AU26: 0 | AW26: =($AW$7/360)*AQ26 -> 39.166667 | AX26: =+AS26/24 -> 20.041667 | AY26: =SUM(AS26:AX26) -> 580.29167 | AZ26: =+AS26*11.15% -> 53.6315 | BA26: =+AS26*1% -> 4.81 | BB26: =SUM(AZ26:BA26) -> 58.4415
B27: =+B26+1 -> 20 | C27: 1724102940 | D27: HIDALGO CHERRES NESTOR VLADIMIR | E27: 45308 | F27: JEFE DE CREDITO | G27: M | H27: Durán | I27: 30 | J27: 817.76 | K27: =IFERROR(VLOOKUP(C27,Tabla15[[CEDULA]:[BONO VEHICULAR]],8,0),0) -> 0 | L27: 17.78 | M27: =+VLOOKUP(C27,Tabla335[[CEDULA ]:[US$,,]],9,0) -> 0 | P27: =+VLOOKUP(C27,'COMISIONES-SOCIOS'!$C$8:$L$57,10,0) -> 0 | Q27: =+VLOOKUP(C27,Tabla3[[CEDULA ]:[US$,]],8,0) -> 0 | R27: =+VLOOKUP($C27,Tabla3[[CEDULA ]:[US$,]],9,0) -> 0 | S27: =SUM(K27:R27) -> 17.78 | T27: =+J27+S27 -> 835.54 | U27: =VLOOKUP(C27,FR!$C$6:$M$55,11,0) -> 69.600482 | Y27: =SUM(T27:X27) -> 905.14048 | Z27: =T27*9.45% -> 78.95853 | AC27: =IFERROR(+VLOOKUP(D27,PQ!$D$35:$E$45,2,0),0) -> 0 | AH27: 500 | AI27: =SUM(Z27:AH27) -> 578.95853 | AJ27: =+Y27-AI27 -> 326.18195 | AK27: 600101010744 | AN27: =+AN26+1 -> 20 | AO27: =+D27 -> HIDALGO CHERRES NESTOR VLADIMIR | AP27: =+E27 -> 45308 | AQ27: =+I27 -> 30 | AR27: =+H27 -> Durán | AS27: =T27 -> 835.54 | AT27: =+AS27/12 -> 69.628333 | AU27: 0 | AW27: =($AW$7/360)*AQ27 -> 39.166667 | AX27: =+AS27/24 -> 34.814167 | AY27: =SUM(AS27:AX27) -> 979.14917 | AZ27: =+AS27*11.15% -> 93.16271 | BA27: =+AS27*1% -> 8.3554 | BB27: =SUM(AZ27:BA27) -> 101.51811
B28: =+B27+1 -> 21 | C28: 943322974 | D28: JANETA RUIZ ALEXANDRA DEL ROCIO | E28: 45114 | F28: OFICIAL DE RECAUDACIONES | G28: F | H28: Norte | I28: 30 | J28: 473.88 | K28: =IFERROR(VLOOKUP(C28,Tabla15[[CEDULA]:[BONO VEHICULAR]],8,0),0) -> 0 | L28: 10.3 | M28: =+VLOOKUP(C28,Tabla335[[CEDULA ]:[US$,,]],9,0) -> 0 | P28: =+VLOOKUP(C28,'COMISIONES-SOCIOS'!$C$8:$L$57,10,0) -> 0 | Q28: =+VLOOKUP(C28,Tabla3[[CEDULA ]:[US$,]],8,0) -> 0 | R28: =+VLOOKUP($C28,Tabla3[[CEDULA ]:[US$,]],9,0) -> 0 | S28: =SUM(K28:R28) -> 10.3 | T28: =+J28+S28 -> 484.18 | U28: =VLOOKUP(C28,FR!$C$6:$M$55,11,0) -> 40.332194 | Y28: =SUM(T28:X28) -> 524.51219 | Z28: =T28*9.45% -> 45.75501 | AB28: 0 | AC28: =IFERROR(+VLOOKUP(D28,PQ!$D$35:$E$45,2,0),0) -> 0 | AH28: 100 | AI28: =SUM(Z28:AH28) -> 145.75501 | AJ28: =+Y28-AI28 -> 378.75718 | AK28: 600201315080 | AN28: =+AN27+1 -> 21 | AO28: =+D28 -> JANETA RUIZ ALEXANDRA DEL ROCIO | AP28: =+E28 -> 45114 | AQ28: =+I28 -> 30 | AR28: =+H28 -> Norte | AS28: =T28 -> 484.18 | AT28: =+AS28/12 -> 40.348333 | AU28: 0 | AW28: =($AW$7/360)*AQ28 -> 39.166667 | AX28: =+AS28/24 -> 20.174167 | AY28: =SUM(AS28:AX28) -> 583.86917 | AZ28: =+AS28*11.15% -> 53.98607 | BA28: =+AS28*1% -> 4.8418 | BB28: =SUM(AZ28:BA28) -> 58.82787
B29: =+B28+1 -> 22 | C29: 941096851 | D29: LEMA CHIRAU RAMONA MARIA | E29: 43033 | F29: ASESOR DE CAPTACIONES | G29: F | H29: Durán | I29: 30 | J29: 700 | K29: =IFERROR(VLOOKUP(C29,Tabla15[[CEDULA]:[BONO VEHICULAR]],8,0),0) -> 0 | L29: 0 | M29: =+VLOOKUP(C29,Tabla335[[CEDULA ]:[US$,,]],9,0) -> 0 | P29: =+VLOOKUP(C29,'COMISIONES-SOCIOS'!$C$8:$L$57,10,0) -> 0 | Q29: =+VLOOKUP(C29,Tabla3[[CEDULA ]:[US$,]],8,0) -> 0 | R29: =+VLOOKUP($C29,Tabla3[[CEDULA ]:[US$,]],9,0) -> 0 | S29: =SUM(K29:R29) -> 0 | T29: =+J29+S29 -> 700 | U29: =VLOOKUP(C29,FR!$C$6:$M$55,11,0) -> 58.31 | Y29: =SUM(T29:X29) -> 758.31 | Z29: =T29*9.45% -> 66.15 | AC29: =IFERROR(+VLOOKUP(D29,PQ!$D$35:$E$45,2,0),0) -> 0 | AH29: 480.64 | AI29: =SUM(Z29:AH29) -> 546.79 | AJ29: =+Y29-AI29 -> 211.52 | AK29: 600101005442 | AN29: =+AN28+1 -> 22 | AO29: =+D29 -> LEMA CHIRAU RAMONA MARIA | AP29: =+E29 -> 43033 | AQ29: =+I29 -> 30 | AR29: =+H29 -> Durán | AS29: =T29 -> 700 | AT29: =+AS29/12 -> 58.333333 | AU29: 0 | AW29: =($AW$7/360)*AQ29 -> 39.166667 | AX29: =+AS29/24 -> 29.166667 | AY29: =SUM(AS29:AX29) -> 826.66667 | AZ29: =+AS29*11.15% -> 78.05 | BA29: =+AS29*1% -> 7 | BB29: =SUM(AZ29:BA29) -> 85.05
B30: =+B29+1 -> 23 | C30: 957093800 | D30: LEMA TADAY BRAYAN WIDINSON | E30: 45793 | F30: OFICIAL DE RECAUDACIONES | G30: M | H30: Durán | I30: 30 | J30: 473.88 | K30: =IFERROR(VLOOKUP(C30,Tabla15[[CEDULA]:[BONO VEHICULAR]],8,0),0) -> 40 | M30: =+VLOOKUP(C30,Tabla335[[CEDULA ]:[US$,,]],9,0) -> 0 | P30: =+VLOOKUP(C30,'COMISIONES-SOCIOS'!$C$8:$L$57,10,0) -> 0 | Q30: =+VLOOKUP(C30,Tabla3[[CEDULA ]:[US$,]],8,0) -> 0 | R30: =+VLOOKUP($C30,Tabla3[[CEDULA ]:[US$,]],9,0) -> 0 | S30: =SUM(K30:R30) -> 40 | T30: =+J30+S30 -> 513.88 | U30: =VLOOKUP(C30,FR!$C$6:$M$55,11,0) -> 0 | Y30: =SUM(T30:X30) -> 513.88 | Z30: =T30*9.45% -> 48.56166 | AC30: =IFERROR(+VLOOKUP(D30,PQ!$D$35:$E$45,2,0),0) -> 0 | AD30: 288.8555 | AH30: 0 | AI30: =SUM(Z30:AH30) -> 337.41716 | AJ30: =+Y30-AI30 -> 176.46284 | AK30: 600301319714 | AN30: =+AN29+1 -> 23 | AO30: =+D30 -> LEMA TADAY BRAYAN WIDINSON | AP30: =+E30 -> 45793 | AQ30: =+I30 -> 30 | AR30: =+H30 -> Durán | AS30: =T30 -> 513.88 | AT30: =+AS30/12 -> 42.823333 | AU30: 0 | AW30: =($AW$7/360)*AQ30 -> 39.166667 | AX30: =+AS30/24 -> 21.411667 | AY30: =SUM(AS30:AX30) -> 617.28167 | AZ30: =+AS30*11.15% -> 57.29762 | BA30: =+AS30*1% -> 5.1388 | BB30: =SUM(AZ30:BA30) -> 62.43642
B31: =+B30+1 -> 24 | C31: 957924350 | D31: LLUMI YUQUILEMA MAYCOOL DANNY | E31: 45727 | F31: ASESOR DE NEGOCIOS | G31: M | H31: Matriz | I31: 30 | J31: 481 | K31: =IFERROR(VLOOKUP(C31,Tabla15[[CEDULA]:[BONO VEHICULAR]],8,0),0) -> 0 | M31: =+VLOOKUP(C31,Tabla335[[CEDULA ]:[US$,,]],9,0) -> 0 | P31: =+VLOOKUP(C31,'COMISIONES-SOCIOS'!$C$8:$L$57,10,0) -> 0 | Q31: =+VLOOKUP(C31,Tabla3[[CEDULA ]:[US$,]],8,0) -> 0 | R31: =+VLOOKUP($C31,Tabla3[[CEDULA ]:[US$,]],9,0) -> 0 | S31: =SUM(K31:R31) -> 0 | T31: =+J31+S31 -> 481 | U31: =VLOOKUP(C31,FR!$C$6:$M$55,11,0) -> 0 | Y31: =SUM(T31:X31) -> 481 | Z31: =T31*9.45% -> 45.4545 | AC31: =IFERROR(+VLOOKUP(D31,PQ!$D$35:$E$45,2,0),0) -> 0 | AH31: 0 | AI31: =SUM(Z31:AH31) -> 45.4545 | AJ31: =+Y31-AI31 -> 435.5455 | AK31: 600101000665 | AN31: =+AN30+1 -> 24 | AO31: =+D31 -> LLUMI YUQUILEMA MAYCOOL DANNY | AP31: =+E31 -> 45727 | AQ31: =+I31 -> 30 | AR31: =+H31 -> Matriz | AS31: =T31 -> 481 | AT31: =+AS31/12 -> 40.083333 | AU31: 0 | AW31: =($AW$7/360)*AQ31 -> 39.166667 | AX31: =+AS31/24 -> 20.041667 | AY31: =SUM(AS31:AX31) -> 580.29167 | AZ31: =+AS31*11.15% -> 53.6315 | BA31: =+AS31*1% -> 4.81 | BB31: =SUM(AZ31:BA31) -> 58.4415
B32: =+B31+1 -> 25 | C32: 603838657 | D32: MALAN DELGADO JOSE ALBERTO | E32: 44835 | F32: OFICIAL DE RECAUDACIONES | G32: M | H32: Durán | I32: 30 | J32: 473.88 | K32: =IFERROR(VLOOKUP(C32,Tabla15[[CEDULA]:[BONO VEHICULAR]],8,0),0) -> 200 | L32: 10.3 | M32: =+VLOOKUP(C32,Tabla335[[CEDULA ]:[US$,,]],9,0) -> 0 | P32: =+VLOOKUP(C32,'COMISIONES-SOCIOS'!$C$8:$L$57,10,0) -> 0 | Q32: =+VLOOKUP(C32,Tabla3[[CEDULA ]:[US$,]],8,0) -> 0 | R32: =+VLOOKUP($C32,Tabla3[[CEDULA ]:[US$,]],9,0) -> 0 | S32: =SUM(K32:R32) -> 210.3 | T32: =+J32+S32 -> 684.18 | U32: =VLOOKUP(C32,FR!$C$6:$M$55,11,0) -> 56.992194 | Y32: =SUM(T32:X32) -> 741.17219 | Z32: =T32*9.45% -> 64.65501 | AC32: =IFERROR(+VLOOKUP(D32,PQ!$D$35:$E$45,2,0),0) -> 36.13 | AH32: 400 | AI32: =SUM(Z32:AH32) -> 500.78501 | AJ32: =+Y32-AI32 -> 240.38718 | AK32: 600101000624 | AN32: =+AN31+1 -> 25 | AO32: =+D32 -> MALAN DELGADO JOSE ALBERTO | AP32: =+E32 -> 44835 | AQ32: =+I32 -> 30 | AR32: =+H32 -> Durán | AS32: =T32 -> 684.18 | AT32: =+AS32/12 -> 57.015 | AU32: 0 | AW32: =($AW$7/360)*AQ32 -> 39.166667 | AX32: =+AS32/24 -> 28.5075 | AY32: =SUM(AS32:AX32) -> 808.86917 | AZ32: =+AS32*11.15% -> 76.28607 | BA32: =+AS32*1% -> 6.8418 | BB32: =SUM(AZ32:BA32) -> 83.12787
B33: =+B32+1 -> 26 | C33: 925240525 | D33: MALAN YUQUILEMA RAUL ALBERTO | E33: 38869 | F33: ASESOR LEGAL | G33: M | H33: Matriz | I33: 30 | J33: 2700 | K33: =IFERROR(VLOOKUP(C33,Tabla15[[CEDULA]:[BONO VEHICULAR]],8,0),0) -> 0 | L33: 0 | M33: =+VLOOKUP(C33,Tabla335[[CEDULA ]:[US$,,]],9,0) -> 0 | P33: =+VLOOKUP(C33,'COMISIONES-SOCIOS'!$C$8:$L$57,10,0) -> 0 | Q33: =+VLOOKUP(C33,Tabla3[[CEDULA ]:[US$,]],8,0) -> 0 | R33: =+VLOOKUP($C33,Tabla3[[CEDULA ]:[US$,]],9,0) -> 0 | S33: =SUM(K33:R33) -> 0 | T33: =+J33+S33 -> 2700 | U33: =VLOOKUP(C33,FR!$C$6:$M$55,11,0) -> 224.91 | W33: =(+T33/12) -> 225 | X33: =(470/12) -> 39.166667 | Y33: =SUM(T33:X33) -> 3189.0767 | Z33: =T33*9.45% -> 255.15 | AA33: 51.88 | AB33: 0 | AC33: =IFERROR(+VLOOKUP(D33,PQ!$D$35:$E$45,2,0),0) -> 0 | AH33: 0 | AI33: =SUM(Z33:AH33) -> 307.03 | AJ33: =+Y33-AI33 -> 2882.0467 | AK33: 600101000359 | AN33: =+AN32+1 -> 26 | AO33: =+D33 -> MALAN YUQUILEMA RAUL ALBERTO | AP33: =+E33 -> 38869 | AQ33: =+I33 -> 30 | AR33: =+H33 -> Matriz | AS33: =T33 -> 2700 | AT33: 0 | AU33: 0 | AW33: 0 | AX33: =+AS33/24 -> 112.5 | AY33: =SUM(AS33:AX33) -> 2812.5 | AZ33: =+AS33*11.15% -> 301.05 | BA33: =+AS33*1% -> 27 | BB33: =SUM(AZ33:BA33) -> 328.05
B34: =+B33+1 -> 27 | C34: 954520599 | D34: MARSHALL VEGA YULIANA LISSETT | E34: 44743 | F34: ASESOR DE NEGOCIOS | G34: F | H34: Durán | I34: 30 | J34: 613.32 | K34: =IFERROR(VLOOKUP(C34,Tabla15[[CEDULA]:[BONO VEHICULAR]],8,0),0) -> 0 | L34: 13.33 | M34: =+VLOOKUP(C34,Tabla335[[CEDULA ]:[US$,,]],9,0) -> 0 | P34: =+VLOOKUP(C34,'COMISIONES-SOCIOS'!$C$8:$L$57,10,0) -> 0 | Q34: =+VLOOKUP(C34,Tabla3[[CEDULA ]:[US$,]],8,0) -> 0 | R34: =+VLOOKUP($C34,Tabla3[[CEDULA ]:[US$,]],9,0) -> 0 | S34: =SUM(K34:R34) -> 13.33 | T34: =+J34+S34 -> 626.65 | U34: =VLOOKUP(C34,FR!$C$6:$M$55,11,0) -> 52.199945 | Y34: =SUM(T34:X34) -> 678.84995 | Z34: =T34*9.45% -> 59.218425 | AC34: =IFERROR(+VLOOKUP(D34,PQ!$D$35:$E$45,2,0),0) -> 27.17 | AH34: 500 | AI34: =SUM(Z34:AH34) -> 586.38842 | AJ34: =+Y34-AI34 -> 92.46152 | AK34: 600201312163 | AN34: =+AN33+1 -> 27 | AO34: =+D34 -> MARSHALL VEGA YULIANA LISSETT | AP34: =+E34 -> 44743 | AQ34: =+I34 -> 30 | AR34: =+H34 -> Durán | AS34: =T34 -> 626.65 | AT34: =+AS34/12 -> 52.220833 | AU34: 0 | AW34: =($AW$7/360)*AQ34 -> 39.166667 | AX34: =+AS34/24 -> 26.110417 | AY34: =SUM(AS34:AX34) -> 744.14792 | AZ34: =+AS34*11.15% -> 69.871475 | BA34: =+AS34*1% -> 6.2665 | BB34: =SUM(AZ34:BA34) -> 76.137975
B35: =+B34+1 -> 28 | C35: 0943906032 | D35: MEZA RODRIGUEZ MICHAEL FERNANDO | E35: 45524 | F35: OFICIAL DE RECAUDACIONES | G35: M | H35: Norte | I35: 30 | J35: 473.88 | K35: =IFERROR(VLOOKUP(C35,Tabla15[[CEDULA]:[BONO VEHICULAR]],8,0),0) -> 100 | L35: 10.3 | M35: =+VLOOKUP(C35,Tabla335[[CEDULA ]:[US$,,]],9,0) -> 0 | P35: =+VLOOKUP(C35,'COMISIONES-SOCIOS'!$C$8:$L$57,10,0) -> 0 | Q35: =+VLOOKUP(C35,Tabla3[[CEDULA ]:[US$,]],8,0) -> 0 | R35: =+VLOOKUP($C35,Tabla3[[CEDULA ]:[US$,]],9,0) -> 0 | S35: =SUM(K35:R35) -> 110.3 | T35: =+J35+S35 -> 584.18 | U35: =VLOOKUP(C35,FR!$C$6:$M$55,11,0) -> 48.662194 | Y35: =SUM(T35:X35) -> 632.84219 | Z35: =T35*9.45% -> 55.20501 | AC35: =IFERROR(+VLOOKUP(D35,PQ!$D$35:$E$45,2,0),0) -> 0 | AD35: 0 | AH35: 300 | AI35: =SUM(Z35:AH35) -> 355.20501 | AJ35: =+Y35-AI35 -> 277.63718 | AK35: 600201318181 | AN35: =+AN34+1 -> 28 | AO35: =+D35 -> MEZA RODRIGUEZ MICHAEL FERNANDO | AP35: =+E35 -> 45524 | AQ35: =+I35 -> 30 | AR35: =+H35 -> Norte | AS35: =T35 -> 584.18 | AT35: =+AS35/12 -> 48.681667 | AU35: 0 | AW35: =($AW$7/360)*AQ35 -> 39.166667 | AX35: =+AS35/24 -> 24.340833 | AY35: =SUM(AS35:AX35) -> 696.36917 | AZ35: =+AS35*11.15% -> 65.13607 | BA35: =+AS35*1% -> 5.8418 | BB35: =SUM(AZ35:BA35) -> 70.97787
B36: =+B35+1 -> 29 | C36: 0919306050 | D36: MORAN GARCIA DANNY FAVIAN | E36: 45376 | F36: OFICIAL DE CUMPLIMIENTO | G36: M | H36: Matriz | I36: 30 | J36: 600 | K36: =IFERROR(VLOOKUP(C36,Tabla15[[CEDULA]:[BONO VEHICULAR]],8,0),0) -> 0 | L36: =200+13.044 -> 213.044 | M36: =+VLOOKUP(C36,Tabla335[[CEDULA ]:[US$,,]],9,0) -> 0 | P36: =+VLOOKUP(C36,'COMISIONES-SOCIOS'!$C$8:$L$57,10,0) -> 0 | Q36: =+VLOOKUP(C36,Tabla3[[CEDULA ]:[US$,]],8,0) -> 0 | R36: =+VLOOKUP($C36,Tabla3[[CEDULA ]:[US$,]],9,0) -> 0 | S36: =SUM(K36:R36) -> 213.044 | T36: =+J36+S36 -> 813.044 | U36: =VLOOKUP(C36,FR!$C$6:$M$55,11,0) -> 67.726565 | Y36: =SUM(T36:X36) -> 880.77057 | Z36: =T36*9.45% -> 76.832658 | AC36: =IFERROR(+VLOOKUP(D36,PQ!$D$35:$E$45,2,0),0) -> 0 | AE36: =+T36*3.41% -> 27.7248 | AH36: 550 | AI36: =SUM(Z36:AH36) -> 654.55746 | AJ36: =+Y36-AI36 -> 226.21311 | AK36: 600101317150 | AN36: =+AN35+1 -> 29 | AO36: =+D36 -> MORAN GARCIA DANNY FAVIAN | AP36: =+E36 -> 45376 | AQ36: =+I36 -> 30 | AR36: =+H36 -> Matriz | AS36: =T36 -> 813.044 | AT36: =+AS36/12 -> 67.753667 | AU36: 0 | AW36: =($AW$7/360)*AQ36 -> 39.166667 | AX36: =+AS36/24 -> 33.876833 | AY36: =SUM(AS36:AX36) -> 953.84117 | AZ36: =+AS36*11.15% -> 90.654406 | BA36: =+AS36*1% -> 8.13044 | BB36: =SUM(AZ36:BA36) -> 98.784846
B37: =+B36+1 -> 30 | C37: 0941235376 | D37: MOREIRA ESPINOZA LINDA ELIZABETH | E37: 45551 | F37: CAJERO FINANCIERO | G37: F | H37: Durán | I37: 30 | J37: 481 | K37: =IFERROR(VLOOKUP(C37,Tabla15[[CEDULA]:[BONO VEHICULAR]],8,0),0) -> 0 | L37: 10.46 | M37: =+VLOOKUP(C37,Tabla335[[CEDULA ]:[US$,,]],9,0) -> 0 | P37: =+VLOOKUP(C37,'COMISIONES-SOCIOS'!$C$8:$L$57,10,0) -> 0 | Q37: =+VLOOKUP(C37,Tabla3[[CEDULA ]:[US$,]],8,0) -> 0 | R37: =+VLOOKUP($C37,Tabla3[[CEDULA ]:[US$,]],9,0) -> 0 | S37: =SUM(K37:R37) -> 10.46 | T37: =+J37+S37 -> 491.46 | U37: =VLOOKUP(C37,FR!$C$6:$M$55,11,0) -> 19.104688 | Y37: =SUM(T37:X37) -> 510.56469 | Z37: =T37*9.45% -> 46.44297 | AC37: =IFERROR(+VLOOKUP(D37,PQ!$D$35:$E$45,2,0),0) -> 35.22 | AG37: 0 | AH37: 332.13 | AI37: =SUM(Z37:AH37) -> 413.79297 | AJ37: =+Y37-AI37 -> 96.771718 | AK37: 600301318316 | AN37: =+AN36+1 -> 30 | AO37: =+D37 -> MOREIRA ESPINOZA LINDA ELIZABETH | AP37: =+E37 -> 45551 | AQ37: =+I37 -> 30 | AR37: =+H37 -> Durán | AS37: =T37 -> 491.46 | AT37: =+AS37/12 -> 40.955 | AU37: 0 | AW37: =($AW$7/360)*AQ37 -> 39.166667 | AX37: =+AS37/24 -> 20.4775 | AY37: =SUM(AS37:AX37) -> 592.05917 | AZ37: =+AS37*11.15% -> 54.79779 | BA37: =+AS37*1% -> 4.9146 | BB37: =SUM(AZ37:BA37) -> 59.71239
B38: =+B37+1 -> 31 | C38: 955395686 | D38: MOROCHO DUCHI SANDRA STEPHANIE | E38: 44211 | F38: ASESOR DE NEGOCIOS | G38: F | H38: Norte | I38: 30 | J38: 613.32 | K38: =IFERROR(VLOOKUP(C38,Tabla15[[CEDULA]:[BONO VEHICULAR]],8,0),0) -> 0 | L38: 13.33 | M38: =+VLOOKUP(C38,Tabla335[[CEDULA ]:[US$,,]],9,0) -> 0 | P38: =+VLOOKUP(C38,'COMISIONES-SOCIOS'!$C$8:$L$57,10,0) -> 0 | Q38: =+VLOOKUP(C38,Tabla3[[CEDULA ]:[US$,]],8,0) -> 0 | R38: =+VLOOKUP($C38,Tabla3[[CEDULA ]:[US$,]],9,0) -> 0 | S38: =SUM(K38:R38) -> 13.33 | T38: =+J38+S38 -> 626.65 | U38: =VLOOKUP(C38,FR!$C$6:$M$55,11,0) -> 52.199945 | Y38: =SUM(T38:X38) -> 678.84995 | Z38: =T38*9.45% -> 59.218425 | AC38: =IFERROR(+VLOOKUP(D38,PQ!$D$35:$E$45,2,0),0) -> 0 | AH38: 100 | AI38: =SUM(Z38:AH38) -> 159.21842 | AJ38: =+Y38-AI38 -> 519.63152 | AK38: 600101012152 | AN38: =+AN37+1 -> 31 | AO38: =+D38 -> MOROCHO DUCHI SANDRA STEPHANIE | AP38: =+E38 -> 44211 | AQ38: =+I38 -> 30 | AR38: =+H38 -> Norte | AS38: =T38 -> 626.65 | AT38: =+AS38/12 -> 52.220833 | AU38: 0 | AW38: =($AW$7/360)*AQ38 -> 39.166667 | AX38: =+AS38/24 -> 26.110417 | AY38: =SUM(AS38:AX38) -> 744.14792 | AZ38: =+AS38*11.15% -> 69.871475 | BA38: =+AS38*1% -> 6.2665 | BB38: =SUM(AZ38:BA38) -> 76.137975
B39: =+B38+1 -> 32 | C39: 940991987 | D39: MOROCHO YANTALEMA DINA MAGALY | E39: 43074 | F39: TALENTO HUMANO | G39: F | H39: Matriz | I39: 30 | J39: 766.65 | K39: =IFERROR(VLOOKUP(C39,Tabla15[[CEDULA]:[BONO VEHICULAR]],8,0),0) -> 0 | L39: =850-J39 -> 83.35 | M39: =+VLOOKUP(C39,Tabla335[[CEDULA ]:[US$,,]],9,0) -> 0 | P39: =+VLOOKUP(C39,'COMISIONES-SOCIOS'!$C$8:$L$57,10,0) -> 0 | Q39: =+VLOOKUP(C39,Tabla3[[CEDULA ]:[US$,]],8,0) -> 0 | R39: =+VLOOKUP($C39,Tabla3[[CEDULA ]:[US$,]],9,0) -> 0 | S39: =SUM(K39:R39) -> 83.35 | T39: =+J39+S39 -> 850 | U39: =VLOOKUP(C39,FR!$C$6:$M$55,11,0) -> 70.805 | Y39: =SUM(T39:X39) -> 920.805 | Z39: =T39*9.45% -> 80.325 | AC39: =IFERROR(+VLOOKUP(D39,PQ!$D$35:$E$45,2,0),0) -> 0 | AD39: 0 | AH39: 700 | AI39: =SUM(Z39:AH39) -> 780.325 | AJ39: =+Y39-AI39 -> 140.48 | AK39: 600101009583 | AN39: =+AN38+1 -> 32 | AO39: =+D39 -> MOROCHO YANTALEMA DINA MAGALY | AP39: =+E39 -> 43074 | AQ39: =+I39 -> 30 | AR39: =+H39 -> Matriz | AS39: =T39 -> 850 | AT39: =+AS39/12 -> 70.833333 | AU39: 0 | AW39: =($AW$7/360)*AQ39 -> 39.166667 | AX39: =+AS39/24 -> 35.416667 | AY39: =SUM(AS39:AX39) -> 995.41667 | AZ39: =+AS39*11.15% -> 94.775 | BA39: =+AS39*1% -> 8.5 | BB39: =SUM(AZ39:BA39) -> 103.275
B40: =+B39+1 -> 33 | C40: 956929277 | D40: NAULA CRIOLLO CINTHYA ABIGAIL | E40: 45721 | F40: CAJERO FINANCIERO | G40: M | H40: Matriz | I40: 30 | J40: 481 | K40: =IFERROR(VLOOKUP(C40,Tabla15[[CEDULA]:[BONO VEHICULAR]],8,0),0) -> 0 | L40: =650-J40 -> 169 | M40: =+VLOOKUP(C40,Tabla335[[CEDULA ]:[US$,,]],9,0) -> 0 | P40: =+VLOOKUP(C40,'COMISIONES-SOCIOS'!$C$8:$L$57,10,0) -> 0 | Q40: =+VLOOKUP(C40,Tabla3[[CEDULA ]:[US$,]],8,0) -> 0 | R40: =+VLOOKUP($C40,Tabla3[[CEDULA ]:[US$,]],9,0) -> 0 | S40: =SUM(K40:R40) -> 169 | T40: =+J40+S40 -> 650 | U40: =VLOOKUP(C40,FR!$C$6:$M$55,11,0) -> 0 | Y40: =SUM(T40:X40) -> 650 | Z40: =T40*9.45% -> 61.425 | AC40: =IFERROR(+VLOOKUP(D40,PQ!$D$35:$E$45,2,0),0) -> 0 | AH40: 0 | AI40: =SUM(Z40:AH40) -> 61.425 | AJ40: =+Y40-AI40 -> 588.575 | AK40: 600201319284 | AN40: =+AN39+1 -> 33 | AO40: =+D40 -> NAULA CRIOLLO CINTHYA ABIGAIL | AP40: =+E40 -> 45721 | AQ40: =+I40 -> 30 | AR40: =+H40 -> Matriz | AS40: =T40 -> 650 | AT40: =+AS40/12 -> 54.166667 | AU40: 0 | AW40: =($AW$7/360)*AQ40 -> 39.166667 | AX40: =+AS40/24 -> 27.083333 | AY40: =SUM(AS40:AX40) -> 770.41667 | AZ40: =+AS40*11.15% -> 72.475 | BA40: =+AS40*1% -> 6.5 | BB40: =SUM(AZ40:BA40) -> 78.975
B41: =+B40+1 -> 34 | C41: 951763994 | D41: NEVAREZ PEÑAFIEL EVELYN JULEXY | E41: 45240 | F41: ASESOR DE CAPTACIONES | G41: F | H41: Norte | I41: 30 | J41: 475.85 | K41: =IFERROR(VLOOKUP(C41,Tabla15[[CEDULA]:[BONO VEHICULAR]],8,0),0) -> 0 | L41: =700-J41-30.32 -> 193.83 | M41: =+VLOOKUP(C41,Tabla335[[CEDULA ]:[US$,,]],9,0) -> 0 | P41: =+VLOOKUP(C41,'COMISIONES-SOCIOS'!$C$8:$L$57,10,0) -> 0 | Q41: =+VLOOKUP(C41,Tabla3[[CEDULA ]:[US$,]],8,0) -> 0 | R41: =+VLOOKUP($C41,Tabla3[[CEDULA ]:[US$,]],9,0) -> 0 | S41: =SUM(K41:R41) -> 193.83 | T41: =+J41+S41 -> 669.68 | U41: =VLOOKUP(C41,FR!$C$6:$M$55,11,0) -> ACUMULA | Y41: =SUM(T41:X41) -> 669.68 | Z41: =T41*9.45% -> 63.28476 | AC41: =IFERROR(+VLOOKUP(D41,PQ!$D$35:$E$45,2,0),0) -> 0 | AH41: 0 | AI41: =SUM(Z41:AH41) -> 63.28476 | AJ41: =+Y41-AI41 -> 606.39524 | AK41: 600101315986 | AN41: =+AN40+1 -> 34 | AO41: =+D41 -> NEVAREZ PEÑAFIEL EVELYN JULEXY | AP41: =+E41 -> 45240 | AQ41: =+I41 -> 30 | AR41: =+H41 -> Norte | AS41: =T41 -> 669.68 | AT41: =+AS41/12 -> 55.806667 | AU41: =+AS41*$AU$7 -> 55.784344 | AW41: =($AW$7/360)*AQ41 -> 39.166667 | AX41: =+AS41/24 -> 27.903333 | AY41: =SUM(AS41:AX41) -> 848.34101 | AZ41: =+AS41*11.15% -> 74.66932 | BA41: =+AS41*1% -> 6.6968 | BB41: =SUM(AZ41:BA41) -> 81.36612
...

Sheet BONO vehicular
B2: CALCULO BONO VEHICULAR
B3: NOMINA SEPTIEMBRE 2025
B6: No. | C6: CEDULA | D6: NOMBRE | E6: FECHA DE INGRESO | F6: CARGO | G6: AGENCIA | H6: DIAS TRABAJADOS | I6: SUELDO | J6: BONO VEHICULAR | K6: Columna1 | N6: DEPARTAMENTOS RECIBEN BONO | O6: BONOS
B7: 1 | C7: 955741970 | D7: =+VLOOKUP(Tabla15[[#This Row],[CEDULA]],'OCTUBRE 2025'!$C$8:$J$57,2,0) -> CHACAGUASAY CHACAGUASAY ROBERTH CRISTHIAN | E7: 01/MARZO/2023 | F7: =+VLOOKUP(Tabla15[[#This Row],[CEDULA]],'OCTUBRE 2025'!$C$8:$J$57,4,0) -> OFICIAL DE RECAUDACIONES | G7: Matriz | H7: =+VLOOKUP(Tabla15[[#This Row],[CEDULA]],'OCTUBRE 2025'!$C$8:$J$57,7,0) -> 30 | I7: =+VLOOKUP(Tabla15[[#This Row],[CEDULA]],'OCTUBRE 2025'!$C$8:$J$57,8,0) -> 473.88 | J7: =100 -> 100 | N7: EJECUTIVO DE CAPTACIONES | O7: 100
B8: 2 | C8: 944143148 | D8: =+VLOOKUP(Tabla15[[#This Row],[CEDULA]],'OCTUBRE 2025'!$C$8:$J$57,2,0) -> CHIMBOLEMA YUNGAN MARIO EFRAIN | E8: 27/ABRIL/2023 | F8: EJECUTIVO DE RECAUDACION | G8: Matriz | H8: =+VLOOKUP(Tabla15[[#This Row],[CEDULA]],'OCTUBRE 2025'!$C$8:$J$57,7,0) -> 9 | I8: =+VLOOKUP(Tabla15[[#This Row],[CEDULA]],'OCTUBRE 2025'!$C$8:$J$57,8,0) -> 142.16 | J8: =+(3.33333333333333)*Tabla15[[#This Row],[DIAS TRABAJADOS]] -> 30 | N8: ASESOR LEGAL | O8: 200
B9: 3 | C9: 950929232 | D9: =+VLOOKUP(Tabla15[[#This Row],[CEDULA]],'OCTUBRE 2025'!$C$8:$J$57,2,0) -> GARCIA VERA HENRY LUIS | E9: 14/JUNIO/2022 | F9: EJECUTIVO DE RECAUDACION | G9: Norte | H9: =+VLOOKUP(Tabla15[[#This Row],[CEDULA]],'OCTUBRE 2025'!$C$8:$J$57,7,0) -> 30 | I9: =+VLOOKUP(Tabla15[[#This Row],[CEDULA]],'OCTUBRE 2025'!$C$8:$J$57,8,0) -> 715.54 | J9: 0 | N9: JEFE DE AGENCIA | O9: 200
B10: 4 | C10: 953819646 | D10: =+VLOOKUP(Tabla15[[#This Row],[CEDULA]],'OCTUBRE 2025'!$C$8:$J$57,2,0) -> GUALACEO ÑAMO JONATHAN IVÁN | E10: 17/MARZO/2022 | F10: EJECUTIVO DE RECAUDACION | G10: Matriz | H10: =+VLOOKUP(Tabla15[[#This Row],[CEDULA]],'OCTUBRE 2025'!$C$8:$J$57,7,0) -> 30 | I10: =+VLOOKUP(Tabla15[[#This Row],[CEDULA]],'OCTUBRE 2025'!$C$8:$J$57,8,0) -> 511.1 | J10: =100 -> 100 | N10: JEFE DE BOVEDA | O10: 300
B11: 5 | C11: 956796767 | D11: =+VLOOKUP(Tabla15[[#This Row],[CEDULA]],'OCTUBRE 2025'!$C$8:$J$57,2,0) -> GUAYANLEMA RUIZ EDINSON DAVID | E11: 21/JULIO/2022 | F11: EJECUTIVO DE RECAUDACION | G11: Norte | H11: =+VLOOKUP(Tabla15[[#This Row],[CEDULA]],'OCTUBRE 2025'!$C$8:$J$57,7,0) -> 30 | I11: =+VLOOKUP(Tabla15[[#This Row],[CEDULA]],'OCTUBRE 2025'!$C$8:$J$57,8,0) -> 473.88 | J11: =100 -> 100 | N11: JEFE DE RECAUDACIÓN | O11: 200
B12: 6 | C12: 957093800 | D12: =+VLOOKUP(Tabla15[[#This Row],[CEDULA]],'OCTUBRE 2025'!$C$8:$J$57,2,0) -> LEMA TADAY BRAYAN WIDINSON | E12: 01/MAYO/2023 | F12: EJECUTIVO DE RECAUDACION | G12: Durán | H12: =+VLOOKUP(Tabla15[[#This Row],[CEDULA]],'OCTUBRE 2025'!$C$8:$J$57,7,0) -> 30 | I12: =+VLOOKUP(Tabla15[[#This Row],[CEDULA]],'OCTUBRE 2025'!$C$8:$J$57,8,0) -> 473.88 | J12: =+(3.33333333333333)*Tabla15[[#This Row],[DIAS TRABAJADOS]]-60 -> 40
B13: 7 | C13: 603838657 | D13: =+VLOOKUP(Tabla15[[#This Row],[CEDULA]],'OCTUBRE 2025'!$C$8:$J$57,2,0) -> MALAN DELGADO JOSE ALBERTO | E13: 01/OCTUBRE/2022 | F13: EJECUTIVO DE RECAUDACION | G13: Durán | H13: =+VLOOKUP(Tabla15[[#This Row],[CEDULA]],'OCTUBRE 2025'!$C$8:$J$57,7,0) -> 30 | I13: =+VLOOKUP(Tabla15[[#This Row],[CEDULA]],'OCTUBRE 2025'!$C$8:$J$57,8,0) -> 473.88 | J13: 200
B14: 8 | C14: 925240525 | D14: =+VLOOKUP(Tabla15[[#This Row],[CEDULA]],'OCTUBRE 2025'!$C$8:$J$57,2,0) -> MALAN YUQUILEMA RAUL ALBERTO | E14: 01/JUNIO/2006 | F14: ASESOR LEGAL | G14: Matriz | H14: =+VLOOKUP(Tabla15[[#This Row],[CEDULA]],'OCTUBRE 2025'!$C$8:$J$57,7,0) -> 30 | I14: =+VLOOKUP(Tabla15[[#This Row],[CEDULA]],'OCTUBRE 2025'!$C$8:$J$57,8,0) -> 2700 | J14: =200-200 -> 0
C15: 0943906032 | D15: =+VLOOKUP(Tabla15[[#This Row],[CEDULA]],'OCTUBRE 2025'!$C$8:$J$57,2,0) -> MEZA RODRIGUEZ MICHAEL FERNANDO | F15: EJECUTIVO DE RECAUDACION | G15: Norte | H15: 30 | I15: 473.88 | J15: =100 -> 100
B16: 9 | C16: 950703199 | D16: =+VLOOKUP(Tabla15[[#This Row],[CEDULA]],'OCTUBRE 2025'!$C$8:$J$57,2,0) -> ÑAMO GUALACEO BRYAN JAVIER | E16: 13/OCTUBRE/2022 | F16: EJECUTIVO DE RECAUDACION | G16: Matriz | H16: =+VLOOKUP(Tabla15[[#This Row],[CEDULA]],'OCTUBRE 2025'!$C$8:$J$57,7,0) -> 30 | I16: =+VLOOKUP(Tabla15[[#This Row],[CEDULA]],'OCTUBRE 2025'!$C$8:$J$57,8,0) -> 473.88 | J16: =100 -> 100
B17: 10 | C17: 925830689 | D17: =+VLOOKUP(Tabla15[[#This Row],[CEDULA]],'OCTUBRE 2025'!$C$8:$J$57,2,0) -> PERALTA MENDEZ LINA LISSETTE | E17: 01/AGOSTO/2019 | F17: JEFE DE AGENCIA | G17: Matriz | H17: =+VLOOKUP(Tabla15[[#This Row],[CEDULA]],'OCTUBRE 2025'!$C$8:$J$57,7,0) -> 30 | I17: =+VLOOKUP(Tabla15[[#This Row],[CEDULA]],'OCTUBRE 2025'!$C$8:$J$57,8,0) -> 1022.2 | J17: 0
B18: 12 | C18: 951340702 | D18: =+VLOOKUP(Tabla15[[#This Row],[CEDULA]],'OCTUBRE 2025'!$C$8:$J$57,2,0) -> QUITO CALDERON JONATHAN ENRIQUE | E18: 18/ENERO/2022 | F18: JEFE DE CAPTACIONES | G18: Matriz | H18: =+VLOOKUP(Tabla15[[#This Row],[CEDULA]],'OCTUBRE 2025'!$C$8:$J$57,7,0) -> 30 | I18: =+VLOOKUP(Tabla15[[#This Row],[CEDULA]],'OCTUBRE 2025'!$C$8:$J$57,8,0) -> 817.76 | J18: 0
B19: 13 | C19: 927257576 | D19: =+VLOOKUP(Tabla15[[#This Row],[CEDULA]],'OCTUBRE 2025'!$C$8:$J$57,2,0) -> SANISACA MITE ISRAEL BENJAMIN | E19: 04/NOVIEMBRE/2020 | F19: JEFE DE AGENCIA | G19: Norte | H19: =+VLOOKUP(Tabla15[[#This Row],[CEDULA]],'OCTUBRE 2025'!$C$8:$J$57,7,0) -> 30 | I19: =+VLOOKUP(Tabla15[[#This Row],[CEDULA]],'OCTUBRE 2025'!$C$8:$J$57,8,0) -> 1022.2 | J19: =200-200 -> 0
B20: 14 | C20: 928901800 | D20: =+VLOOKUP(Tabla15[[#This Row],[CEDULA]],'OCTUBRE 2025'!$C$8:$J$57,2,0) -> TADAY GUAMAN NÉSTOR ALONSO | E20: 01/MAYO/2017 | F20: JEFE DE BOVEDA | G20: Matriz | H20: =+VLOOKUP(Tabla15[[#This Row],[CEDULA]],'OCTUBRE 2025'!$C$8:$J$57,7,0) -> 30 | I20: =+VLOOKUP(Tabla15[[#This Row],[CEDULA]],'OCTUBRE 2025'!$C$8:$J$57,8,0) -> 511.1 | J20: =300-100-100 -> 100
B21: 15 | C21: 954184321 | D21: =+VLOOKUP(Tabla15[[#This Row],[CEDULA]],'OCTUBRE 2025'!$C$8:$J$57,2,0) -> URQUIZO GUARANGA ALEX EFRAIN | E21: 01/JULIO/2021 | F21: EJECUTIVO DE RECAUDACION | G21: Matriz | H21: =+VLOOKUP(Tabla15[[#This Row],[CEDULA]],'OCTUBRE 2025'!$C$8:$J$57,7,0) -> 30 | I21: =+VLOOKUP(Tabla15[[#This Row],[CEDULA]],'OCTUBRE 2025'!$C$8:$J$57,8,0) -> 511.1 | J21: =100 -> 100
B22: 16 | C22: 941508905 | D22: =+VLOOKUP(Tabla15[[#This Row],[CEDULA]],'OCTUBRE 2025'!$C$8:$J$57,2,0) -> YUQUILEMA CACUANGO ANGEL JOSE | E22: 12/ABRIL/2019 | F22: EJECUTIVO DE RECAUDACION | G22: Matriz | H22: =+VLOOKUP(Tabla15[[#This Row],[CEDULA]],'OCTUBRE 2025'!$C$8:$J$57,7,0) -> 30 | I22: =+VLOOKUP(Tabla15[[#This Row],[CEDULA]],'OCTUBRE 2025'!$C$8:$J$57,8,0) -> 511.1 | J22: =(100/30)*Tabla15[[#This Row],[DIAS TRABAJADOS]] -> 100
B23: 18 | C23: 604154575 | D23: =+VLOOKUP(Tabla15[[#This Row],[CEDULA]],'OCTUBRE 2025'!$C$8:$J$57,2,0) -> YUQUILEMA DELGADO PEDRO ANTONIO | E23: 06/OCTUBRE/2018 | F23: JEFE DE AGENCIA | G23: Durán | H23: =+VLOOKUP(Tabla15[[#This Row],[CEDULA]],'OCTUBRE 2025'!$C$8:$J$57,7,0) -> 30 | I23: =+VLOOKUP(Tabla15[[#This Row],[CEDULA]],'OCTUBRE 2025'!$C$8:$J$57,8,0) -> 1022.2 | J23: =200-200 -> 0
D25: TOTALES | J25: =SUM(Tabla15[BONO VEHICULAR]) -> 1070
B44: 4

Sheet COMISIONES
B2: CALCULO DE APERTURA CUENTA- COLOCACIONES - PLAZO FIJO
B3: NOMINA AGOSTO 2023
B4: DEL CORTE DEL 01 DE AGOSTO AL 31 DE AGOSTO DEL 2023
B6: No. | C6: CEDULA | D6: NOMBRE | E6: BONO POR CUMPLIMIENTO | F6: COMISIÓN META | G6: COMISION POR PLAZOS FIJOS | H6: COM. SOCIOS NUEVOS Y COLOCACION | I6: ANTICIPO A SUELDO
B8: 1 | C8: =+'OCTUBRE 2025'!C8 -> 925813685 | D8: =+VLOOKUP(C8,'OCTUBRE 2025'!$C$8:$F$57,2,0) -> ASITIMBAY CRIOLLO JOHN ANDERSON
B9: 2 | C9: =+'OCTUBRE 2025'!C9 -> 944405737 | D9: =+VLOOKUP(C9,'OCTUBRE 2025'!$C$8:$F$57,2,0) -> BARAHONA ZAMBRANO DAYANA NICOLE
B10: 3 | C10: =+'OCTUBRE 2025'!C10 -> 604394502 | D10: =+VLOOKUP(C10,'OCTUBRE 2025'!$C$8:$F$57,2,0) -> BETUN CHAFLA JULIO CESAR
B11: 4 | C11: =+'OCTUBRE 2025'!#REF! -> #REF! | D11: =+VLOOKUP(C11,'OCTUBRE 2025'!$C$8:$F$57,2,0) -> #REF! | E11: 100 | F11: 236.65 | H11: 30
B12: 5 | C12: =+'OCTUBRE 2025'!C11 -> 955741970 | D12: =+VLOOKUP(C12,'OCTUBRE 2025'!$C$8:$F$57,2,0) -> CHACAGUASAY CHACAGUASAY ROBERTH CRISTHIAN | E12: 100 | F12: 99.5
B13: 6 | C13: =+'OCTUBRE 2025'!C15 -> 914163654 | D13: =+VLOOKUP(C13,'OCTUBRE 2025'!$C$8:$F$57,2,0) -> COCA BENITEZ JORGE MANUEL
B14: 7 | C14: =+'OCTUBRE 2025'!C19 -> 1105483422 | D14: =+VLOOKUP(C14,'OCTUBRE 2025'!$C$8:$F$57,2,0) -> FLORES HERRERA WENDY DEL CISNE
B15: 8 | C15: =+'OCTUBRE 2025'!C20 -> 942614645 | D15: =+VLOOKUP(C15,'OCTUBRE 2025'!$C$8:$F$57,2,0) -> FUELA TOABANDA JOSUE CHRISTIAN
B16: 9 | C16: =+'OCTUBRE 2025'!C21 -> 951200062 | D16: =+VLOOKUP(C16,'OCTUBRE 2025'!$C$8:$F$57,2,0) -> GALAN LEMACHE INGRID GISELA
B17: 10 | C17: =+'OCTUBRE 2025'!C22 -> 950929232 | D17: =+VLOOKUP(C17,'OCTUBRE 2025'!$C$8:$F$57,2,0) -> GARCIA VERA HENRY LUIS
B18: 11 | C18: =+'OCTUBRE 2025'!C23 -> 953819646 | D18: =+VLOOKUP(C18,'OCTUBRE 2025'!$C$8:$F$57,2,0) -> GUALACEO ÑAMO JONATHAN IVÁN
B19: 12 | C19: =+'OCTUBRE 2025'!#REF! -> #REF! | D19: =+VLOOKUP(C19,'OCTUBRE 2025'!$C$8:$F$57,2,0) -> #REF!
B20: 13 | C20: =+'OCTUBRE 2025'!C24 -> 956953392 | D20: =+VLOOKUP(C20,'OCTUBRE 2025'!$C$8:$F$57,2,0) -> GUAPI YUMAGLLA OSCAR EDUARDO
B21: 14 | C21: =+'OCTUBRE 2025'!#REF! -> #REF! | D21: =+VLOOKUP(C21,'OCTUBRE 2025'!$C$8:$F$57,2,0) -> #REF!
B22: 15 | C22: =+'OCTUBRE 2025'!C25 -> 956796767 | D22: =+VLOOKUP(C22,'OCTUBRE 2025'!$C$8:$F$57,2,0) -> GUAYANLEMA RUIZ EDINSON DAVID | F22: 7.31
B23: 16 | C23: =+'OCTUBRE 2025'!C27 -> 1724102940 | D23: =+VLOOKUP(C23,'OCTUBRE 2025'!$C$8:$F$57,2,0) -> HIDALGO CHERRES NESTOR VLADIMIR
B24: 17 | C24: =+'OCTUBRE 2025'!C28 -> 943322974 | D24: =+VLOOKUP(C24,'OCTUBRE 2025'!$C$8:$F$57,2,0) -> JANETA RUIZ ALEXANDRA DEL ROCIO | F24: 10.84
B25: 18 | C25: =+'OCTUBRE 2025'!C29 -> 941096851 | D25: =+VLOOKUP(C25,'OCTUBRE 2025'!$C$8:$F$57,2,0) -> LEMA CHIRAU RAMONA MARIA
B26: 19 | C26: =+'OCTUBRE 2025'!#REF! -> #REF! | D26: =+VLOOKUP(C26,'OCTUBRE 2025'!$C$8:$F$57,2,0) -> #REF!
B27: 20 | C27: =+'OCTUBRE 2025'!C32 -> 603838657 | D27: =+VLOOKUP(C27,'OCTUBRE 2025'!$C$8:$F$57,2,0) -> MALAN DELGADO JOSE ALBERTO
B28: 21 | C28: =+'OCTUBRE 2025'!C33 -> 925240525 | D28: =+VLOOKUP(C28,'OCTUBRE 2025'!$C$8:$F$57,2,0) -> MALAN YUQUILEMA RAUL ALBERTO
B29: 22 | C29: =+'OCTUBRE 2025'!C34 -> 954520599 | D29: =+VLOOKUP(C29,'OCTUBRE 2025'!$C$8:$F$57,2,0) -> MARSHALL VEGA YULIANA LISSETT
B30: 23 | C30: =+'OCTUBRE 2025'!#REF! -> #REF! | D30: =+VLOOKUP(C30,'OCTUBRE 2025'!$C$8:$F$57,2,0) -> #REF! | E30: 100 | F30: 518.5
B31: 24 | C31: =+'OCTUBRE 2025'!C35 -> 0943906032 | D31: =+VLOOKUP(C31,'OCTUBRE 2025'!$C$8:$F$57,2,0) -> MEZA RODRIGUEZ MICHAEL FERNANDO
B32: 25 | C32: =+'OCTUBRE 2025'!C36 -> 0919306050 | D32: =+VLOOKUP(C32,'OCTUBRE 2025'!$C$8:$F$57,2,0) -> MORAN GARCIA DANNY FAVIAN
B33: 26 | C33: =+'OCTUBRE 2025'!C37 -> 0941235376 | D33: =+VLOOKUP(C33,'OCTUBRE 2025'!$C$8:$F$57,2,0) -> MOREIRA ESPINOZA LINDA ELIZABETH
B34: 27 | C34: =+'OCTUBRE 2025'!C38 -> 955395686 | D34: =+VLOOKUP(C34,'OCTUBRE 2025'!$C$8:$F$57,2,0) -> MOROCHO DUCHI SANDRA STEPHANIE
B35: 28 | C35: =+'OCTUBRE 2025'!C39 -> 940991987 | D35: =+VLOOKUP(C35,'OCTUBRE 2025'!$C$8:$F$57,2,0) -> MOROCHO YANTALEMA DINA MAGALY
B36: 29 | C36: =+'OCTUBRE 2025'!#REF! -> #REF! | D36: =+VLOOKUP(C36,'OCTUBRE 2025'!$C$8:$F$57,2,0) -> #REF!
B37: 30 | C37: =+'OCTUBRE 2025'!C41 -> 951763994 | D37: =+VLOOKUP(C37,'OCTUBRE 2025'!$C$8:$F$57,2,0) -> NEVAREZ PEÑAFIEL EVELYN JULEXY
B38: 31 | C38: =+'OCTUBRE 2025'!C42 -> 950703199 | D38: =+VLOOKUP(C38,'OCTUBRE 2025'!$C$8:$F$57,2,0) -> ÑAMO GUALACEO BRYAN JAVIER | F38: 60.37
B39: 32 | C39: =+'OCTUBRE 2025'!C44 -> 925830689 | D39: =+VLOOKUP(C39,'OCTUBRE 2025'!$C$8:$F$57,2,0) -> PERALTA MENDEZ LINA LISSETTE
B40: 33 | C40: =+'OCTUBRE 2025'!C46 -> 951340702 | D40: =+VLOOKUP(C40,'OCTUBRE 2025'!$C$8:$F$57,2,0) -> QUITO CALDERON JONATHAN ENRIQUE | E40: 100 | F40: 75
B41: 34 | C41: =+'OCTUBRE 2025'!C47 -> 650112949 | D41: =+VLOOKUP(C41,'OCTUBRE 2025'!$C$8:$F$57,2,0) -> QUITO UCHUBANDA JANETH ALEXANDRA
B42: 35 | C42: =+'OCTUBRE 2025'!C48 -> 924232804 | D42: =+VLOOKUP(C42,'OCTUBRE 2025'!$C$8:$F$57,2,0) -> RECALDE NARANJO ANGEL ALEXIS
B43: 36 | C43: =+'OCTUBRE 2025'!C49 -> 605031145 | D43: =+VLOOKUP(C43,'OCTUBRE 2025'!$C$8:$F$57,2,0) -> SALAO PEREZ GERMAN FABRICIO
...

Sheet ROL INDIVIDUAL
F5: ROL INDIVIDUAL | H5: 45931
C7: Identificación: | D7: 955325238 | F7: Oficina: | G7: =VLOOKUP($D$7,'OCTUBRE 2025'!$C$8:$AJ$57,6,0) -> Matriz
C8: Nombres: | D8: ='OCTUBRE 2025'!F12 -> ASESOR DE NEGOCIOS | F8: No. días: | G8: =VLOOKUP($D$7,'OCTUBRE 2025'!$C$8:$AJ$57,7,0) -> 16
C9: Cargo: | D9: =VLOOKUP($D$7,'OCTUBRE 2025'!$C$8:$AJ$57,4,0) -> CAJERA FINANCIERA
C11: INGRESOS | E11: VALOR | F11: EGRESOS | H11: VALOR
C12: Sueldo básico cooperativa | E12: =VLOOKUP($D$7,'OCTUBRE 2025'!$C$8:$AJ$57,8,0) -> 256.53 | F12: Aporte Individual IESS 9.45% | H12: =VLOOKUP($D$7,'OCTUBRE 2025'!$C$8:$AJ$57,24,0) -> 24.242085
C13: Bono Movilización | E13: =VLOOKUP($D$7,'OCTUBRE 2025'!$C$8:$AJ$57,9,0) -> 0 | F13: Préstamos Quirografarios o Hipotecarios | H13: =VLOOKUP($D$7,'OCTUBRE 2025'!$C$8:$AJ$57,27,0) -> 0
C14: Bono mensual (2.174%) | E14: =VLOOKUP($D$7,'OCTUBRE 2025'!$C$8:$AJ$57,10,0) -> 0 | F14: Subsidio Monetario | H14: =VLOOKUP($D$7,'OCTUBRE 2025'!$C$8:$AJ$57,28,0) -> 0
C15: Bono cumplimiento | E15: =VLOOKUP($D$7,'OCTUBRE 2025'!$C$8:$AJ$57,11,0) -> 0 | F15: Extensión de Salud | H15: =VLOOKUP($D$7,'OCTUBRE 2025'!$C$8:$AJ$57,29,0) -> 0
C16: Comisión por superación de meta | E16: =VLOOKUP($D$7,'OCTUBRE 2025'!$C$8:$AJ$57,12,0) -> 0 | F16: Pensión alimenticia | H16: =VLOOKUP($D$7,'OCTUBRE 2025'!$C$8:$AJ$57,30,0) -> 0
C17: Comisión por Depósito a Plazo Fijo | E17: =VLOOKUP($D$7,'OCTUBRE 2025'!$C$8:$AJ$57,13,0) -> 0 | F17: Cuentas por cobrar | H17: =VLOOKUP($D$7,'OCTUBRE 2025'!$C$8:$AJ$57,31,0) -> 0
C18: Comisión socios nuevos | E18: =VLOOKUP($D$7,'OCTUBRE 2025'!$C$8:$AJ$57,14,0) -> 0 | F18: Anticipo de Sueldo | H18: =VLOOKUP($D$7,'OCTUBRE 2025'!$C$8:$AJ$57,32,0) -> 0
C19: Horas Extras 50% | E19: =VLOOKUP($D$7,'OCTUBRE 2025'!$C$8:$AJ$57,15,0) -> 0 | F19: Ret Imp. A la Renta | H19: =VLOOKUP($D$7,'OCTUBRE 2025'!$C$8:$AJ$57,25,0) -> 0
C20: Horas Extras 100% | E20: =VLOOKUP($D$7,'OCTUBRE 2025'!$C$8:$AJ$57,16,0) -> 0 | F20: Descuentos | H20: =VLOOKUP($D$7,'OCTUBRE 2025'!$C$8:$AJ$57,26,0) -> 0
C21: Fondo de Reserva | E21: =VLOOKUP($D$7,'OCTUBRE 2025'!$C$8:$AJ$57,19,0) -> 0
C22: Fondo de Reserva (ajustes) | E22: =VLOOKUP($D$7,'OCTUBRE 2025'!$C$8:$AJ$57,20,0) -> 0
C23: Décimo Tercero | E23: =VLOOKUP($D$7,'OCTUBRE 2025'!$C$8:$AJ$57,21,0) -> 0
C24: Décimo Cuarto | E24: =VLOOKUP($D$7,'OCTUBRE 2025'!$C$8:$AJ$57,22,0) -> 0
C25: TOTAL DE INGRESOS | E25: =SUM(E12:E24) -> 256.53 | F25: TOTAL EGRESOS | H25: =SUM(H12:H23) -> 24.242085
F26: VALOR NETO A RECIBIR | H26: =+E25-H25 -> 232.28791
C28: Elaborado por: | G28: Recibí Conforme:
C31: Ing. Magaly Morocho | G31: =+$D$8 -> ASESOR DE NEGOCIOS
C32: Talento Humano | G32: Funcionario

Sheet ROL INDIVIDUAL (2)
F5: ROL INDIVIDUAL | H5: 45839
C7: Identificación: | D7: 0943906032 | F7: Oficina: | G7: =VLOOKUP($D$7,'OCTUBRE 2025'!$C$8:$AJ$57,6,0) -> Norte
C8: Nombres: | D8: =VLOOKUP($D$7,'OCTUBRE 2025'!$C$8:$AJ$57,2,0) -> MEZA RODRIGUEZ MICHAEL FERNANDO | F8: No. días: | G8: =VLOOKUP($D$7,'OCTUBRE 2025'!$C$8:$AJ$57,7,0) -> 30
C9: Cargo: | D9: =VLOOKUP($D$7,'OCTUBRE 2025'!$C$8:$AJ$57,4,0) -> OFICIAL DE RECAUDACIONES
C11: INGRESOS | E11: VALOR | F11: EGRESOS | H11: VALOR
C12: Sueldo básico cooperativa | E12: =VLOOKUP($D$7,'OCTUBRE 2025'!$C$8:$AJ$57,8,0) -> 473.88 | F12: Aporte Individual IESS 9.45% | H12: =VLOOKUP($D$7,'OCTUBRE 2025'!$C$8:$AJ$57,24,0) -> 55.20501
C13: Bono Movilización | E13: =VLOOKUP($D$7,'OCTUBRE 2025'!$C$8:$AJ$57,9,0) -> 100 | F13: Préstamos Quirografarios o Hipotecarios | H13: =VLOOKUP($D$7,'OCTUBRE 2025'!$C$8:$AJ$57,27,0) -> 0
C14: Bono mensual (2.174%) | E14: =VLOOKUP($D$7,'OCTUBRE 2025'!$C$8:$AJ$57,10,0) -> 10.3 | F14: Subsidio Monetario | H14: =VLOOKUP($D$7,'OCTUBRE 2025'!$C$8:$AJ$57,28,0) -> 0
C15: Bono cumplimiento | E15: =VLOOKUP($D$7,'OCTUBRE 2025'!$C$8:$AJ$57,11,0) -> 0 | F15: Extensión de Salud | H15: =VLOOKUP($D$7,'OCTUBRE 2025'!$C$8:$AJ$57,29,0) -> 0
C16: Comisión por cumplimiento de meta | E16: =VLOOKUP($D$7,'OCTUBRE 2025'!$C$8:$AJ$57,12,0) -> 0 | F16: Pensión alimenticia | H16: =VLOOKUP($D$7,'OCTUBRE 2025'!$C$8:$AJ$57,30,0) -> 0
C17: Comisión por Depósito a Plazo Fijo | E17: =VLOOKUP($D$7,'OCTUBRE 2025'!$C$8:$AJ$57,13,0) -> 0 | F17: Cuentas por cobrar | H17: =VLOOKUP($D$7,'OCTUBRE 2025'!$C$8:$AJ$57,31,0) -> 0
C18: Comisión socios nuevos | E18: =VLOOKUP($D$7,'OCTUBRE 2025'!$C$8:$AJ$57,14,0) -> 0 | F18: Anticipo de Sueldo | H18: 0
C19: Horas Extras 50% | E19: =VLOOKUP($D$7,'OCTUBRE 2025'!$C$8:$AJ$57,15,0) -> 0 | F19: Ret Imp. A la Renta | H19: =VLOOKUP($D$7,'OCTUBRE 2025'!$C$8:$AJ$57,25,0) -> 0
C20: Horas Extras 100% | E20: =VLOOKUP($D$7,'OCTUBRE 2025'!$C$8:$AJ$57,16,0) -> 0 | F20: Descuentos | H20: =VLOOKUP($D$7,'OCTUBRE 2025'!$C$8:$AJ$57,26,0) -> 0
C21: Fondo de Reserva | E21: =VLOOKUP($D$7,'OCTUBRE 2025'!$C$8:$AJ$57,19,0) -> 48.662194
C22: Fondo de Reserva (ajustes) | E22: =VLOOKUP($D$7,'OCTUBRE 2025'!$C$8:$AJ$57,20,0) -> 0
C23: Décimo Tercero | E23: =VLOOKUP($D$7,'OCTUBRE 2025'!$C$8:$AJ$57,21,0) -> 0
C24: Décimo Cuarto | E24: =VLOOKUP($D$7,'OCTUBRE 2025'!$C$8:$AJ$57,22,0) -> 0
C25: TOTAL DE INGRESOS | E25: =SUM(E12:E24) -> 632.84219 | F25: TOTAL EGRESOS | H25: =SUM(H12:H23) -> 55.20501
F26: VALOR NETO A RECIBIR | H26: =+E25-H25 -> 577.63718
C28: Elaborado por: | G28: Recibí Conforme:
C31: Ing. Magaly Morocho | G31: =+$D$8 -> MEZA RODRIGUEZ MICHAEL FERNANDO
C32: Talento Humano | G32: Funcionario

Sheet ROL INDIVIDUAL Prueba
F5: ROL INDIVIDUAL
C7: Identificación: | F7: Oficina:
C8: Nombres: | F8: No. días:
C9: Cargo:
C11: INGRESOS | E11: VALOR | F11: EGRESOS | H11: VALOR
C12: Sueldo básico cooperativa | E12: $ | F12: Aporte Individual IESS 9.45% | H12: $
C13: Bono Movilización | E13: $ | F13: Préstamos Quirografarios o Hipotecarios | H13: $
C14: Bono mensual (2.174%) | E14: $ | F14: Subsidio Monetario | H14: $
C15: Bono cumplimiento | E15: $ | F15: Extensión de Salud | H15: $
C16: Comisión por superación de meta | E16: $ | F16: Pensión alimenticia | H16: $
C17: Comisión por Depósito a Plazo Fijo | E17: $ | F17: Cuentas por cobrar | H17: $
C18: Comisión socios nuevos | E18: $ | F18: Anticipo de Sueldo | H18: $
C19: Horas Extras 50% | E19: $ | F19: Ret Imp. A la Renta | H19: $
C20: Horas Extras 100% | E20: $ | F20: Descuentos | H20: $
C21: Fondo de Reserva | E21: $
C22: Fondo de Reserva (ajustes) | E22: $
C23: Décimo Tercero | E23: $
C24: Décimo Cuarto | E24: $
C25: TOTAL DE INGRESOS | E25: $ | F25: TOTAL EGRESOS | H25: $
F26: VALOR NETO A RECIBIR | H26: $
C28: Elaborado por: | G28: Recibí Conforme:
C31: Ing. Magaly Morocho | G31: =+$D$8 -> 0
C32: Talento Humano | G32: Funcionario

Sheet CHIMBOLEMA
B8: Trabajador(a): | C8: CHIMBOLEMA YUNGAN MARIO EFRAIN | F8: Inicio: | G8: 45884
B9: Fecha de ingreso: | C9: 45884 | F9: Fin: | G9: 45681
B10: Sueldo: | C10: 473.88 | F10: Total de dias | G10: =+_xlfn.DAYS(G9,G8) -> -203
