Workbook
Name CANTIDAD_POR_DEPARTAMENTO: #REF!
Name SUELDOS_POR_DEPARTAMENTO: #REF!

Sheet OCTUBRE 2025
B2: COOPERATIVA DE AHORRO Y CRÉDITO "LOS ANDES LATINOS" LTDA. | AN2: COOPERATIVA DE AHORRO Y CRÉDITO "LOS ANDES LATINOS" LTDA.
B3: ROL DE PAGOS | R3: MES DE OCTUBRE 2025 | AN3: BENEFICIOS SOCIALES | AU3: =+R3 -> MES DE OCTUBRE 2025
C4: 1 | D4: 2 | E4: 3 | F4: 4 | G4: 5 | H4: 6 | I4: 7 | J4: 8 | K4: 9 | L4: 10 | M4: 11 | N4: 12 | O4: 13 | P4: 14 | Q4: 15 | R4: 16 | S4: 17 | T4: 18 | U4: 19 | V4: 20 | W4: 21 | X4: 22 | Y4: 23 | Z4: 24 | AA4: 25 | AB4: 26 | AC4: 27 | AD4: 28 | AE4: 29 | AF4: 30 | AG4: 31 | AH4: 32 | AI4: 33
J5: INGRESOS | Z5: EGRESOS
B6: No. | C6: CEDULA | D6: NOMBRE | E6: FECHA DE INGRESO | F6: CARGO | G6: GÉNERO | H6: AGENCIA | I6: DIAS TRABAJADOS | J6: SUELDO BRUTO | K6: BONO VEHICULAR | L6: Bono General Mensual | M6: BONO CUMPLIMIENTO | N6: COMISIÓN SUP. META | O6: COMISION POR PLAZOS FIJOS | P6: COM. SOCIOS NUEVOS Y COLOCACION | Q6: VALOR EN HORAS EXTRAS | S6: TOTAL POR VARIACION | T6: INGRESOS APORTE AL IESS | U6: FONDO RESERVAS | V6: FONDO DE RESERVA (BONO NAVIDEÑO) | W6: DECIMO TERCERO | X6: DECIMO CUARTO | Y6: TOTAL DE Ingresos | Z6: IESS | AA6: RET IMP A LA RENTA | AB6: DSCTOS | AC6: PRESTAMO PQ- HIP | AD6: SUBSIDIOS MONETARIO | AE6: EXT. SALUD | AF6: PENSION ALIMENTICIA | AG6: C*C | AH6: ANTICP. SUELD. | AI6: TOTAL DESCTS. | AJ6: NETO | AK6: RECIBI CONFORME | AN6: No. | AO6: NOMBRE | AP6: FECHA DE INGRESO. | AQ6: DIAS TRABAJADOS | AR6: AGENCIA | AS6: TOTAL GANADO EN EL MES GRAVABLE | AT6: 13ER. SUELDO | AU6: FONDO DE RESERVA | AV6: 14TO. SUELDO | AW6: 14TO. SUELDO | AX6: VACACIONES | AY6: TOTAL SUELDO + B.SOCIAL | AZ6: APORTE AL IESS
Q7: 0.5 | R7: 1 | Z7: 0.0945 | AT7: 12 | AU7: 0.0833 | AV7: AJUSTE | AW7: 470 | AX7: 24 | AZ7: Patronal 11,15% | BA7: CCC 1% | BB7: TOTAL
B8: =+#REF!+1 -> #REF! | C8: 923837991 | D8: YUNDA CUJILEMA MARIA TERESA | E8: 41426 | F8: CONTADOR GENERAL | G8: F | H8: Matriz | I8: 30 | J8: 1022.2 | K8: =IFERROR(VLOOKUP(C8,Tabla15[[CEDULA]:[BONO VEHICULAR]],8,0),0) -> 0 | L8: 100 | M8: =+VLOOKUP(C8,Tabla335[[CEDULA ]:[US$,,]],9,0) -> 0 | P8: =+VLOOKUP(C8,'COMISIONES-SOCIOS'!$C$8:$L$57,10,0) -> 0 | Q8: =+VLOOKUP(C8,Tabla3[[CEDULA ]:[US$,]],8,0) -> 0 | R8: =+VLOOKUP($C8,Tabla3[[CEDULA ]:[US$,]],9,0) -> 0 | S8: =SUM(K8:R8) -> 100 | T8: =+J8+S8 -> 1122.2 | U8: =VLOOKUP(C8,FR!$C$6:$M$55,11,0) -> 93.47926 | Y8: =SUM(T8:X8) -> 1215.6793 | Z8: =T8*9.45% -> 106.0479 | AC8: =IFERROR(+VLOOKUP(D8,PQ!$D$35:$E$45,2,0),0) -> 0 | AD8: 0 | AH8: 850 | AI8: =SUM(Z8:AH8) -> 956.0479 | AJ8: =+Y8-AI8 -> 259.63136 | AK8: 600101004961 | AN8: =+#REF!+1 -> #REF! | AO8: =+D8 -> YUNDA CUJILEMA MARIA TERESA | AP8: =+E8 -> 41426 | AQ8: =+I8 -> 30 | AR8: =+H8 -> Matriz | AS8: =T8 -> 1122.2 | AT8: =+AS8/12 -> 93.516667 | AU8: 0 | AW8: =($AW$7/360)*AQ8 -> 39.166667 | AX8: =+AS8/24 -> 46.758333 | AY8: =SUM(AS8:AX8) -> 1301.6417 | AZ8: =+AS8*11.15% -> 125.1253 | BA8: =+AS8*1% -> 11.222 | BB8: =SUM(AZ8:BA8) -> 136.3473
B9: =+B8+1 -> #REF! | C9: 941508905 | D9: YUQUILEMA CACUANGO ANGEL JOSE | E9: 43567 | F9: OFICIAL DE RECAUDACIONES | G9: M | H9: Matriz | I9: 30 | J9: 511.1 | K9: =IFERROR(VLOOKUP(C9,Tabla15[[CEDULA]:[BONO VEHICULAR]],8,0),0) -> 100 | L9: 11.11 | M9: =+VLOOKUP(C9,Tabla335[[CEDULA ]:[US$,,]],9,0) -> 0 | P9: =+VLOOKUP(C9,'COMISIONES-SOCIOS'!$C$8:$L$57,10,0) -> 0 | Q9: =+VLOOKUP(C9,Tabla3[[CEDULA ]:[US$,]],8,0) -> 0 | R9: =+VLOOKUP($C9,Tabla3[[CEDULA ]:[US$,]],9,0) -> 0 | S9: =SUM(K9:R9) -> 111.11 | T9: =+J9+S9 -> 622.21 | U9: =VLOOKUP(C9,FR!$C$6:$M$55,11,0) -> 51.830093 | Y9: =SUM(T9:X9) -> 674.04009 | Z9: =T9*9.45% -> 58.798845 | AC9: =IFERROR(+VLOOKUP(D9,PQ!$D$35:$E$45,2,0),0) -> 0 | AH9: 500 | AI9: =SUM(Z9:AH9) -> 558.79885 | AJ9: =+Y9-AI9 -> 115.24125 | AK9: 600101008981 | AN9: =+AN8+1 -> #REF! | AO9: =+D9 -> YUQUILEMA CACUANGO ANGEL JOSE | AP9: =+E9 -> 43567 | AQ9: =+I9 -> 30 | AR9: =+H9 -> Matriz | AS9: =T9 -> 622.21 | AT9: =+AS9/12 -> 51.850833 | AU9: 0 | AW9: =($AW$7/360)*AQ9 -> 39.166667 | AX9: =+AS9/24 -> 25.925417 | AY9: =SUM(AS9:AX9) -> 739.15292 | AZ9: =+AS9*11.15% -> 69.376415 | BA9: =+AS9*1% -> 6.2221 | BB9: =SUM(AZ9:BA9) -> 75.598515
B10: =+B9+1 -> #REF! | C10: 604154575 | D10: YUQUILEMA DELGADO PEDRO ANTONIO | E10: 43379 | F10: JEFE DE CRÉDITO | G10: M | H10: Durán | I10: 30 | J10: 1022.2 | K10: =IFERROR(VLOOKUP(C10,Tabla15[[CEDULA]:[BONO VEHICULAR]],8,0),0) -> 0 | L10: 0 | M10: =+VLOOKUP(C10,Tabla335[[CEDULA ]:[US$,,]],9,0) -> 0 | P10: =+VLOOKUP(C10,'COMISIONES-SOCIOS'!$C$8:$L$57,10,0) -> 0 | Q10: =+VLOOKUP(C10,Tabla3[[CEDULA ]:[US$,]],8,0) -> 0 | R10: =+VLOOKUP($C10,Tabla3[[CEDULA ]:[US$,]],9,0) -> 0 | S10: =SUM(K10:R10) -> 0 | T10: =+J10+S10 -> 1022.2 | U10: =VLOOKUP(C10,FR!$C$6:$M$55,11,0) -> 85.14926 | Y10: =SUM(T10:X10) -> 1107.3493 | Z10: =T10*9.45% -> 96.5979 | AB10: 0 | AC10: =IFERROR(+VLOOKUP(D10,PQ!$D$35:$E$45,2,0),0) -> 0 | AG10: 0 | AH10: 800 | AI10: =SUM(Z10:AH10) -> 896.5979 | AJ10: =+Y10-AI10 -> 210.75136 | AK10: 600101003932 | AN10: =+AN9+1 -> #REF! | AO10: =+D10 -> YUQUILEMA DELGADO PEDRO ANTONIO | AP10: =+E10 -> 43379 | AQ10: =+I10 -> 30 | AR10: =+H10 -> Durán | AS10: =T10 -> 1022.2 | AT10: =+AS10/12 -> 85.183333 | AU10: 0 | AW10: =($AW$7/360)*AQ10 -> 39.166667 | AX10: =+AS10/24 -> 42.591667 | AY10: =SUM(AS10:AX10) -> 1189.1417 | AZ10: =+AS10*11.15% -> 113.9753 | BA10: =+AS10*1% -> 10.222 | BB10: =SUM(AZ10:BA10) -> 124.1973
D11: TOTALES | J11: =SUBTOTAL(9,J8:J10) -> 2555.5 | K11: =SUBTOTAL(9,K8:K10) -> 100 | L11: =SUBTOTAL(9,L8:L10) -> 111.11 | M11: =SUBTOTAL(9,M8:M10) -> 0 | N11: =SUBTOTAL(9,N8:N10) -> 0 | O11: =SUBTOTAL(9,O8:O10) -> 0 | P11: =SUBTOTAL(9,P8:P10) -> 0 | Q11: =SUBTOTAL(9,Q8:Q10) -> 0 | ... Y11: =SUBTOTAL(9,Y8:Y10) -> 2997.0686 | Z11: =T11*9.45% -> 261.44464 | AA11: =+SUBTOTAL(9,AA8:AA10) -> 0 | AB11: =SUBTOTAL(9,AB8:AB10) -> 0 | AC11: =SUBTOTAL(9,AC8:AC10) -> 0 | AD11: =SUBTOTAL(9,AD8:AD10) -> 0 | AE11: =SUBTOTAL(9,AE8:AE10) -> 0 | AF11: =SUBTOTAL(9,AF8:AF10) -> 0 | AG11: =SUBTOTAL(9,AG8:AG10) -> 0 | AH11: =SUBTOTAL(9,AH8:AH10) -> 2150 | AI11: =SUBTOTAL(9,AI8:AI10) -> 2411.4446 | AJ11: =SUBTOTAL(9,AJ8:AJ10) -> 585.62397 | AO11: =+D11 -> TOTALES | AS11: =SUBTOTAL(9,AS8:AS10) -> 2766.61 | AT11: =SUBTOTAL(9,AT8:AT10) -> 230.55083 | AU11: =SUBTOTAL(9,AU8:AU10) -> 0 | AV11: =SUBTOTAL(9,AV8:AV10) -> 0 | AW11: =SUBTOTAL(9,AW8:AW10) -> 117.5 | AX11: =SUBTOTAL(9,AX8:AX10) -> 115.27542 | AY11: =SUM(AS11:AX11) -> 3229.9363 | AZ11: =+AS11*11.15% -> 308.47701 | BA11: =+AS11*1% -> 27.6661 | BB11: =SUM(AZ11:BA11) -> 336.14311
AT12: 45011005 | AU12: 450135 | AW12: 45011010 | AX12: 45019020 | AZ12: 45012005 | BA12: 45012015
J13: 45010505 | K13: 45019005 | Q13: 45019015 | U13: 450135 | W13: 45011005 | X13: 45011010 | Z13: 25031505 | AA13: 25040505 | AC13: 25039001 | AD13: 45010505 | AE13: 25039002 | AF13: 25039003 | AG13: 16909005 | AH13: 169005 | AJ13: 250305 | AT13: 25031005 | AU13: 250320 | AW13: 25031010 | AX13: 25031025 | AZ13: 25031510 | BA13: 25031510
I27: NORMAL: | J27: =J11 -> 2555.5 | O27: AJUSTE: | P27: =+S11 -> 211.11
I28: 0.0945 | J28: =+J27*I28 -> 241.49475 | O28: 0.0945 | P28: =+P27*O28 -> 19.949895
I29: 0.1215 | J29: =+J27*I29 -> 310.49325 | O29: 0.1215 | P29: =+P27*O29 -> 25.649865 | AT29: 45011005 | AU29: 13° | AV29: =+#REF! -> #REF! | AW29: =+AT11 -> 230.55083
I30: TOTAL | J30: =SUM(J28:J29) -> 551.988 | O30: TOTAL | P30: =SUM(P28:P29) -> 45.59976 | AT30: 450135 | AU30: FR | AW30: =+AU11 -> 0
AT31: 45011010 | AU31: 14° | AV31: =SUM(#REF!) -> #REF! | AW31: =+AW11 -> 117.5
AT32: 45019020 | AU32: Vacaciones | AV32: =SUM(#REF!) -> #REF! | AW32: =+AX11 -> 115.27542
AT33: 45012005 | AU33: Aporte 11.15% | AV33: =+#REF! -> #REF! | AW33: =+AZ11 -> 308.47701
I34: 25031505 | J34: Personal IESS | K34: 2910.88 | O34: 25031505 | P34: Personal IESS | Q34: 657.98 | S34: =+K34+Q34 -> 3568.86 | W34: Cuadre | X34: Personal | Y34: Patronal | Z34: Remuneración | AT34: 45012015 | AU34: Aporte 1% | AV34: =+#REF! -> #REF! | AW34: =+BA11 -> 27.6661
I35: 25031510 | J35: Patronal IESS | K35: 3742.58 | O35: 25031510 | P35: Patronal IESS | Q35: 845.91 | S35: =+K35+Q35 -> 4588.49 | X35: 25031505 | Y35: 25031510 | Z35: 250305 | AT35: 25031005 | AU35: 13° | AX35: =+AT11 -> 230.55083
I36: 45039005 | J36: Gtos Banca | K36: 0 | O36: 45039005 | P36: Gtos Banca | Q36: 0 | W36: Consolidado | X36: =+S34 -> 3568.86 | Y36: =+S35 -> 4588.49 | Z36: 22934.41 | AT36: 250320 | AU36: FR | AX36: =+AU11 -> 0
I37: 25031505 | J37: Personal IESS | M37: 0 | O37: 11031020 | P37: Produbanco | R37: 1503.89 | W37: Matriz | X37: 2129.96 | Y37: 2674.74 | Z37: 13492.95 | AT37: 25031010 | AU37: 14° | AX37: =+AW11 -> 117.5
I38: 25031510 | J38: Patronal IESS | M38: 0 | Q38: =SUM(Q34:Q37) -> 1503.89 | R38: =SUM(R34:R37) -> 1503.89 | W38: Norte | X38: 866.39 | Y38: 1102.87 | Z38: 5495.22 | AT38: 25031025 | AU38: Vacaciones | AX38: =+AX11 -> 115.27542
I39: 11031020 | J39: Produbanco | M39: 6653.46 | R39: =+Q38-R38 -> 0 | W39: Durán | X39: 572.51 | Y39: 783.26 | Z39: 3946.23 | AT39: 25031510 | AU39: Aporte 11.15% | AX39: =+AZ11 -> 308.47701
K40: =SUM(K34:K39) -> 6653.46 | M40: =SUM(M34:M39) -> 6653.46 | W40: Diferencia | X40: =+X36-X37-X38-X39 -> 0 | Y40: =+Y36-Y37-Y38-Y39 -> 27.62 | Z40: =+Z36-Z37-Z38-Z39 -> 0.01 | AT40: 25031510 | AU40: Aporte 1% | AX40: =+BA11 -> 27.6661
M41: =+K40-M40 -> 0 | AW41: =SUM(AW29:AW40) -> 799.46937 | AX41: =SUM(AX29:AX40) -> 799.46937 | AY41: =+AW41-AX41 -> 0
I44: NOTAS DE CRÉDITO IESS
I45: Colaborador | J45: Sueldo | K45: Personal | M45: Patronal
K46: 0.0945 | M46: 0.1115
I47: …... | J47: 0 | K47: =+J47*K46 -> 0 | M47: =+J47*M46 -> 0
I51: 45010505 | J51: Sueldo | K51: =+J11 -> 2555.5
I52: 45019005 | J52: Comisiones | K52: =SUM(K11:P11) -> 211.11
I53: 45019015 | J53: Horas Extras | K53: =SUM(Q11:R11) -> 0
I54: 450135 | J54: FR | K54: =+U11 -> 230.45861
I55: 45011005 | J55: 13° | K55: =+W11 -> 0
I56: 45011010 | J56: 14° | K56: =+X11 -> 0
I57: 25031505 | J57: Apor Personal | M57: =+Z11 -> 261.44464
I58: 25040505 | J58: Retención del Personal | M58: =+AA11 -> 0
I59: 25039001 | J59: Prestamos Q/H | M59: =+AC11 -> 0
...

Sheet BONO vehicular
B2: CALCULO BONO VEHICULAR
B3: NOMINA SEPTIEMBRE 2025
B6: No. | C6: CEDULA | D6: NOMBRE | E6: FECHA DE INGRESO | F6: CARGO | G6: AGENCIA | H6: DIAS TRABAJADOS | I6: SUELDO | J6: BONO VEHICULAR | K6: Columna1 | N6: DEPARTAMENTOS RECIBEN BONO | O6: BONOS
B7: 1 | C7: 955741970 | D7: =+VLOOKUP(Tabla15[[#This Row],[CEDULA]],'OCTUBRE 2025'!$C$8:$J$10,2,0) -> #N/A | E7: 01/MARZO/2023 | F7: =+VLOOKUP(Tabla15[[#This Row],[CEDULA]],'OCTUBRE 2025'!$C$8:$J$10,4,0) -> #N/A | G7: Matriz | H7: =+VLOOKUP(Tabla15[[#This Row],[CEDULA]],'OCTUBRE 2025'!$C$8:$J$10,7,0) -> #N/A | I7: =+VLOOKUP(Tabla15[[#This Row],[CEDULA]],'OCTUBRE 2025'!$C$8:$J$10,8,0) -> #N/A | J7: =100 -> 100 | N7: EJECUTIVO DE CAPTACIONES | O7: 100
B8: 2 | C8: 944143148 | D8: =+VLOOKUP(Tabla15[[#This Row],[CEDULA]],'OCTUBRE 2025'!$C$8:$J$10,2,0) -> #N/A | E8: 27/ABRIL/2023 | F8: EJECUTIVO DE RECAUDACION | G8: Matriz | H8: =+VLOOKUP(Tabla15[[#This Row],[CEDULA]],'OCTUBRE 2025'!$C$8:$J$10,7,0) -> #N/A | I8: =+VLOOKUP(Tabla15[[#This Row],[CEDULA]],'OCTUBRE 2025'!$C$8:$J$10,8,0) -> #N/A | J8: =+(3.33333333333333)*Tabla15[[#This Row],[DIAS TRABAJADOS]] -> #N/A | N8: ASESOR LEGAL | O8: 200
B9: 3 | C9: 950929232 | D9: =+VLOOKUP(Tabla15[[#This Row],[CEDULA]],'OCTUBRE 2025'!$C$8:$J$10,2,0) -> #N/A | E9: 14/JUNIO/2022 | F9: EJECUTIVO DE RECAUDACION | G9: Norte | H9: =+VLOOKUP(Tabla15[[#This Row],[CEDULA]],'OCTUBRE 2025'!$C$8:$J$10,7,0) -> #N/A | I9: =+VLOOKUP(Tabla15[[#This Row],[CEDULA]],'OCTUBRE 2025'!$C$8:$J$10,8,0) -> #N/A | J9: 0 | N9: JEFE DE AGENCIA | O9: 200
B10: 4 | C10: 953819646 | D10: =+VLOOKUP(Tabla15[[#This Row],[CEDULA]],'OCTUBRE 2025'!$C$8:$J$10,2,0) -> #N/A | E10: 17/MARZO/2022 | F10: EJECUTIVO DE RECAUDACION | G10: Matriz | H10: =+VLOOKUP(Tabla15[[#This Row],[CEDULA]],'OCTUBRE 2025'!$C$8:$J$10,7,0) -> #N/A | I10: =+VLOOKUP(Tabla15[[#This Row],[CEDULA]],'OCTUBRE 2025'!$C$8:$J$10,8,0) -> #N/A | J10: =100 -> 100 | N10: JEFE DE BOVEDA | O10: 300
B11: 5 | C11: 956796767 | D11: =+VLOOKUP(Tabla15[[#This Row],[CEDULA]],'OCTUBRE 2025'!$C$8:$J$10,2,0) -> #N/A | E11: 21/JULIO/2022 | F11: EJECUTIVO DE RECAUDACION | G11: Norte | H11: =+VLOOKUP(Tabla15[[#This Row],[CEDULA]],'OCTUBRE 2025'!$C$8:$J$10,7,0) -> #N/A | I11: =+VLOOKUP(Tabla15[[#This Row],[CEDULA]],'OCTUBRE 2025'!$C$8:$J$10,8,0) -> #N/A | J11: =100 -> 100 | N11: JEFE DE RECAUDACIÓN | O11: 200
B12: 6 | C12: 957093800 | D12: =+VLOOKUP(Tabla15[[#This Row],[CEDULA]],'OCTUBRE 2025'!$C$8:$J$10,2,0) -> #N/A | E12: 01/MAYO/2023 | F12: EJECUTIVO DE RECAUDACION | G12: Durán | H12: =+VLOOKUP(Tabla15[[#This Row],[CEDULA]],'OCTUBRE 2025'!$C$8:$J$10,7,0) -> #N/A | I12: =+VLOOKUP(Tabla15[[#This Row],[CEDULA]],'OCTUBRE 2025'!$C$8:$J$10,8,0) -> #N/A | J12: =+(3.33333333333333)*Tabla15[[#This Row],[DIAS TRABAJADOS]]-60 -> #N/A
B13: 7 | C13: 603838657 | D13: =+VLOOKUP(Tabla15[[#This Row],[CEDULA]],'OCTUBRE 2025'!$C$8:$J$10,2,0) -> #N/A | E13: 01/OCTUBRE/2022 | F13: EJECUTIVO DE RECAUDACION | G13: Durán | H13: =+VLOOKUP(Tabla15[[#This Row],[CEDULA]],'OCTUBRE 2025'!$C$8:$J$10,7,0) -> #N/A | I13: =+VLOOKUP(Tabla15[[#This Row],[CEDULA]],'OCTUBRE 2025'!$C$8:$J$10,8,0) -> #N/A | J13: 200
B14: 8 | C14: 925240525 | D14: =+VLOOKUP(Tabla15[[#This Row],[CEDULA]],'OCTUBRE 2025'!$C$8:$J$10,2,0) -> #N/A | E14: 01/JUNIO/2006 | F14: ASESOR LEGAL | G14: Matriz | H14: =+VLOOKUP(Tabla15[[#This Row],[CEDULA]],'OCTUBRE 2025'!$C$8:$J$10,7,0) -> #N/A | I14: =+VLOOKUP(Tabla15[[#This Row],[CEDULA]],'OCTUBRE 2025'!$C$8:$J$10,8,0) -> #N/A | J14: =200-200 -> 0
C15: 0943906032 | D15: =+VLOOKUP(Tabla15[[#This Row],[CEDULA]],'OCTUBRE 2025'!$C$8:$J$10,2,0) -> #N/A | F15: EJECUTIVO DE RECAUDACION | G15: Norte | H15: 30 | I15: 473.88 | J15: =100 -> 100
B16: 9 | C16: 950703199 | D16: =+VLOOKUP(Tabla15[[#This Row],[CEDULA]],'OCTUBRE 2025'!$C$8:$J$10,2,0) -> #N/A | E16: 13/OCTUBRE/2022 | F16: EJECUTIVO DE RECAUDACION | G16: Matriz | H16: =+VLOOKUP(Tabla15[[#This Row],[CEDULA]],'OCTUBRE 2025'!$C$8:$J$10,7,0) -> #N/A | I16: =+VLOOKUP(Tabla15[[#This Row],[CEDULA]],'OCTUBRE 2025'!$C$8:$J$10,8,0) -> #N/A | J16: =100 -> 100
B17: 10 | C17: 925830689 | D17: =+VLOOKUP(Tabla15[[#This Row],[CEDULA]],'OCTUBRE 2025'!$C$8:$J$10,2,0) -> #N/A | E17: 01/AGOSTO/2019 | F17: JEFE DE AGENCIA | G17: Matriz | H17: =+VLOOKUP(Tabla15[[#This Row],[CEDULA]],'OCTUBRE 2025'!$C$8:$J$10,7,0) -> #N/A | I17: =+VLOOKUP(Tabla15[[#This Row],[CEDULA]],'OCTUBRE 2025'!$C$8:$J$10,8,0) -> #N/A | J17: 0
B18: 12 | C18: 951340702 | D18: =+VLOOKUP(Tabla15[[#This Row],[CEDULA]],'OCTUBRE 2025'!$C$8:$J$10,2,0) -> #N/A | E18: 18/ENERO/2022 | F18: JEFE DE CAPTACIONES | G18: Matriz | H18: =+VLOOKUP(Tabla15[[#This Row],[CEDULA]],'OCTUBRE 2025'!$C$8:$J$10,7,0) -> #N/A | I18: =+VLOOKUP(Tabla15[[#This Row],[CEDULA]],'OCTUBRE 2025'!$C$8:$J$10,8,0) -> #N/A | J18: 0
B19: 13 | C19: 927257576 | D19: =+VLOOKUP(Tabla15[[#This Row],[CEDULA]],'OCTUBRE 2025'!$C$8:$J$10,2,0) -> #N/A | E19: 04/NOVIEMBRE/2020 | F19: JEFE DE AGENCIA | G19: Norte | H19: =+VLOOKUP(Tabla15[[#This Row],[CEDULA]],'OCTUBRE 2025'!$C$8:$J$10,7,0) -> #N/A | I19: =+VLOOKUP(Tabla15[[#This Row],[CEDULA]],'OCTUBRE 2025'!$C$8:$J$10,8,0) -> #N/A | J19: =200-200 -> 0
B20: 14 | C20: 928901800 | D20: =+VLOOKUP(Tabla15[[#This Row],[CEDULA]],'OCTUBRE 2025'!$C$8:$J$10,2,0) -> #N/A | E20: 01/MAYO/2017 | F20: JEFE DE BOVEDA | G20: Matriz | H20: =+VLOOKUP(Tabla15[[#This Row],[CEDULA]],'OCTUBRE 2025'!$C$8:$J$10,7,0) -> #N/A | I20: =+VLOOKUP(Tabla15[[#This Row],[CEDULA]],'OCTUBRE 2025'!$C$8:$J$10,8,0) -> #N/A | J20: =300-100-100 -> 100
B21: 15 | C21: 954184321 | D21: =+VLOOKUP(Tabla15[[#This Row],[CEDULA]],'OCTUBRE 2025'!$C$8:$J$10,2,0) -> #N/A | E21: 01/JULIO/2021 | F21: EJECUTIVO DE RECAUDACION | G21: Matriz | H21: =+VLOOKUP(Tabla15[[#This Row],[CEDULA]],'OCTUBRE 2025'!$C$8:$J$10,7,0) -> #N/A | I21: =+VLOOKUP(Tabla15[[#This Row],[CEDULA]],'OCTUBRE 2025'!$C$8:$J$10,8,0) -> #N/A | J21: =100 -> 100
B22: 16 | C22: 941508905 | D22: =+VLOOKUP(Tabla15[[#This Row],[CEDULA]],'OCTUBRE 2025'!$C$8:$J$10,2,0) -> YUQUILEMA CACUANGO ANGEL JOSE | E22: 12/ABRIL/2019 | F22: EJECUTIVO DE RECAUDACION | G22: Matriz | H22: =+VLOOKUP(Tabla15[[#This Row],[CEDULA]],'OCTUBRE 2025'!$C$8:$J$10,7,0) -> 30 | I22: =+VLOOKUP(Tabla15[[#This Row],[CEDULA]],'OCTUBRE 2025'!$C$8:$J$10,8,0) -> 511.1 | J22: =(100/30)*Tabla15[[#This Row],[DIAS TRABAJADOS]] -> 100
B23: 18 | C23: 604154575 | D23: =+VLOOKUP(Tabla15[[#This Row],[CEDULA]],'OCTUBRE 2025'!$C$8:$J$10,2,0) -> YUQUILEMA DELGADO PEDRO ANTONIO | E23: 06/OCTUBRE/2018 | F23: JEFE DE AGENCIA | G23: Durán | H23: =+VLOOKUP(Tabla15[[#This Row],[CEDULA]],'OCTUBRE 2025'!$C$8:$J$10,7,0) -> 30 | I23: =+VLOOKUP(Tabla15[[#This Row],[CEDULA]],'OCTUBRE 2025'!$C$8:$J$10,8,0) -> 1022.2 | J23: =200-200 -> 0
D25: TOTALES | J25: =SUM(Tabla15[BONO VEHICULAR]) -> #N/A
B44: 4

Sheet COMISIONES
B2: CALCULO DE APERTURA CUENTA- COLOCACIONES - PLAZO FIJO
B3: NOMINA AGOSTO 2023
B4: DEL CORTE DEL 01 DE AGOSTO AL 31 DE AGOSTO DEL 2023
B6: No. | C6: CEDULA | D6: NOMBRE | E6: BONO POR CUMPLIMIENTO | F6: COMISIÓN META | G6: COMISION POR PLAZOS FIJOS | H6: COM. SOCIOS NUEVOS Y COLOCACION | I6: ANTICIPO A SUELDO
B8: 1 | C8: =+'OCTUBRE 2025'!#REF! -> #REF! | D8: =+VLOOKUP(C8,'OCTUBRE 2025'!$C$8:$F$10,2,0) -> #REF!
B9: 2 | C9: =+'OCTUBRE 2025'!#REF! -> #REF! | D9: =+VLOOKUP(C9,'OCTUBRE 2025'!$C$8:$F$10,2,0) -> #REF!
B10: 3 | C10: =+'OCTUBRE 2025'!#REF! -> #REF! | D10: =+VLOOKUP(C10,'OCTUBRE 2025'!$C$8:$F$10,2,0) -> #REF!
B11: 4 | C11: =+'OCTUBRE 2025'!#REF! -> #REF! | D11: =+VLOOKUP(C11,'OCTUBRE 2025'!$C$8:$F$10,2,0) -> #REF! | E11: 100 | F11: 236.65 | H11: 30
B12: 5 | C12: =+'OCTUBRE 2025'!#REF! -> #REF! | D12: =+VLOOKUP(C12,'OCTUBRE 2025'!$C$8:$F$10,2,0) -> #REF! | E12: 100 | F12: 99.5
B13: 6 | C13: =+'OCTUBRE 2025'!#REF! -> #REF! | D13: =+VLOOKUP(C13,'OCTUBRE 2025'!$C$8:$F$10,2,0) -> #REF!
B14: 7 | C14: =+'OCTUBRE 2025'!#REF! -> #REF! | D14: =+VLOOKUP(C14,'OCTUBRE 2025'!$C$8:$F$10,2,0) -> #REF!
B15: 8 | C15: =+'OCTUBRE 2025'!#REF! -> #REF! | D15: =+VLOOKUP(C15,'OCTUBRE 2025'!$C$8:$F$10,2,0) -> #REF!
B16: 9 | C16: =+'OCTUBRE 2025'!#REF! -> #REF! | D16: =+VLOOKUP(C16,'OCTUBRE 2025'!$C$8:$F$10,2,0) -> #REF!
B17: 10 | C17: =+'OCTUBRE 2025'!#REF! -> #REF! | D17: =+VLOOKUP(C17,'OCTUBRE 2025'!$C$8:$F$10,2,0) -> #REF!
B18: 11 | C18: =+'OCTUBRE 2025'!#REF! -> #REF! | D18: =+VLOOKUP(C18,'OCTUBRE 2025'!$C$8:$F$10,2,0) -> #REF!
B19: 12 | C19: =+'OCTUBRE 2025'!#REF! -> #REF! | D19: =+VLOOKUP(C19,'OCTUBRE 2025'!$C$8:$F$10,2,0) -> #REF!
B20: 13 | C20: =+'OCTUBRE 2025'!#REF! -> #REF! | D20: =+VLOOKUP(C20,'OCTUBRE 2025'!$C$8:$F$10,2,0) -> #REF!
B21: 14 | C21: =+'OCTUBRE 2025'!#REF! -> #REF! | D21: =+VLOOKUP(C21,'OCTUBRE 2025'!$C$8:$F$10,2,0) -> #REF!
B22: 15 | C22: =+'OCTUBRE 2025'!#REF! -> #REF! | D22: =+VLOOKUP(C22,'OCTUBRE 2025'!$C$8:$F$10,2,0) -> #REF! | F22: 7.31
B23: 16 | C23: =+'OCTUBRE 2025'!#REF! -> #REF! | D23: =+VLOOKUP(C23,'OCTUBRE 2025'!$C$8:$F$10,2,0) -> #REF!
B24: 17 | C24: =+'OCTUBRE 2025'!#REF! -> #REF! | D24: =+VLOOKUP(C24,'OCTUBRE 2025'!$C$8:$F$10,2,0) -> #REF! | F24: 10.84
B25: 18 | C25: =+'OCTUBRE 2025'!#REF! -> #REF! | D25: =+VLOOKUP(C25,'OCTUBRE 2025'!$C$8:$F$10,2,0) -> #REF!
B26: 19 | C26: =+'OCTUBRE 2025'!#REF! -> #REF! | D26: =+VLOOKUP(C26,'OCTUBRE 2025'!$C$8:$F$10,2,0) -> #REF!
B27: 20 | C27: =+'OCTUBRE 2025'!#REF! -> #REF! | D27: =+VLOOKUP(C27,'OCTUBRE 2025'!$C$8:$F$10,2,0) -> #REF!
B28: 21 | C28: =+'OCTUBRE 2025'!#REF! -> #REF! | D28: =+VLOOKUP(C28,'OCTUBRE 2025'!$C$8:$F$10,2,0) -> #REF!
B29: 22 | C29: =+'OCTUBRE 2025'!#REF! -> #REF! | D29: =+VLOOKUP(C29,'OCTUBRE 2025'!$C$8:$F$10,2,0) -> #REF!
B30: 23 | C30: =+'OCTUBRE 2025'!#REF! -> #REF! | D30: =+VLOOKUP(C30,'OCTUBRE 2025'!$C$8:$F$10,2,0) -> #REF! | E30: 100 | F30: 518.5
B31: 24 | C31: =+'OCTUBRE 2025'!#REF! -> #REF! | D31: =+VLOOKUP(C31,'OCTUBRE 2025'!$C$8:$F$10,2,0) -> #REF!
B32: 25 | C32: =+'OCTUBRE 2025'!#REF! -> #REF! | D32: =+VLOOKUP(C32,'OCTUBRE 2025'!$C$8:$F$10,2,0) -> #REF!
B33: 26 | C33: =+'OCTUBRE 2025'!#REF! -> #REF! | D33: =+VLOOKUP(C33,'OCTUBRE 2025'!$C$8:$F$10,2,0) -> #REF!
B34: 27 | C34: =+'OCTUBRE 2025'!#REF! -> #REF! | D34: =+VLOOKUP(C34,'OCTUBRE 2025'!$C$8:$F$10,2,0) -> #REF!
B35: 28 | C35: =+'OCTUBRE 2025'!#REF! -> #REF! | D35: =+VLOOKUP(C35,'OCTUBRE 2025'!$C$8:$F$10,2,0) -> #REF!
B36: 29 | C36: =+'OCTUBRE 2025'!#REF! -> #REF! | D36: =+VLOOKUP(C36,'OCTUBRE 2025'!$C$8:$F$10,2,0) -> #REF!
B37: 30 | C37: =+'OCTUBRE 2025'!#REF! -> #REF! | D37: =+VLOOKUP(C37,'OCTUBRE 2025'!$C$8:$F$10,2,0) -> #REF!
B38: 31 | C38: =+'OCTUBRE 2025'!#REF! -> #REF! | D38: =+VLOOKUP(C38,'OCTUBRE 2025'!$C$8:$F$10,2,0) -> #REF! | F38: 60.37
B39: 32 | C39: =+'OCTUBRE 2025'!#REF! -> #REF! | D39: =+VLOOKUP(C39,'OCTUBRE 2025'!$C$8:$F$10,2,0) -> #REF!
B40: 33 | C40: =+'OCTUBRE 2025'!#REF! -> #REF! | D40: =+VLOOKUP(C40,'OCTUBRE 2025'!$C$8:$F$10,2,0) -> #REF! | E40: 100 | F40: 75
B41: 34 | C41: =+'OCTUBRE 2025'!#REF! -> #REF! | D41: =+VLOOKUP(C41,'OCTUBRE 2025'!$C$8:$F$10,2,0) -> #REF!
B42: 35 | C42: =+'OCTUBRE 2025'!#REF! -> #REF! | D42: =+VLOOKUP(C42,'OCTUBRE 2025'!$C$8:$F$10,2,0) -> #REF!
B43: 36 | C43: =+'OCTUBRE 2025'!#REF! -> #REF! | D43: =+VLOOKUP(C43,'OCTUBRE 2025'!$C$8:$F$10,2,0) -> #REF!
...

Sheet ROL INDIVIDUAL
F5: ROL INDIVIDUAL | H5: 45931
C7: Identificación: | D7: 923837991 | F7: Oficina: | G7: =VLOOKUP($D$7,'OCTUBRE 2025'!$C$8:$AJ$10,6,0) -> Matriz
C8: Nombres: | D8: =VLOOKUP($D$7,'OCTUBRE 2025'!$C$8:$AJ$10,2,0) -> YUNDA CUJILEMA MARIA TERESA | F8: No. días: | G8: =VLOOKUP($D$7,'OCTUBRE 2025'!$C$8:$AJ$10,7,0) -> 30
C9: Cargo: | D9: =VLOOKUP($D$7,'OCTUBRE 2025'!$C$8:$AJ$10,4,0) -> CONTADOR GENERAL
C11: INGRESOS | E11: VALOR | F11: EGRESOS | H11: VALOR
C12: Sueldo básico cooperativa | E12: =VLOOKUP($D$7,'OCTUBRE 2025'!$C$8:$AJ$10,8,0) -> 1022.2 | F12: Aporte Individual IESS 9.45% | H12: =VLOOKUP($D$7,'OCTUBRE 2025'!$C$8:$AJ$10,24,0) -> 106.0479
C13: Bono Movilización | E13: =VLOOKUP($D$7,'OCTUBRE 2025'!$C$8:$AJ$10,9,0) -> 0 | F13: Préstamos Quirografarios o Hipotecarios | H13: =VLOOKUP($D$7,'OCTUBRE 2025'!$C$8:$AJ$10,27,0) -> 0
C14: Bono mensual (2.174%) | E14: =VLOOKUP($D$7,'OCTUBRE 2025'!$C$8:$AJ$10,10,0) -> 100 | F14: Subsidio Monetario | H14: =VLOOKUP($D$7,'OCTUBRE 2025'!$C$8:$AJ$10,28,0) -> 0
C15: Bono cumplimiento | E15: =VLOOKUP($D$7,'OCTUBRE 2025'!$C$8:$AJ$10,11,0) -> 0 | F15: Extensión de Salud | H15: =VLOOKUP($D$7,'OCTUBRE 2025'!$C$8:$AJ$10,29,0) -> 0
C16: Comisión por superación de meta | E16: =VLOOKUP($D$7,'OCTUBRE 2025'!$C$8:$AJ$10,12,0) -> 0 | F16: Pensión alimenticia | H16: =VLOOKUP($D$7,'OCTUBRE 2025'!$C$8:$AJ$10,30,0) -> 0
C17: Comisión por Depósito a Plazo Fijo | E17: =VLOOKUP($D$7,'OCTUBRE 2025'!$C$8:$AJ$10,13,0) -> 0 | F17: Cuentas por cobrar | H17: =VLOOKUP($D$7,'OCTUBRE 2025'!$C$8:$AJ$10,31,0) -> 0
C18: Comisión socios nuevos | E18: =VLOOKUP($D$7,'OCTUBRE 2025'!$C$8:$AJ$10,14,0) -> 0 | F18: Anticipo de Sueldo | H18: =VLOOKUP($D$7,'OCTUBRE 2025'!$C$8:$AJ$10,32,0) -> 850
C19: Horas Extras 50% | E19: =VLOOKUP($D$7,'OCTUBRE 2025'!$C$8:$AJ$10,15,0) -> 0 | F19: Ret Imp. A la Renta | H19: =VLOOKUP($D$7,'OCTUBRE 2025'!$C$8:$AJ$10,25,0) -> 0
C20: Horas Extras 100% | E20: =VLOOKUP($D$7,'OCTUBRE 2025'!$C$8:$AJ$10,16,0) -> 0 | F20: Descuentos | H20: =VLOOKUP($D$7,'OCTUBRE 2025'!$C$8:$AJ$10,26,0) -> 0
C21: Fondo de Reserva | E21: =VLOOKUP($D$7,'OCTUBRE 2025'!$C$8:$AJ$10,19,0) -> 93.47926
C22: Fondo de Reserva (ajustes) | E22: =VLOOKUP($D$7,'OCTUBRE 2025'!$C$8:$AJ$10,20,0) -> 0
C23: Décimo Tercero | E23: =VLOOKUP($D$7,'OCTUBRE 2025'!$C$8:$AJ$10,21,0) -> 0
C24: Décimo Cuarto | E24: =VLOOKUP($D$7,'OCTUBRE 2025'!$C$8:$AJ$10,22,0) -> 0
C25: TOTAL DE INGRESOS | E25: =SUM(E12:E24) -> 1215.6793 | F25: TOTAL EGRESOS | H25: =SUM(H12:H23) -> 956.0479
F26: VALOR NETO A RECIBIR | H26: =+E25-H25 -> 259.63136
C28: Elaborado por: | G28: Recibí Conforme:
C31: Ing. Magaly Morocho | G31: =+$D$8 -> YUNDA CUJILEMA MARIA TERESA
C32: Talento Humano | G32: Funcionario

Sheet ROL INDIVIDUAL (2)
F5: ROL INDIVIDUAL | H5: 45839
C7: Identificación: | D7: 0943906032 | F7: Oficina: | G7: =VLOOKUP($D$7,'OCTUBRE 2025'!$C$8:$AJ$10,6,0) -> #N/A
C8: Nombres: | D8: =VLOOKUP($D$7,'OCTUBRE 2025'!$C$8:$AJ$10,2,0) -> #N/A | F8: No. días: | G8: =VLOOKUP($D$7,'OCTUBRE 2025'!$C$8:$AJ$10,7,0) -> #N/A
C9: Cargo: | D9: =VLOOKUP($D$7,'OCTUBRE 2025'!$C$8:$AJ$10,4,0) -> #N/A
C11: INGRESOS | E11: VALOR | F11: EGRESOS | H11: VALOR
C12: Sueldo básico cooperativa | E12: =VLOOKUP($D$7,'OCTUBRE 2025'!$C$8:$AJ$10,8,0) -> #N/A | F12: Aporte Individual IESS 9.45% | H12: =VLOOKUP($D$7,'OCTUBRE 2025'!$C$8:$AJ$10,24,0) -> #N/A
C13: Bono Movilización | E13: =VLOOKUP($D$7,'OCTUBRE 2025'!$C$8:$AJ$10,9,0) -> #N/A | F13: Préstamos Quirografarios o Hipotecarios | H13: =VLOOKUP($D$7,'OCTUBRE 2025'!$C$8:$AJ$10,27,0) -> #N/A
C14: Bono mensual (2.174%) | E14: =VLOOKUP($D$7,'OCTUBRE 2025'!$C$8:$AJ$10,10,0) -> #N/A | F14: Subsidio Monetario | H14: =VLOOKUP($D$7,'OCTUBRE 2025'!$C$8:$AJ$10,28,0) -> #N/A
C15: Bono cumplimiento | E15: =VLOOKUP($D$7,'OCTUBRE 2025'!$C$8:$AJ$10,11,0) -> #N/A | F15: Extensión de Salud | H15: =VLOOKUP($D$7,'OCTUBRE 2025'!$C$8:$AJ$10,29,0) -> #N/A
C16: Comisión por cumplimiento de meta | E16: =VLOOKUP($D$7,'OCTUBRE 2025'!$C$8:$AJ$10,12,0) -> #N/A | F16: Pensión alimenticia | H16: =VLOOKUP($D$7,'OCTUBRE 2025'!$C$8:$AJ$10,30,0) -> #N/A
C17: Comisión por Depósito a Plazo Fijo | E17: =VLOOKUP($D$7,'OCTUBRE 2025'!$C$8:$AJ$10,13,0) -> #N/A | F17: Cuentas por cobrar | H17: =VLOOKUP($D$7,'OCTUBRE 2025'!$C$8:$AJ$10,31,0) -> #N/A
C18: Comisión socios nuevos | E18: =VLOOKUP($D$7,'OCTUBRE 2025'!$C$8:$AJ$10,14,0) -> #N/A | F18: Anticipo de Sueldo | H18: 0
C19: Horas Extras 50% | E19: =VLOOKUP($D$7,'OCTUBRE 2025'!$C$8:$AJ$10,15,0) -> #N/A | F19: Ret Imp. A la Renta | H19: =VLOOKUP($D$7,'OCTUBRE 2025'!$C$8:$AJ$10,25,0) -> #N/A
C20: Horas Extras 100% | E20: =VLOOKUP($D$7,'OCTUBRE 2025'!$C$8:$AJ$10,16,0) -> #N/A | F20: Descuentos | H20: =VLOOKUP($D$7,'OCTUBRE 2025'!$C$8:$AJ$10,26,0) -> #N/A
C21: Fondo de Reserva | E21: =VLOOKUP($D$7,'OCTUBRE 2025'!$C$8:$AJ$10,19,0) -> #N/A
C22: Fondo de Reserva (ajustes) | E22: =VLOOKUP($D$7,'OCTUBRE 2025'!$C$8:$AJ$10,20,0) -> #N/A
C23: Décimo Tercero | E23: =VLOOKUP($D$7,'OCTUBRE 2025'!$C$8:$AJ$10,21,0) -> #N/A
C24: Décimo Cuarto | E24: =VLOOKUP($D$7,'OCTUBRE 2025'!$C$8:$AJ$10,22,0) -> #N/A
C25: TOTAL DE INGRESOS | E25: =SUM(E12:E24) -> #N/A | F25: TOTAL EGRESOS | H25: =SUM(H12:H23) -> #N/A
F26: VALOR NETO A RECIBIR | H26: =+E25-H25 -> #N/A
C28: Elaborado por: | G28: Recibí Conforme:
C31: Ing. Magaly Morocho | G31: =+$D$8 -> #N/A
C32: Talento Humano | G32: Funcionario

Sheet CHIMBOLEMA
B8: Trabajador(a): | C8: CHIMBOLEMA YUNGAN MARIO EFRAIN | F8: Inicio: | G8: 45884
B9: Fecha de ingreso: | C9: 45884 | F9: Fin: | G9: 45681
B10: Sueldo: | C10: 473.88 | F10: Total de dias | G10: =+_xlfn.DAYS(G9,G8) -> -203
B11: Subsidio: | C11: MATERNIDAD
B13: Calculo para el Pago:
B14: Sueldo Promedio Diario: | D14: =+C10/30 -> 15.796 | E14: (1-3 dias) | F14: =+C10/30 -> 15.796
B15: Promedio Diario (25%): | D15: =+D14*25% -> 3.949 | E15: (4-70 dias) | F15: =+F14*25% -> 3.949
B17: Nº | C17: Periodo | E17: Pocentaje | F17: Num. Dias | G17: Valor | M17: Nº | N17: Periodo | P17: Pocentaje | Q17: Num. Dias | R17: Valor
C18: Desde | D18: Hasta | N18: Desde | O18: Hasta
B19: 1 | C19: 45931 | D19: 45939 | E19: 100 | F19: =+D19-C19+1 -> 9 | G19: =+F14*F19 -> 142.164 | M19: 1 | N19: 45593 | O19: 45596 | P19: 25 | Q19: 4 | R19: =+Q15*Q19 -> 0
B20: 2 | M20: 2 | N20: 45597 | O20: 45626 | P20: 25 | Q20: 30 | R20: =+Q15*Q20 -> 0
B21: 3 | M21: 3 | N21: 45992 | O21: 45657 | P21: 25 | Q21: 31 | R21: =+Q21*Q15 -> 0
B22: 4 | M22: 4 | N22: 45658 | O22: 45676 | P22: 25 | Q22: 19 | R22: =+Q22*Q14 -> 0
B27: TOTAL | F27: =SUM(F19:F22) -> 9 | G27: =SUM(G19:G26) -> 142.164 | M27: TOTAL | Q27: =SUM(Q19:Q24) -> 84 | R27: =SUM(R19:R26) -> 0
B29: ROL PROPORCIONAL OCTUBRE 2024
B31: INGRESOS | C31: VALOR | D31: EGRESOS | E31: VALOR
B32: SUELDO BÁSICO COOPERATIVA | C32: =+G19 -> 142.164 | D32: APORTE INDIVIDUAL AL IESS 9.45 | E32: =+((C32+C33+C34+C39)*9.45%) -> 16.269498
B33: BONO MOVILIZACION | C33: =+(3.33333333333333)*9 -> 30 | D33: CUENTAS POR COBRAR | E33: 0
B34: BONO CUMPLIMIENTO | C34: 0
B35: COMISION POR SUPERAR LA META | C35: 0
B36: COMISION POR PLAZOS FIJOS | C36: 0 | D36: anticipo | E36: 0
B37: COMISION POR SOCIOS NUEVOS | C37: 0
B38: HORAS EXTRAS 50% | C38: 0
B39: HORAS EXTRAS 100% | C39: 0
B40: FONDO DE RESERVA | C40: 0
B41: DECIMO TERCERO | C41: 0
B42: DECIMO CUARTO | C42: 0
B43: TOTAL INGRESOS | C43: =SUM(C32:C42) -> 172.164 | D43: TOTAL EGRESOS | E43: =SUM(E32:E42) -> 16.269498
D44: VALOR NETO A RECIBIR | E44: =+C43-E43 -> 155.8945
E48: 645.95749

Sheet coca
B8: Trabajador(a): | C8: COCA BENITEZ JORGE | F8: Inicio:
B9: Fecha de ingreso: | C9: 45762 | F9: Fin:
B10: Sueldo: | C10: 715.54 | F10: Total de dias | G10: =+_xlfn.DAYS(G9,G8)+1 -> 1
B11: Subsidio: | C11: MATERNIDAD
B13: Calculo para el Pago: | H13: =+C10/30 -> 23.851333
B14: Sueldo Promedio Diario: | D14: =+C10/30 -> 23.851333 | E14: (1-3 dias) | F14: =+C10/30 -> 23.851333
B15: Promedio Diario (25%): | D15: =+D14*25% -> 5.9628333 | E15: (4-70 dias) | F15: =+F14*25% -> 5.9628333
B17: Nº | C17: Periodo | E17: Pocentaje | F17: Num. Dias | G17: Valor | M17: Nº | N17: Periodo | P17: Pocentaje | Q17: Num. Dias | R17: Valor
C18: Desde | D18: Hasta | N18: Desde | O18: Hasta
B19: 1 | C19: 45658 | D19: 45674 | E19: 100 | F19: 17 | G19: =+F14*F19 -> 405.47267 | M19: 1 | N19: 45593 | O19: 45596 | P19: 25 | Q19: 4 | R19: =+Q15*Q19 -> 0
B20: 2 | C20: 45675 | D20: 45688 | E20: 25 | F20: 14 | G20: =+F15*F20 -> 83.479667 | M20: 2 | N20: 45597 | O20: 45626 | P20: 25 | Q20: 30 | R20: =+Q15*Q20 -> 0
B21: 3 | G21: =+F21*F15 -> 0 | M21: 3 | N21: 45992 | O21: 45657 | P21: 25 | Q21: 31 | R21: =+Q21*Q15 -> 0
B22: 4 | G22: =+F22*F14 -> 0 | M22: 4 | N22: 45658 | O22: 45676 | P22: 25 | Q22: 19 | R22: =+Q22*Q14 -> 0
B27: TOTAL | F27: =SUM(F19:F22) -> 31 | G27: =SUM(G19:G26) -> 488.95233 | M27: TOTAL | Q27: =SUM(Q19:Q24) -> 84 | R27: =SUM(R19:R26) -> 0
B29: ROL PROPORCIONAL JUNIO 2024
B31: INGRESOS | C31: VALOR | D31: EGRESOS | E31: VALOR
B32: SUELDO BÁSICO COOPERATIVA | C32: 715.54 | D32: APORTE INDIVIDUAL AL IESS 9.45 | E32: =+((C10*9.45%)) -> 67.61853
B33: BONO MOVILIZACION | C33: 0 | D33: descuento | E33: 0 | H33: =1200-C32 -> 484.46
B34: BONO CUMPLIMIENTO | C34: 0 | E34: 145 | H34: =+ROUND(H33*9.45%,2) -> 45.78
B35: COMISION POR SUPERAR LA META | C35: 0 | H35: =+ROUND(H33*12.15%,2) -> 58.86
B36: COMISION POR PLAZOS FIJOS | C36: 0 | H36: =+H33*8.33% -> 40.355518
B37: COMISION POR SOCIOS NUEVOS | C37: 0
B38: HORAS EXTRAS 50% | C38: 0 | H38: =+SUM(H34:H36) -> 144.99552
B39: HORAS EXTRAS 100% | C39: 0
B40: FONDO DE RESERVA | C40: =+(C32*8.33%) -> 59.604482
B41: DECIMO TERCERO | C41: 0
B42: DECIMO CUARTO | C42: 0
B43: TOTAL INGRESOS | C43: =SUM(C32:C42) -> 775.14448 | D43: TOTAL EGRESOS | E43: =SUM(E32:E42) -> 212.61853 | G43: 1186.55
D44: VALOR NETO A RECIBIR | E44: =+C43-E43 -> 562.52595 | G44: =+G43-E44 -> 624.02405
K47: 602.89
B50: INGRESOS | C50: VALOR | D50: EGRESOS | E50: VALOR
B51: SUELDO BÁSICO COOPERATIVA | C51: 1200 | D51: APORTE INDIVIDUAL AL IESS 9.45 | E51: =+((C51*9.45%)) -> 113.4
B52: BONO MOVILIZACION | C52: 0 | D52: descuento | E52: 36
B53: BONO CUMPLIMIENTO | C53: 0 | E53: 0
B54: COMISION POR SUPERAR LA META | C54: 0
B55: COMISION POR PLAZOS FIJOS | C55: 0
B56: COMISION POR SOCIOS NUEVOS | C56: 0
B57: HORAS EXTRAS 50% | C57: 0
B58: HORAS EXTRAS 100% | C58: 0
B59: FONDO DE RESERVA | C59: =+(C51*8.33%) -> 99.96
...

Sheet coca (2)
B8: Trabajador(a): | C8: COCA BENITEZ JORGE | F8: Inicio:
B9: Fecha de ingreso: | C9: 45762 | F9: Fin:
B10: Sueldo: | C10: 715.54 | F10: Total de dias | G10: =+_xlfn.DAYS(G9,G8)+1 -> 1
B11: Subsidio: | C11: MATERNIDAD
B13: Calculo para el Pago: | H13: =+C10/30 -> 23.851333
B14: Sueldo Promedio Diario: | D14: =+C10/30 -> 23.851333 | E14: (1-3 dias) | F14: =+C10/30 -> 23.851333
B15: Promedio Diario (25%): | D15: =+D14*25% -> 5.9628333 | E15: (4-70 dias) | F15: =+F14*25% -> 5.9628333
B17: Nº | C17: Periodo | E17: Pocentaje | F17: Num. Dias | G17: Valor | M17: Nº | N17: Periodo | P17: Pocentaje | Q17: Num. Dias | R17: Valor
C18: Desde | D18: Hasta | N18: Desde | O18: Hasta
B19: 1 | C19: 45658 | D19: 45674 | E19: 100 | F19: 17 | G19: =+F14*F19 -> 405.47267 | M19: 1 | N19: 45593 | O19: 45596 | P19: 25 | Q19: 4 | R19: =+Q15*Q19 -> 0
B20: 2 | C20: 45675 | D20: 45688 | E20: 25 | F20: 14 | G20: =+F15*F20 -> 83.479667 | M20: 2 | N20: 45597 | O20: 45626 | P20: 25 | Q20: 30 | R20: =+Q15*Q20 -> 0
B21: 3 | G21: =+F21*F15 -> 0 | M21: 3 | N21: 45992 | O21: 45657 | P21: 25 | Q21: 31 | R21: =+Q21*Q15 -> 0
B22: 4 | G22: =+F22*F14 -> 0 | M22: 4 | N22: 45658 | O22: 45676 | P22: 25 | Q22: 19 | R22: =+Q22*Q14 -> 0
B27: TOTAL | F27: =SUM(F19:F22) -> 31 | G27: =SUM(G19:G26) -> 488.95233 | M27: TOTAL | Q27: =SUM(Q19:Q24) -> 84 | R27: =SUM(R19:R26) -> 0
B29: ROL PROPORCIONAL JUNIO 2024
B31: INGRESOS | C31: VALOR | D31: EGRESOS | E31: VALOR
B32: SUELDO BÁSICO COOPERATIVA | C32: 700 | D32: APORTE INDIVIDUAL AL IESS 9.45 | E32: =+SUM(C32:C34)*9.45% -> 115.46766
B33: BONO MOVILIZACION | C33: 21.88 | D33: descuento | E33: 0 | H33: =1200-C32 -> 500 | J33: =+SUM(C32:C34) -> 1221.88
B34: BONO CUMPLIMIENTO | C34: 500 | E34: 360 | H34: =+ROUND(H33*9.45%,2) -> 47.25 | J34: =+J33*9.45% -> 115.46766
B35: COMISION POR SUPERAR LA META | C35: 0 | H35: =+ROUND(H33*12.15%,2) -> 60.75
B36: COMISION POR PLAZOS FIJOS | C36: 0 | H36: =+H33*8.33% -> 41.65
B37: COMISION POR SOCIOS NUEVOS | C37: 0
B38: HORAS EXTRAS 50% | C38: 0 | H38: =+SUM(H34:H36) -> 149.65
B39: HORAS EXTRAS 100% | C39: 0
B40: FONDO DE RESERVA | C40: =+((C32+C33+C34)*8.33%) -> 101.7826
B41: DECIMO TERCERO | C41: 0
B42: DECIMO CUARTO | C42: 0
B43: TOTAL INGRESOS | C43: =SUM(C32:C42) -> 1323.6626 | D43: TOTAL EGRESOS | E43: =SUM(E32:E42) -> 475.46766 | G43: 1186.55
D44: VALOR NETO A RECIBIR | E44: =+C43-E43 -> 848.19494 | G44: =+G43-E44 -> 338.35506
K47: 602.89
B50: INGRESOS | C50: VALOR | D50: EGRESOS | E50: VALOR
B51: SUELDO BÁSICO COOPERATIVA | C51: 1200 | D51: APORTE INDIVIDUAL AL IESS 9.45 | E51: =+((C51*9.45%)) -> 113.4
B52: BONO MOVILIZACION | C52: 0 | D52: descuento | E52: 36
B53: BONO CUMPLIMIENTO | C53: 0 | E53: 0
B54: COMISION POR SUPERAR LA META | C54: 0
B55: COMISION POR PLAZOS FIJOS | C55: 0
B56: COMISION POR SOCIOS NUEVOS | C56: 0
B57: HORAS EXTRAS 50% | C57: 0
B58: HORAS EXTRAS 100% | C58: 0
B59: FONDO DE RESERVA | C59: =+(C51*8.33%) -> 99.96
...

Sheet Enfermedad-Meza)
B8: Trabajador(a): | C8: MEZA RODRIGUEZ MICHAEL FERNANDO | F8: Inicio: | G8: 45850
B9: Fecha de ingreso: | C9: 45762 | F9: Fin: | G9: 45869
B10: Sueldo: | C10: 473.88 | F10: Total de dias | G10: =+_xlfn.DAYS(G9,G8)+1 -> 20
B11: Subsidio: | C11: ENFERMEDAD GENERAL
B13: Calculo para el Pago:
B14: Sueldo Promedio Diario: | D14: =+C10/30 -> 15.796 | E14: (1-3 dias) | F14: =+C10/30 -> 15.796
B15: Promedio Diario (25%): | D15: =+D14*25% -> 3.949 | E15: (4-70 dias) | F15: =+F14*25% -> 3.949 | G15: =+F14*75% -> 11.847
B17: Nº | C17: Periodo | E17: Pocentaje | F17: Num. Dias | G17: Valor | M17: Nº | N17: Periodo | P17: Pocentaje | Q17: Num. Dias | R17: Valor
C18: Desde | D18: Hasta | N18: Desde | O18: Hasta
B19: 1 | C19: 45839 | D19: 45849 | E19: 100 | F19: 11 | G19: =IF(E19=100,$F$14*F19,$F$15*F19) -> 173.756 | M19: 1 | N19: 45593 | O19: 45596 | P19: 25 | Q19: 4 | R19: =+Q15*Q19 -> 0
B20: 2 | C20: 45850 | D20: 45852 | E20: 100 | F20: 19 | G20: =IF(E20=100,$F$14*F20,$F$15*F20) -> 300.124 | M20: 2 | N20: 45597 | O20: 45626 | P20: 25 | Q20: 30 | R20: =+Q15*Q20 -> 0
B21: 3 | E21: 0 | F21: 0 | G21: =IF(E21=100,$F$14*F21,$F$15*F21) -> 0 | M21: 3 | N21: 45992 | O21: 45657 | P21: 25 | Q21: 31 | R21: =+Q21*Q15 -> 0
B22: 4 | M22: 4 | N22: 45658 | O22: 45676 | P22: 25 | Q22: 19 | R22: =+Q22*Q14 -> 0
B23: 5
B24: 6
B25: 7
B26: 8
B27: TOTAL | F27: =SUM(F19:F22) -> 30 | G27: =SUM(G19:G26) -> 473.88 | M27: TOTAL | Q27: =SUM(Q19:Q24) -> 84 | R27: =SUM(R19:R26) -> 0
B29: ROL PROPORCIONAL FEBRERO 2025
B31: INGRESOS | C31: VALOR | D31: EGRESOS | E31: VALOR
B32: SUELDO BÁSICO COOPERATIVA | C32: =+G19 -> 173.756 | D32: APORTE INDIVIDUAL AL IESS 9.45 | E32: =+((C10+C34+C33+C37+C39)*9.45%) -> 51.596055
B33: BONO MOVILIZACION | C33: 36.67 | D33: CUENTAS POR COBRAR | E33: 0
B34: BONO CUMPLIMIENTO | C34: 10.3 | D34: anticipo de sueldo
B35: COMISION POR SUPERAR LA META | C35: 0
B36: COMISION POR PLAZOS FIJOS | C36: 0
B37: COMISION POR SOCIOS NUEVOS | C37: 5
B38: HORAS EXTRAS 50% | C38: 0
B39: HORAS EXTRAS 100% | C39: 20.14
B40: FONDO DE RESERVA | C40: 0
B41: DECIMO TERCERO | C41: 0
B42: DECIMO CUARTO | C42: 0
B43: TOTAL INGRESOS | C43: =SUM(C32:C42) -> 245.866 | D43: TOTAL EGRESOS | E43: =SUM(E32:E42) -> 51.596055 | G43: 494.39385
D44: VALOR NETO A RECIBIR | E44: =+C43-E43 -> 194.26995 | G44: =+G43-E44 -> 300.12391
J45: =100/30 -> 3.3333333
J46: =+J45*11 -> 36.666667

Sheet Cálculo Morocho
B8: Trabajador(a): | C8: MOROCHO YANTALEMA DINA | F8: Inicio: | G8: 45850
B9: Fecha de ingreso: | C9: 43074 | F9: Fin: | G9: 45869
B10: Sueldo: | C10: 766.65 | F10: Total de dias | G10: =+_xlfn.DAYS(G9,G8)+1 -> 20
B11: Subsidio: | C11: ENFERMEDAD GENERAL
B13: Calculo para el Pago:
B14: Sueldo Promedio Diario: | D14: =+C10/30 -> 25.555 | E14: (1-3 dias) | F14: =+C10/30 -> 25.555
B15: Promedio Diario (25%): | D15: =+D14*25% -> 6.38875 | E15: (4-70 dias) | F15: =+F14*25% -> 6.38875 | G15: =+F14*75% -> 19.16625
B17: Nº | C17: Periodo | E17: Pocentaje | F17: Num. Dias | G17: Valor | M17: Nº | N17: Periodo | P17: Pocentaje | Q17: Num. Dias | R17: Valor
C18: Desde | D18: Hasta | N18: Desde | O18: Hasta
B19: 1 | C19: 45839 | D19: 45849 | E19: 100 | F19: 19 | G19: =IF(E19=100,$F$14*F19,$F$15*F19) -> 485.545 | M19: 1 | N19: 45593 | O19: 45596 | P19: 25 | Q19: 4 | R19: =+Q15*Q19 -> 0
B20: 2 | C20: 45850 | D20: 45852 | E20: 0 | F20: 0 | G20: =IF(E20=100,$F$14*F20,$F$15*F20) -> 0 | M20: 2 | N20: 45597 | O20: 45626 | P20: 25 | Q20: 30 | R20: =+Q15*Q20 -> 0
B21: 3 | E21: 0 | F21: 0 | G21: =IF(E21=100,$F$14*F21,$F$15*F21) -> 0 | M21: 3 | N21: 45992 | O21: 45657 | P21: 25 | Q21: 31 | R21: =+Q21*Q15 -> 0
B22: 4 | M22: 4 | N22: 45658 | O22: 45676 | P22: 25 | Q22: 19 | R22: =+Q22*Q14 -> 0
B23: 5
B24: 6
B25: 7
B26: 8
B27: TOTAL | F27: =SUM(F19:F22) -> 19 | G27: =SUM(G19:G26) -> 485.545 | M27: TOTAL | Q27: =SUM(Q19:Q24) -> 84 | R27: =SUM(R19:R26) -> 0
B29: ROL PROPORCIONAL FEBRERO 2025
B31: INGRESOS | C31: VALOR | D31: EGRESOS | E31: VALOR
B32: SUELDO BÁSICO COOPERATIVA | C32: =+G19 -> 485.545 | D32: APORTE INDIVIDUAL AL IESS 9.45 | E32: =+((C10+C34+C33+C37+C39+C35)*9.45%) -> 78.74874
B33: BONO MOVILIZACION | D33: CUENTAS POR COBRAR | E33: 0
B34: BONO CUMPLIMIENTO | C34: 16.67 | D34: anticipo de sueldo
B35: COMISION POR SUPERAR LA META | C35: 50
B36: COMISION POR PLAZOS FIJOS
B37: COMISION POR SOCIOS NUEVOS
B38: HORAS EXTRAS 50%
B39: HORAS EXTRAS 100%
B40: FONDO DE RESERVA | C40: 69.42
B41: DECIMO TERCERO | C41: 0
B42: DECIMO CUARTO | C42: 0
B43: TOTAL INGRESOS | C43: =SUM(C32:C42) -> 621.635 | D43: TOTAL EGRESOS | E43: =SUM(E32:E42) -> 78.74874 | G43: 823.99
D44: VALOR NETO A RECIBIR | E44: =+C43-E43 -> 542.88626 | G44: =+G43-E44 -> 281.10374
J45: =100/30 -> 3.3333333
J46: =+J45*11 -> 36.666667

Sheet DEL ROSARIO
B8: Trabajador(a): | C8: LEMA TADAY BRAYAN | F8: Inicio: | G8: 45922
B9: Fecha de ingreso: | C9: 45841 | F9: Fin: | G9: 45930
B10: Sueldo: | C10: 481 | F10: Total de dias | G10: =+_xlfn.DAYS(G9,G8)+1 -> 9
B11: Subsidio: | C11: ENFERMEDAD GENERAL
B13: Calculo para el Pago:
B14: Sueldo Promedio Diario: | D14: =+C10/30 -> 16.033333 | E14: (1-3 dias) | F14: =+C10/30 -> 16.033333
B15: Promedio Diario (25%): | D15: =+D14*25% -> 4.0083333 | E15: (4-70 dias) | F15: =+F14*25% -> 4.0083333 | G15: =+F14*75% -> 12.025
I16: =+G15*18 -> 216.45
B17: Nº | C17: Periodo | E17: Pocentaje | F17: Num. Dias | G17: Valor
C18: Desde | D18: Hasta | I18: =+G27+I16 -> 841.75
B19: 1 | C19: 45922 | D19: 45930 | E19: 100 | F19: =+D19-C19+1 -> 9 | G19: =IF(E19=100,$F$14*F19,$F$15*F19) -> 144.3
B20: 2 | C20: 45931 | D20: 45944 | E20: 100 | F20: =+D20-C20+1 -> 14 | G20: =IF(E20=100,$F$14*F20,$F$15*F20) -> 224.46667
B21: 3 | C21: 45945 | D21: 45961 | E21: 100 | F21: =+D21-C21 -> 16 | G21: =IF(E21=100,$F$14*F21,$F$15*F21) -> 256.53333
B22: 4
B23: 5
B24: 6
B25: 7
B26: 8
B27: TOTAL | F27: =SUM(F19:F22) -> 39 | G27: =SUM(G19:G26) -> 625.3
B29: ROL PROPORCIONAL FEBRERO 2025
B31: INGRESOS | C31: VALOR | D31: EGRESOS | E31: VALOR
B32: SUELDO BÁSICO COOPERATIVA | C32: =+G19 -> 144.3 | D32: APORTE INDIVIDUAL AL IESS 9.45 | E32: =+((C10+C33+C39)*9.45%) -> 45.4545
B33: BONO MOVILIZACION | C33: 0 | D33: CUENTAS POR COBRAR | E33: 0 | H33: =100/30 -> 3.3333333
B34: BONO CUMPLIMIENTO | C34: 0 | D34: anticipo de sueldo | H34: =+H33*F19 -> 30
B35: COMISION POR SUPERAR LA META | C35: 0
B36: COMISION POR PLAZOS FIJOS
B37: COMISION POR SOCIOS NUEVOS
B38: HORAS EXTRAS 50%
B39: HORAS EXTRAS 100%
B40: FONDO DE RESERVA | C40: 0
B41: DECIMO TERCERO | C41: 0
B42: DECIMO CUARTO | C42: 0
B43: TOTAL INGRESOS | C43: =SUM(C32:C42) -> 144.3 | D43: TOTAL EGRESOS | E43: =SUM(E32:E42) -> 45.4545 | G43: 469.84584
D44: VALOR NETO A RECIBIR | E44: =+C43-E43 -> 98.8455 | G44: =+G43-E44 -> 371.00034

Sheet CHIMBOLEMA KEVIN
B8: Trabajador(a): | C8: LEMA TADAY BRAYAN | F8: Inicio: | G8: 45922
B9: Fecha de ingreso: | C9: 45841 | F9: Fin: | G9: 45930
B10: Sueldo: | C10: 481 | F10: Total de dias | G10: =+_xlfn.DAYS(G9,G8)+1 -> 9
B11: Subsidio: | C11: ENFERMEDAD GENERAL
B13: Calculo para el Pago:
B14: Sueldo Promedio Diario: | D14: =+C10/30 -> 16.033333 | E14: (1-3 dias) | F14: =+C10/30 -> 16.033333
B15: Promedio Diario (25%): | D15: =+D14*25% -> 4.0083333 | E15: (4-70 dias) | F15: =+F14*25% -> 4.0083333 | G15: =+F14*75% -> 12.025
I16: =+G15*18 -> 216.45
B17: Nº | C17: Periodo | E17: Pocentaje | F17: Num. Dias | G17: Valor
C18: Desde | D18: Hasta | I18: =+G27+I16 -> 841.75
B19: 1 | C19: 45922 | D19: 45930 | E19: 100 | F19: =+D19-C19+1 -> 9 | G19: =IF(E19=100,$F$14*F19,$F$15*F19) -> 144.3
B20: 2 | C20: 45931 | D20: 45944 | E20: 100 | F20: =+D20-C20+1 -> 14 | G20: =IF(E20=100,$F$14*F20,$F$15*F20) -> 224.46667
B21: 3 | C21: 45945 | D21: 45961 | E21: 100 | F21: =+D21-C21 -> 16 | G21: =IF(E21=100,$F$14*F21,$F$15*F21) -> 256.53333
B22: 4
B23: 5
B24: 6
B25: 7
B26: 8
B27: TOTAL | F27: =SUM(F19:F22) -> 39 | G27: =SUM(G19:G26) -> 625.3
B29: ROL PROPORCIONAL FEBRERO 2025
B31: INGRESOS | C31: VALOR | D31: EGRESOS | E31: VALOR
B32: SUELDO BÁSICO COOPERATIVA | C32: =+G19 -> 144.3 | D32: APORTE INDIVIDUAL AL IESS 9.45 | E32: =+((C10+C33+C39)*9.45%) -> 45.4545
B33: BONO MOVILIZACION | C33: 0 | D33: CUENTAS POR COBRAR | E33: 0 | H33: =100/30 -> 3.3333333
B34: BONO CUMPLIMIENTO | C34: 0 | D34: anticipo de sueldo | H34: =+H33*F19 -> 30
B35: COMISION POR SUPERAR LA META | C35: 0
B36: COMISION POR PLAZOS FIJOS
B37: COMISION POR SOCIOS NUEVOS
B38: HORAS EXTRAS 50%
B39: HORAS EXTRAS 100%
B40: FONDO DE RESERVA | C40: 0
B41: DECIMO TERCERO | C41: 0
B42: DECIMO CUARTO | C42: 0
B43: TOTAL INGRESOS | C43: =SUM(C32:C42) -> 144.3 | D43: TOTAL EGRESOS | E43: =SUM(E32:E42) -> 45.4545 | G43: 469.84584
D44: VALOR NETO A RECIBIR | E44: =+C43-E43 -> 98.8455 | G44: =+G43-E44 -> 371.00034

Sheet OTRAS COMISIONES
B2: CÁLCULO DE COMISIONES (METAS, BONOS,ETC)
B3: NÓMINA OCTUBRE 2025
H5: COMISIONES | K5: TOTAL COMISIÓN
J6: CRÉD-INV
B7: NO | C7: CEDULA | D7: NOMBRE | E7: CARGO | F7: Agencia | G7: SUELDO | H7: BONO BOLETOS | I7: COM. POR CARGO | J7: BONO CUMP | K7: US$,,
B8: 1 | C8: 925813685 | D8: =+VLOOKUP(Tabla335[[#This Row],[CEDULA ]],'OCTUBRE 2025'!$C$8:$J$10,2,0) -> #N/A | E8: =+VLOOKUP(Tabla335[[#This Row],[CEDULA ]],'OCTUBRE 2025'!$C$8:$J$10,4,0) -> #N/A | F8: =+VLOOKUP(Tabla335[[#This Row],[CEDULA ]],'OCTUBRE 2025'!$C$8:$J$10,6,0) -> #N/A | G8: =+VLOOKUP(Tabla335[[#This Row],[CEDULA ]],'OCTUBRE 2025'!$C$8:$J$10,8,0) -> #N/A | K8: =+Tabla335[[#This Row],[BONO BOLETOS]]+Tabla335[[#This Row],[COM. POR CARGO]]+Tabla335[[#This Row],[BONO CUMP]] -> 0
B9: 2 | C9: 944405737 | D9: =+VLOOKUP(Tabla335[[#This Row],[CEDULA ]],'OCTUBRE 2025'!$C$8:$J$10,2,0) -> #N/A | E9: =+VLOOKUP(Tabla335[[#This Row],[CEDULA ]],'OCTUBRE 2025'!$C$8:$J$10,4,0) -> #N/A | F9: =+VLOOKUP(Tabla335[[#This Row],[CEDULA ]],'OCTUBRE 2025'!$C$8:$J$10,6,0) -> #N/A | G9: =+VLOOKUP(Tabla335[[#This Row],[CEDULA ]],'OCTUBRE 2025'!$C$8:$J$10,8,0) -> #N/A | K9: =+Tabla335[[#This Row],[BONO BOLETOS]]+Tabla335[[#This Row],[COM. POR CARGO]]+Tabla335[[#This Row],[BONO CUMP]] -> 0
B10: 3 | C10: 604394502 | D10: =+VLOOKUP(Tabla335[[#This Row],[CEDULA ]],'OCTUBRE 2025'!$C$8:$J$10,2,0) -> #N/A | E10: =+VLOOKUP(Tabla335[[#This Row],[CEDULA ]],'OCTUBRE 2025'!$C$8:$J$10,4,0) -> #N/A | F10: =+VLOOKUP(Tabla335[[#This Row],[CEDULA ]],'OCTUBRE 2025'!$C$8:$J$10,6,0) -> #N/A | G10: =+VLOOKUP(Tabla335[[#This Row],[CEDULA ]],'OCTUBRE 2025'!$C$8:$J$10,8,0) -> #N/A | J10: 0 | K10: =+Tabla335[[#This Row],[BONO BOLETOS]]+Tabla335[[#This Row],[COM. POR CARGO]]+Tabla335[[#This Row],[BONO CUMP]] -> 0
B11: 4 | C11: 955741970 | D11: =+VLOOKUP(Tabla335[[#This Row],[CEDULA ]],'OCTUBRE 2025'!$C$8:$J$10,2,0) -> #N/A | E11: =+VLOOKUP(Tabla335[[#This Row],[CEDULA ]],'OCTUBRE 2025'!$C$8:$J$10,4,0) -> #N/A | F11: =+VLOOKUP(Tabla335[[#This Row],[CEDULA ]],'OCTUBRE 2025'!$C$8:$J$10,6,0) -> #N/A | G11: =+VLOOKUP(Tabla335[[#This Row],[CEDULA ]],'OCTUBRE 2025'!$C$8:$J$10,8,0) -> #N/A | K11: =+Tabla335[[#This Row],[BONO BOLETOS]]+Tabla335[[#This Row],[COM. POR CARGO]]+Tabla335[[#This Row],[BONO CUMP]] -> 0
B12: 5 | C12: 0943964973 | D12: =+VLOOKUP(Tabla335[[#This Row],[CEDULA ]],'OCTUBRE 2025'!$C$8:$J$10,2,0) -> #N/A | E12: =+VLOOKUP(Tabla335[[#This Row],[CEDULA ]],'OCTUBRE 2025'!$C$8:$J$10,4,0) -> #N/A | F12: =+VLOOKUP(Tabla335[[#This Row],[CEDULA ]],'OCTUBRE 2025'!$C$8:$J$10,6,0) -> #N/A | G12: =+VLOOKUP(Tabla335[[#This Row],[CEDULA ]],'OCTUBRE 2025'!$C$8:$J$10,8,0) -> #N/A | J12: 368.77 | K12: =+Tabla335[[#This Row],[BONO BOLETOS]]+Tabla335[[#This Row],[COM. POR CARGO]]+Tabla335[[#This Row],[BONO CUMP]] -> 368.77
B13: 6 | C13: 944143148 | D13: =+VLOOKUP(Tabla335[[#This Row],[CEDULA ]],'OCTUBRE 2025'!$C$8:$J$10,2,0) -> #N/A | E13: =+VLOOKUP(Tabla335[[#This Row],[CEDULA ]],'OCTUBRE 2025'!$C$8:$J$10,4,0) -> #N/A | F13: =+VLOOKUP(Tabla335[[#This Row],[CEDULA ]],'OCTUBRE 2025'!$C$8:$J$10,6,0) -> #N/A | G13: =+VLOOKUP(Tabla335[[#This Row],[CEDULA ]],'OCTUBRE 2025'!$C$8:$J$10,8,0) -> #N/A | K13: =+Tabla335[[#This Row],[BONO BOLETOS]]+Tabla335[[#This Row],[COM. POR CARGO]]+Tabla335[[#This Row],[BONO CUMP]] -> 0
B14: 7 | C14: 955325238 | D14: =+VLOOKUP(Tabla335[[#This Row],[CEDULA ]],'OCTUBRE 2025'!$C$8:$J$10,2,0) -> #N/A | E14: =+VLOOKUP(Tabla335[[#This Row],[CEDULA ]],'OCTUBRE 2025'!$C$8:$J$10,4,0) -> #N/A | F14: =+VLOOKUP(Tabla335[[#This Row],[CEDULA ]],'OCTUBRE 2025'!$C$8:$J$10,6,0) -> #N/A | G14: =+VLOOKUP(Tabla335[[#This Row],[CEDULA ]],'OCTUBRE 2025'!$C$8:$J$10,8,0) -> #N/A | K14: =+Tabla335[[#This Row],[BONO BOLETOS]]+Tabla335[[#This Row],[COM. POR CARGO]]+Tabla335[[#This Row],[BONO CUMP]] -> 0
B15: 8 | C15: 914163654 | D15: =+VLOOKUP(Tabla335[[#This Row],[CEDULA ]],'OCTUBRE 2025'!$C$8:$J$10,2,0) -> #N/A | E15: =+VLOOKUP(Tabla335[[#This Row],[CEDULA ]],'OCTUBRE 2025'!$C$8:$J$10,4,0) -> #N/A | F15: =+VLOOKUP(Tabla335[[#This Row],[CEDULA ]],'OCTUBRE 2025'!$C$8:$J$10,6,0) -> #N/A | G15: =+VLOOKUP(Tabla335[[#This Row],[CEDULA ]],'OCTUBRE 2025'!$C$8:$J$10,8,0) -> #N/A | K15: =+Tabla335[[#This Row],[BONO BOLETOS]]+Tabla335[[#This Row],[COM. POR CARGO]]+Tabla335[[#This Row],[BONO CUMP]] -> 0
B16: 9 | C16: 956668305 | D16: =+VLOOKUP(Tabla335[[#This Row],[CEDULA ]],'OCTUBRE 2025'!$C$8:$J$10,2,0) -> #N/A | E16: =+VLOOKUP(Tabla335[[#This Row],[CEDULA ]],'OCTUBRE 2025'!$C$8:$J$10,4,0) -> #N/A | F16: =+VLOOKUP(Tabla335[[#This Row],[CEDULA ]],'OCTUBRE 2025'!$C$8:$J$10,6,0) -> #N/A | G16: =+VLOOKUP(Tabla335[[#This Row],[CEDULA ]],'OCTUBRE 2025'!$C$8:$J$10,8,0) -> #N/A | J16: 0 | K16: =+Tabla335[[#This Row],[BONO BOLETOS]]+Tabla335[[#This Row],[COM. POR CARGO]]+Tabla335[[#This Row],[BONO CUMP]] -> 0
B17: 10 | C17: 0918741448 | D17: =+VLOOKUP(Tabla335[[#This Row],[CEDULA ]],'OCTUBRE 2025'!$C$8:$J$10,2,0) -> #N/A | E17: =+VLOOKUP(Tabla335[[#This Row],[CEDULA ]],'OCTUBRE 2025'!$C$8:$J$10,4,0) -> #N/A | F17: =+VLOOKUP(Tabla335[[#This Row],[CEDULA ]],'OCTUBRE 2025'!$C$8:$J$10,6,0) -> #N/A | G17: =+VLOOKUP(Tabla335[[#This Row],[CEDULA ]],'OCTUBRE 2025'!$C$8:$J$10,8,0) -> #N/A | K17: =+Tabla335[[#This Row],[BONO BOLETOS]]+Tabla335[[#This Row],[COM. POR CARGO]]+Tabla335[[#This Row],[BONO CUMP]] -> 0
B18: 11 | C18: 931097620 | D18: =+VLOOKUP(Tabla335[[#This Row],[CEDULA ]],'OCTUBRE 2025'!$C$8:$J$10,2,0) -> #N/A | E18: =+VLOOKUP(Tabla335[[#This Row],[CEDULA ]],'OCTUBRE 2025'!$C$8:$J$10,4,0) -> #N/A | F18: =+VLOOKUP(Tabla335[[#This Row],[CEDULA ]],'OCTUBRE 2025'!$C$8:$J$10,6,0) -> #N/A | G18: =+VLOOKUP(Tabla335[[#This Row],[CEDULA ]],'OCTUBRE 2025'!$C$8:$J$10,8,0) -> #N/A | J18: 368.77 | K18: =+Tabla335[[#This Row],[BONO BOLETOS]]+Tabla335[[#This Row],[COM. POR CARGO]]+Tabla335[[#This Row],[BONO CUMP]] -> 368.77
B19: 12 | C19: 1105483422 | D19: =+VLOOKUP(Tabla335[[#This Row],[CEDULA ]],'OCTUBRE 2025'!$C$8:$J$10,2,0) -> #N/A | E19: =+VLOOKUP(Tabla335[[#This Row],[CEDULA ]],'OCTUBRE 2025'!$C$8:$J$10,4,0) -> #N/A | F19: =+VLOOKUP(Tabla335[[#This Row],[CEDULA ]],'OCTUBRE 2025'!$C$8:$J$10,6,0) -> #N/A | G19: =+VLOOKUP(Tabla335[[#This Row],[CEDULA ]],'OCTUBRE 2025'!$C$8:$J$10,8,0) -> #N/A | K19: =+Tabla335[[#This Row],[BONO BOLETOS]]+Tabla335[[#This Row],[COM. POR CARGO]]+Tabla335[[#This Row],[BONO CUMP]] -> 0
B20: 13 | C20: 942614645 | D20: =+VLOOKUP(Tabla335[[#This Row],[CEDULA ]],'OCTUBRE 2025'!$C$8:$J$10,2,0) -> #N/A | E20: =+VLOOKUP(Tabla335[[#This Row],[CEDULA ]],'OCTUBRE 2025'!$C$8:$J$10,4,0) -> #N/A | F20: =+VLOOKUP(Tabla335[[#This Row],[CEDULA ]],'OCTUBRE 2025'!$C$8:$J$10,6,0) -> #N/A | G20: =+VLOOKUP(Tabla335[[#This Row],[CEDULA ]],'OCTUBRE 2025'!$C$8:$J$10,8,0) -> #N/A | K20: =+Tabla335[[#This Row],[BONO BOLETOS]]+Tabla335[[#This Row],[COM. POR CARGO]]+Tabla335[[#This Row],[BONO CUMP]] -> 0
B21: 14 | C21: 951200062 | D21: =+VLOOKUP(Tabla335[[#This Row],[CEDULA ]],'OCTUBRE 2025'!$C$8:$J$10,2,0) -> #N/A | E21: =+VLOOKUP(Tabla335[[#This Row],[CEDULA ]],'OCTUBRE 2025'!$C$8:$J$10,4,0) -> #N/A | F21: =+VLOOKUP(Tabla335[[#This Row],[CEDULA ]],'OCTUBRE 2025'!$C$8:$J$10,6,0) -> #N/A | G21: =+VLOOKUP(Tabla335[[#This Row],[CEDULA ]],'OCTUBRE 2025'!$C$8:$J$10,8,0) -> #N/A | K21: =+Tabla335[[#This Row],[BONO BOLETOS]]+Tabla335[[#This Row],[COM. POR CARGO]]+Tabla335[[#This Row],[BONO CUMP]] -> 0
B22: 15 | C22: 950929232 | D22: =+VLOOKUP(Tabla335[[#This Row],[CEDULA ]],'OCTUBRE 2025'!$C$8:$J$10,2,0) -> #N/A | E22: =+VLOOKUP(Tabla335[[#This Row],[CEDULA ]],'OCTUBRE 2025'!$C$8:$J$10,4,0) -> #N/A | F22: =+VLOOKUP(Tabla335[[#This Row],[CEDULA ]],'OCTUBRE 2025'!$C$8:$J$10,6,0) -> #N/A | G22: =+VLOOKUP(Tabla335[[#This Row],[CEDULA ]],'OCTUBRE 2025'!$C$8:$J$10,8,0) -> #N/A | K22: =+Tabla335[[#This Row],[BONO BOLETOS]]+Tabla335[[#This Row],[COM. POR CARGO]]+Tabla335[[#This Row],[BONO CUMP]] -> 0
B23: 16 | C23: 953819646 | D23: =+VLOOKUP(Tabla335[[#This Row],[CEDULA ]],'OCTUBRE 2025'!$C$8:$J$10,2,0) -> #N/A | E23: =+VLOOKUP(Tabla335[[#This Row],[CEDULA ]],'OCTUBRE 2025'!$C$8:$J$10,4,0) -> #N/A | F23: =+VLOOKUP(Tabla335[[#This Row],[CEDULA ]],'OCTUBRE 2025'!$C$8:$J$10,6,0) -> #N/A | G23: =+VLOOKUP(Tabla335[[#This Row],[CEDULA ]],'OCTUBRE 2025'!$C$8:$J$10,8,0) -> #N/A | K23: =+Tabla335[[#This Row],[BONO BOLETOS]]+Tabla335[[#This Row],[COM. POR CARGO]]+Tabla335[[#This Row],[BONO CUMP]] -> 0
B24: 17 | C24: 956953392 | D24: =+VLOOKUP(Tabla335[[#This Row],[CEDULA ]],'OCTUBRE 2025'!$C$8:$J$10,2,0) -> #N/A | E24: =+VLOOKUP(Tabla335[[#This Row],[CEDULA ]],'OCTUBRE 2025'!$C$8:$J$10,4,0) -> #N/A | F24: =+VLOOKUP(Tabla335[[#This Row],[CEDULA ]],'OCTUBRE 2025'!$C$8:$J$10,6,0) -> #N/A | G24: =+VLOOKUP(Tabla335[[#This Row],[CEDULA ]],'OCTUBRE 2025'!$C$8:$J$10,8,0) -> #N/A | K24: =+Tabla335[[#This Row],[BONO BOLETOS]]+Tabla335[[#This Row],[COM. POR CARGO]]+Tabla335[[#This Row],[BONO CUMP]] -> 0
B25: 18 | C25: 956796767 | D25: =+VLOOKUP(Tabla335[[#This Row],[CEDULA ]],'OCTUBRE 2025'!$C$8:$J$10,2,0) -> #N/A | E25: =+VLOOKUP(Tabla335[[#This Row],[CEDULA ]],'OCTUBRE 2025'!$C$8:$J$10,4,0) -> #N/A | F25: =+VLOOKUP(Tabla335[[#This Row],[CEDULA ]],'OCTUBRE 2025'!$C$8:$J$10,6,0) -> #N/A | G25: =+VLOOKUP(Tabla335[[#This Row],[CEDULA ]],'OCTUBRE 2025'!$C$8:$J$10,8,0) -> #N/A | K25: =+Tabla335[[#This Row],[BONO BOLETOS]]+Tabla335[[#This Row],[COM. POR CARGO]]+Tabla335[[#This Row],[BONO CUMP]] -> 0
B26: 19 | C26: 0932036049 | D26: =+VLOOKUP(Tabla335[[#This Row],[CEDULA ]],'OCTUBRE 2025'!$C$8:$J$10,2,0) -> #N/A | E26: =+VLOOKUP(Tabla335[[#This Row],[CEDULA ]],'OCTUBRE 2025'!$C$8:$J$10,4,0) -> #N/A | F26: =+VLOOKUP(Tabla335[[#This Row],[CEDULA ]],'OCTUBRE 2025'!$C$8:$J$10,6,0) -> #N/A | G26: =+VLOOKUP(Tabla335[[#This Row],[CEDULA ]],'OCTUBRE 2025'!$C$8:$J$10,8,0) -> #N/A | K26: =+Tabla335[[#This Row],[BONO BOLETOS]]+Tabla335[[#This Row],[COM. POR CARGO]]+Tabla335[[#This Row],[BONO CUMP]] -> 0
B27: 20 | C27: 1724102940 | D27: =+VLOOKUP(Tabla335[[#This Row],[CEDULA ]],'OCTUBRE 2025'!$C$8:$J$10,2,0) -> #N/A | E27: =+VLOOKUP(Tabla335[[#This Row],[CEDULA ]],'OCTUBRE 2025'!$C$8:$J$10,4,0) -> #N/A | F27: =+VLOOKUP(Tabla335[[#This Row],[CEDULA ]],'OCTUBRE 2025'!$C$8:$J$10,6,0) -> #N/A | G27: =+VLOOKUP(Tabla335[[#This Row],[CEDULA ]],'OCTUBRE 2025'!$C$8:$J$10,8,0) -> #N/A | J27: 0 | K27: =+Tabla335[[#This Row],[BONO BOLETOS]]+Tabla335[[#This Row],[COM. POR CARGO]]+Tabla335[[#This Row],[BONO CUMP]] -> 0
B28: 21 | C28: 943322974 | D28: =+VLOOKUP(Tabla335[[#This Row],[CEDULA ]],'OCTUBRE 2025'!$C$8:$J$10,2,0) -> #N/A | E28: =+VLOOKUP(Tabla335[[#This Row],[CEDULA ]],'OCTUBRE 2025'!$C$8:$J$10,4,0) -> #N/A | F28: =+VLOOKUP(Tabla335[[#This Row],[CEDULA ]],'OCTUBRE 2025'!$C$8:$J$10,6,0) -> #N/A | G28: =+VLOOKUP(Tabla335[[#This Row],[CEDULA ]],'OCTUBRE 2025'!$C$8:$J$10,8,0) -> #N/A | K28: =+Tabla335[[#This Row],[BONO BOLETOS]]+Tabla335[[#This Row],[COM. POR CARGO]]+Tabla335[[#This Row],[BONO CUMP]] -> 0
B29: 22 | C29: 941096851 | D29: =+VLOOKUP(Tabla335[[#This Row],[CEDULA ]],'OCTUBRE 2025'!$C$8:$J$10,2,0) -> #N/A | E29: =+VLOOKUP(Tabla335[[#This Row],[CEDULA ]],'OCTUBRE 2025'!$C$8:$J$10,4,0) -> #N/A | F29: =+VLOOKUP(Tabla335[[#This Row],[CEDULA ]],'OCTUBRE 2025'!$C$8:$J$10,6,0) -> #N/A | G29: =+VLOOKUP(Tabla335[[#This Row],[CEDULA ]],'OCTUBRE 2025'!$C$8:$J$10,8,0) -> #N/A | J29: 0 | K29: =+Tabla335[[#This Row],[BONO BOLETOS]]+Tabla335[[#This Row],[COM. POR CARGO]]+Tabla335[[#This Row],[BONO CUMP]] -> 0
B30: 23 | C30: 957093800 | D30: =+VLOOKUP(Tabla335[[#This Row],[CEDULA ]],'OCTUBRE 2025'!$C$8:$J$10,2,0) -> #N/A | E30: =+VLOOKUP(Tabla335[[#This Row],[CEDULA ]],'OCTUBRE 2025'!$C$8:$J$10,4,0) -> #N/A | F30: =+VLOOKUP(Tabla335[[#This Row],[CEDULA ]],'OCTUBRE 2025'!$C$8:$J$10,6,0) -> #N/A | G30: =+VLOOKUP(Tabla335[[#This Row],[CEDULA ]],'OCTUBRE 2025'!$C$8:$J$10,8,0) -> #N/A | K30: =+Tabla335[[#This Row],[BONO BOLETOS]]+Tabla335[[#This Row],[COM. POR CARGO]]+Tabla335[[#This Row],[BONO CUMP]] -> 0
B31: 24 | C31: 957924350 | D31: =+VLOOKUP(Tabla335[[#This Row],[CEDULA ]],'OCTUBRE 2025'!$C$8:$J$10,2,0) -> #N/A | E31: =+VLOOKUP(Tabla335[[#This Row],[CEDULA ]],'OCTUBRE 2025'!$C$8:$J$10,4,0) -> #N/A | F31: =+VLOOKUP(Tabla335[[#This Row],[CEDULA ]],'OCTUBRE 2025'!$C$8:$J$10,6,0) -> #N/A | G31: =+VLOOKUP(Tabla335[[#This Row],[CEDULA ]],'OCTUBRE 2025'!$C$8:$J$10,8,0) -> #N/A | K31: =+Tabla335[[#This Row],[BONO BOLETOS]]+Tabla335[[#This Row],[COM. POR CARGO]]+Tabla335[[#This Row],[BONO CUMP]] -> 0
B32: 25 | C32: 603838657 | D32: =+VLOOKUP(Tabla335[[#This Row],[CEDULA ]],'OCTUBRE 2025'!$C$8:$J$10,2,0) -> #N/A | E32: =+VLOOKUP(Tabla335[[#This Row],[CEDULA ]],'OCTUBRE 2025'!$C$8:$J$10,4,0) -> #N/A | F32: =+VLOOKUP(Tabla335[[#This Row],[CEDULA ]],'OCTUBRE 2025'!$C$8:$J$10,6,0) -> #N/A | G32: =+VLOOKUP(Tabla335[[#This Row],[CEDULA ]],'OCTUBRE 2025'!$C$8:$J$10,8,0) -> #N/A | K32: =+Tabla335[[#This Row],[BONO BOLETOS]]+Tabla335[[#This Row],[COM. POR CARGO]]+Tabla335[[#This Row],[BONO CUMP]] -> 0
B33: 26 | C33: 925240525 | D33: =+VLOOKUP(Tabla335[[#This Row],[CEDULA ]],'OCTUBRE 2025'!$C$8:$J$10,2,0) -> #N/A | E33: =+VLOOKUP(Tabla335[[#This Row],[CEDULA ]],'OCTUBRE 2025'!$C$8:$J$10,4,0) -> #N/A | F33: =+VLOOKUP(Tabla335[[#This Row],[CEDULA ]],'OCTUBRE 2025'!$C$8:$J$10,6,0) -> #N/A | G33: =+VLOOKUP(Tabla335[[#This Row],[CEDULA ]],'OCTUBRE 2025'!$C$8:$J$10,8,0) -> #N/A | K33: =+Tabla335[[#This Row],[BONO BOLETOS]]+Tabla335[[#This Row],[COM. POR CARGO]]+Tabla335[[#This Row],[BONO CUMP]] -> 0
B34: 27 | C34: 954520599 | D34: =+VLOOKUP(Tabla335[[#This Row],[CEDULA ]],'OCTUBRE 2025'!$C$8:$J$10,2,0) -> #N/A | E34: =+VLOOKUP(Tabla335[[#This Row],[CEDULA ]],'OCTUBRE 2025'!$C$8:$J$10,4,0) -> #N/A | F34: =+VLOOKUP(Tabla335[[#This Row],[CEDULA ]],'OCTUBRE 2025'!$C$8:$J$10,6,0) -> #N/A | G34: =+VLOOKUP(Tabla335[[#This Row],[CEDULA ]],'OCTUBRE 2025'!$C$8:$J$10,8,0) -> #N/A | J34: 0 | K34: =+Tabla335[[#This Row],[BONO BOLETOS]]+Tabla335[[#This Row],[COM. POR CARGO]]+Tabla335[[#This Row],[BONO CUMP]] -> 0
B35: 28 | C35: 0943906032 | D35: =+VLOOKUP(Tabla335[[#This Row],[CEDULA ]],'OCTUBRE 2025'!$C$8:$J$10,2,0) -> #N/A | E35: =+VLOOKUP(Tabla335[[#This Row],[CEDULA ]],'OCTUBRE 2025'!$C$8:$J$10,4,0) -> #N/A | F35: =+VLOOKUP(Tabla335[[#This Row],[CEDULA ]],'OCTUBRE 2025'!$C$8:$J$10,6,0) -> #N/A | G35: =+VLOOKUP(Tabla335[[#This Row],[CEDULA ]],'OCTUBRE 2025'!$C$8:$J$10,8,0) -> #N/A | K35: =+Tabla335[[#This Row],[BONO BOLETOS]]+Tabla335[[#This Row],[COM. POR CARGO]]+Tabla335[[#This Row],[BONO CUMP]] -> 0
B36: 29 | C36: 0919306050 | D36: =+VLOOKUP(Tabla335[[#This Row],[CEDULA ]],'OCTUBRE 2025'!$C$8:$J$10,2,0) -> #N/A | E36: =+VLOOKUP(Tabla335[[#This Row],[CEDULA ]],'OCTUBRE 2025'!$C$8:$J$10,4,0) -> #N/A | F36: =+VLOOKUP(Tabla335[[#This Row],[CEDULA ]],'OCTUBRE 2025'!$C$8:$J$10,6,0) -> #N/A | G36: =+VLOOKUP(Tabla335[[#This Row],[CEDULA ]],'OCTUBRE 2025'!$C$8:$J$10,8,0) -> #N/A | K36: =+Tabla335[[#This Row],[BONO BOLETOS]]+Tabla335[[#This Row],[COM. POR CARGO]]+Tabla335[[#This Row],[BONO CUMP]] -> 0
B37: 30 | C37: 0941235376 | D37: =+VLOOKUP(Tabla335[[#This Row],[CEDULA ]],'OCTUBRE 2025'!$C$8:$J$10,2,0) -> #N/A | E37: =+VLOOKUP(Tabla335[[#This Row],[CEDULA ]],'OCTUBRE 2025'!$C$8:$J$10,4,0) -> #N/A | F37: =+VLOOKUP(Tabla335[[#This Row],[CEDULA ]],'OCTUBRE 2025'!$C$8:$J$10,6,0) -> #N/A | G37: =+VLOOKUP(Tabla335[[#This Row],[CEDULA ]],'OCTUBRE 2025'!$C$8:$J$10,8,0) -> #N/A | K37: =+Tabla335[[#This Row],[BONO BOLETOS]]+Tabla335[[#This Row],[COM. POR CARGO]]+Tabla335[[#This Row],[BONO CUMP]] -> 0
B38: 31 | C38: 955395686 | D38: =+VLOOKUP(Tabla335[[#This Row],[CEDULA ]],'OCTUBRE 2025'!$C$8:$J$10,2,0) -> #N/A | E38: =+VLOOKUP(Tabla335[[#This Row],[CEDULA ]],'OCTUBRE 2025'!$C$8:$J$10,4,0) -> #N/A | F38: =+VLOOKUP(Tabla335[[#This Row],[CEDULA ]],'OCTUBRE 2025'!$C$8:$J$10,6,0) -> #N/A | G38: =+VLOOKUP(Tabla335[[#This Row],[CEDULA ]],'OCTUBRE 2025'!$C$8:$J$10,8,0) -> #N/A | H38: 0 | J38: 0 | K38: =+Tabla335[[#This Row],[BONO BOLETOS]]+Tabla335[[#This Row],[COM. POR CARGO]]+Tabla335[[#This Row],[BONO CUMP]] -> 0
B39: 32 | C39: 940991987 | D39: =+VLOOKUP(Tabla335[[#This Row],[CEDULA ]],'OCTUBRE 2025'!$C$8:$J$10,2,0) -> #N/A | E39: =+VLOOKUP(Tabla335[[#This Row],[CEDULA ]],'OCTUBRE 2025'!$C$8:$J$10,4,0) -> #N/A | F39: =+VLOOKUP(Tabla335[[#This Row],[CEDULA ]],'OCTUBRE 2025'!$C$8:$J$10,6,0) -> #N/A | G39: =+VLOOKUP(Tabla335[[#This Row],[CEDULA ]],'OCTUBRE 2025'!$C$8:$J$10,8,0) -> #N/A | K39: =+Tabla335[[#This Row],[BONO BOLETOS]]+Tabla335[[#This Row],[COM. POR CARGO]]+Tabla335[[#This Row],[BONO CUMP]] -> 0
